Workbook

Sheet Data_DBD
A1: Nama | B1: Usia | C1: Lama Rawat Inap | D1: Jumlah Kasus Perbulan | E1: Jenis Kelamin | F1: Tingkat Resiko
A2: Neni Sumetria | B2: 34 | C2: 3 | D2: 12 | E2: 0 | F2: Sedang
A3: Malki Amron | B3: 43 | C3: 3 | D3: 12 | E3: 1 | F3: Sedang
A4: Arifa Qyaratul | B4: 23 | C4: 5 | D4: 12 | E4: 0 | F4: Sedang
A5: Rezki Mhd | B5: 18 | C5: 2 | D5: 12 | E5: 1 | F5: Sedang
A6: Selfiolla | B6: 14 | C6: 4 | D6: 12 | E6: 0 | F6: Sedang
A7: M.Albiruni | B7: 12 | C7: 1 | D7: 12 | E7: 1 | F7: Sedang
A8: Yurika Azarine | B8: 4 | C8: 2 | D8: 12 | E8: 0 | F8: Sedang
A9: Rahmad Ihtiar | B9: 16 | C9: 6 | D9: 12 | E9: 1 | F9: Sedang
A10: Tiara Endiwa | B10: 18 | C10: 5 | D10: 12 | E10: 0 | F10: Sedang
A11: Boby | B11: 24 | C11: 5 | D11: 12 | E11: 1 | F11: Sedang
A12: Defi Putri | B12: 23 | C12: 3 | D12: 12 | E12: 0 | F12: Sedang
A13: Nini Efriza | B13: 47 | C13: 2 | D13: 12 | E13: 0 | F13: Sedang
... A164: Aprillia Khairunnisa | B164: 10 | C164: 6 | D164: 3 | E164: 0 | F164: Rendah

Sheet Pohon 1
A1: No | B1: Usia | C1: Lama Rawat Inap | D1: Jumlah Kasus Per Bulan | E1: Jenis Kelamin | F1: Tingkat Resiko | H1: No | I1: Usia | J1: Lama Rawat Inap | K1: Jumlah Kasus Per Bulan | L1: Jenis Kelamin | M1: Tingkat Resiko | O1: Perhitungan root
A2: =RANDBETWEEN(2,164) | B2: {=INDEX(Data_DBD!$B:$B,$A2)} | C2: {=INDEX(Data_DBD!$C:$C,$A2)} | D2: {=INDEX(Data_DBD!$D:$D,$A2)} | E2: {=INDEX(Data_DBD!$E:$E,$A2)} | F2: {=INDEX(Data_DBD!$F:$F,$A2)} | H2: 42 | I2: 21 | J2: 5 | K2: 13 | L2: 1 | M2: Sedang | O2: Tinggi | P2: =COUNTIF(M2:M164,"Tinggi") | Q2: =P2/163
A3: =RANDBETWEEN(2,164) | B3: {=INDEX(Data_DBD!$B:$B,$A3)} | C3: {=INDEX(Data_DBD!$C:$C,$A3)} | D3: {=INDEX(Data_DBD!$D:$D,$A3)} | E3: {=INDEX(Data_DBD!$E:$E,$A3)} | F3: {=INDEX(Data_DBD!$F:$F,$A3)} | H3: 47 | I3: 19 | J3: 2 | K3: 13 | L3: 0 | M3: Sedang | O3: Sedang | P3: =COUNTIF(M2:M164,"Sedang") | Q3: =P3/163
A4: =RANDBETWEEN(2,164) | B4: {=INDEX(Data_DBD!$B:$B,$A4)} | C4: {=INDEX(Data_DBD!$C:$C,$A4)} | D4: {=INDEX(Data_DBD!$D:$D,$A4)} | E4: {=INDEX(Data_DBD!$E:$E,$A4)} | F4: {=INDEX(Data_DBD!$F:$F,$A4)} | H4: 123 | I4: 22 | J4: 4 | K4: 33 | L4: 0 | M4: Tinggi | O4: Rendah | P4: =COUNTIF(M2:M164,"Rendah") | Q4: =P4/163
A5: =RANDBETWEEN(2,164) | B5: {=INDEX(Data_DBD!$B:$B,$A5)} | C5: {=INDEX(Data_DBD!$C:$C,$A5)} | D5: {=INDEX(Data_DBD!$D:$D,$A5)} | E5: {=INDEX(Data_DBD!$E:$E,$A5)} | F5: {=INDEX(Data_DBD!$F:$F,$A5)} | H5: 52 | I5: 59 | J5: 4 | K5: 15 | L5: 1 | M5: Sedang | O5: Entropy Root | P5: =-(IFERROR(Q2*LOG(Q2,2),0)+IFERROR(Q3*LOG(Q3,2),0)+IFERROR(Q4*LOG(Q4,2),0))
A6: =RANDBETWEEN(2,164) | B6: {=INDEX(Data_DBD!$B:$B,$A6)} | C6: {=INDEX(Data_DBD!$C:$C,$A6)} | D6: {=INDEX(Data_DBD!$D:$D,$A6)} | E6: {=INDEX(Data_DBD!$E:$E,$A6)} | F6: {=INDEX(Data_DBD!$F:$F,$A6)} | H6: 111 | I6: 25 | J6: 4 | K6: 33 | L6: 0 | M6: Tinggi
A7: =RANDBETWEEN(2,164) | B7: {=INDEX(Data_DBD!$B:$B,$A7)} | C7: {=INDEX(Data_DBD!$C:$C,$A7)} | D7: {=INDEX(Data_DBD!$D:$D,$A7)} | E7: {=INDEX(Data_DBD!$E:$E,$A7)} | F7: {=INDEX(Data_DBD!$F:$F,$A7)} | H7: 156 | I7: 5 | J7: 2 | K7: 21 | L7: 0 | M7: Tinggi
A8: =RANDBETWEEN(2,164) | B8: {=INDEX(Data_DBD!$B:$B,$A8)} | C8: {=INDEX(Data_DBD!$C:$C,$A8)} | D8: {=INDEX(Data_DBD!$D:$D,$A8)} | E8: {=INDEX(Data_DBD!$E:$E,$A8)} | F8: {=INDEX(Data_DBD!$F:$F,$A8)} | H8: 64 | I8: 35 | J8: 1 | K8: 15 | L8: 0 | M8: Sedang
A9: =RANDBETWEEN(2,164) | B9: {=INDEX(Data_DBD!$B:$B,$A9)} | C9: {=INDEX(Data_DBD!$C:$C,$A9)} | D9: {=INDEX(Data_DBD!$D:$D,$A9)} | E9: {=INDEX(Data_DBD!$E:$E,$A9)} | F9: {=INDEX(Data_DBD!$F:$F,$A9)} | H9: 160 | I9: 16 | J9: 3 | K9: 21 | L9: 0 | M9: Tinggi
A10: =RANDBETWEEN(2,164) | B10: {=INDEX(Data_DBD!$B:$B,$A10)} | C10: {=INDEX(Data_DBD!$C:$C,$A10)} | D10: {=INDEX(Data_DBD!$D:$D,$A10)} | E10: {=INDEX(Data_DBD!$E:$E,$A10)} | F10: {=INDEX(Data_DBD!$F:$F,$A10)} | H10: 82 | I10: 28 | J10: 3 | K10: 13 | L10: 1 | M10: Sedang
A11: =RANDBETWEEN(2,164) | B11: {=INDEX(Data_DBD!$B:$B,$A11)} | C11: {=INDEX(Data_DBD!$C:$C,$A11)} | D11: {=INDEX(Data_DBD!$D:$D,$A11)} | E11: {=INDEX(Data_DBD!$E:$E,$A11)} | F11: {=INDEX(Data_DBD!$F:$F,$A11)} | H11: 6 | I11: 14 | J11: 4 | K11: 12 | L11: 0 | M11: Sedang
A12: =RANDBETWEEN(2,164) | B12: {=INDEX(Data_DBD!$B:$B,$A12)} | C12: {=INDEX(Data_DBD!$C:$C,$A12)} | D12: {=INDEX(Data_DBD!$D:$D,$A12)} | E12: {=INDEX(Data_DBD!$E:$E,$A12)} | F12: {=INDEX(Data_DBD!$F:$F,$A12)} | H12: 121 | I12: 82 | J12: 5 | K12: 33 | L12: 1 | M12: Tinggi
A13: =RANDBETWEEN(2,164) | B13: {=INDEX(Data_DBD!$B:$B,$A13)} | C13: {=INDEX(Data_DBD!$C:$C,$A13)} | D13: {=INDEX(Data_DBD!$D:$D,$A13)} | E13: {=INDEX(Data_DBD!$E:$E,$A13)} | F13: {=INDEX(Data_DBD!$F:$F,$A13)} | H13: 138 | I13: 13 | J13: 3 | K13: 33 | L13: 1 | M13: Tinggi
A14: =RANDBETWEEN(2,164) | B14: {=INDEX(Data_DBD!$B:$B,$A14)} | C14: {=INDEX(Data_DBD!$C:$C,$A14)} | D14: {=INDEX(Data_DBD!$D:$D,$A14)} | E14: {=INDEX(Data_DBD!$E:$E,$A14)} | F14: {=INDEX(Data_DBD!$F:$F,$A14)} | H14: 122 | I14: 28 | J14: 3 | K14: 33 | L14: 1 | M14: Tinggi
A15: =RANDBETWEEN(2,164) | B15: {=INDEX(Data_DBD!$B:$B,$A15)} | C15: {=INDEX(Data_DBD!$C:$C,$A15)} | D15: {=INDEX(Data_DBD!$D:$D,$A15)} | E15: {=INDEX(Data_DBD!$E:$E,$A15)} | F15: {=INDEX(Data_DBD!$F:$F,$A15)} | H15: 10 | I15: 18 | J15: 5 | K15: 12 | L15: 0 | M15: Sedang
A16: =RANDBETWEEN(2,164) | B16: {=INDEX(Data_DBD!$B:$B,$A16)} | C16: {=INDEX(Data_DBD!$C:$C,$A16)} | D16: {=INDEX(Data_DBD!$D:$D,$A16)} | E16: {=INDEX(Data_DBD!$E:$E,$A16)} | F16: {=INDEX(Data_DBD!$F:$F,$A16)} | H16: 71 | I16: 84 | J16: 3 | K16: 10 | L16: 0 | M16: Sedang
A17: =RANDBETWEEN(2,164) | B17: {=INDEX(Data_DBD!$B:$B,$A17)} | C17: {=INDEX(Data_DBD!$C:$C,$A17)} | D17: {=INDEX(Data_DBD!$D:$D,$A17)} | E17: {=INDEX(Data_DBD!$E:$E,$A17)} | F17: {=INDEX(Data_DBD!$F:$F,$A17)} | H17: 128 | I17: 38 | J17: 2 | K17: 33 | L17: 0 | M17: Tinggi
... A164: =RANDBETWEEN(2,164) | B164: {=INDEX(Data_DBD!$B:$B,$A164)} | C164: {=INDEX(Data_DBD!$C:$C,$A164)} | D164: {=INDEX(Data_DBD!$D:$D,$A164)} | E164: {=INDEX(Data_DBD!$E:$E,$A164)} | F164: {=INDEX(Data_DBD!$F:$F,$A164)} | H164: 69 | I164: 24 | J164: 4 | K164: 10 | L164: 1 | M164: Sedang
I165: =AVERAGE(I2:I164) | J165: =AVERAGE(J2:J164) | K165: =AVERAGE(K2:K164) | L165: =AVERAGE(L2:L164)
B167: 2
E168: USIA | J168: LAMA RAWAT INAP | O168: JUMLAH KASUS PER BULAN | T168: JENIS KELAMIN
E169: Usia | F169: =AVERAGEIF($I$2:$I$164,"<="&$I$165) | G169: =AVERAGEIF($I$2:$I$164,">"&$I$165) | J169: Lama rawat inap | K169: =AVERAGEIF($J$2:$J$164,"<="&$J$165) | L169: =AVERAGEIF($J$2:$J$164,">"&$J$165) | O169: Jumlah kasus perbulan | P169: =AVERAGEIF($K$2:$K$164,"<="&$K$165) | Q169: =AVERAGEIF($K$2:$K$164,">"&$K$165) | T169: Jenis kelamin | U169: =AVERAGEIF($L$2:$L$164,"<="&$L$165) | V169: =AVERAGEIF($L$2:$L$164,">"&$L$165)
E170: {=IF($I$2:$I$164<$F$169,"kiri",IF($I$2:$I$164<$G$169,"tengah","kanan"))} | F170: Kanan > 55.5 | J170: {=IF($J$2:$J$164<$K$169,"kiri",IF($J$2:$J$164<$L$169,"tengah","kanan"))} | K170: Kanan > 4.5 | O170: {=IF($K$2:$K$164<$P$169,"kiri",IF($K$2:$K$164<$Q$169,"tengah","kanan"))} | P170: Kanan > 28.4 | T170: {=IF($L$2:$L$164<$U$169,"kiri",IF($L$2:$L$164<$V$169,"tengah","kanan"))} | U170: Kanan > 1
E171: tengah | F171: =COUNTIFS($E$170:$E$332,"Kanan",$M$2:$M$164,"Tinggi") | G171: =F171/32 | J171: kiri | K171: =COUNTIFS($J$170:$J$332,"Kanan",$M$2:$M$164,"Tinggi") | L171: =K171/27 | O171: kiri | P171: =COUNTIFS($O$170:$O$332,"Kanan",$M$2:$M$164,"Tinggi") | Q171: =P171/33 | T171: tengah | U171: =COUNTIFS($T$170:$T$332,"Kanan",$M$2:$M$164,"Tinggi") | V171: =U171/87
E172: tengah | F172: =COUNTIFS($E$170:$E$332,"Kanan",$M$2:$M$164,"Sedang") | G172: =F172/32 | J172: tengah | K172: =COUNTIFS($J$170:$J$332,"Kanan",$M$2:$M$164,"Sedang") | L172: =K172/27 | O172: kanan | P172: =COUNTIFS($O$170:$O$332,"Kanan",$M$2:$M$164,"Sedang") | Q172: =P172/27 | T172: tengah | U172: =COUNTIFS($T$170:$T$332,"Kanan",$M$2:$M$164,"Sedang") | V172: =U172/87
E173: kanan | F173: =COUNTIFS($E$170:$E$332,"Kanan",$M$2:$M$164,"Rendah") | G173: =F173/32 | J173: tengah | K173: =COUNTIFS($J$170:$J$332,"Kanan",$M$2:$M$164,"Rendah") | L173: =K173/27 | O173: tengah | P173: =COUNTIFS($O$170:$O$332,"Kanan",$M$2:$M$164,"Rendah") | Q173: =P173/27 | T173: kanan | U173: =COUNTIFS($T$170:$T$332,"Kanan",$M$2:$M$164,"Rendah") | V173: =U173/87
E174: tengah | F174: Entropy | G174: =-(IFERROR(G171*LOG(G171,2),0)+IFERROR(G172*LOG(G172,2),0)+IFERROR(G173*LOG(G173,2),0)) | J174: tengah | K174: Entropy | L174: =-(IFERROR(L171*LOG(L171,2),0)+IFERROR(L172*LOG(L172,2),0)+IFERROR(L173*LOG(L173,2),0)) | O174: kanan | P174: Entropy | Q174: =-(IFERROR(Q171*LOG(Q171,2),0)+IFERROR(Q172*LOG(Q172,2),0)+IFERROR(Q173*LOG(Q173,2),0)) | T174: tengah | U174: Entropy | V174: =-(IFERROR(V171*LOG(V171,2),0)+IFERROR(V172*LOG(V172,2),0)+IFERROR(V173*LOG(V173,2),0))
E175: kiri | G175: =SUM(F171:F173)/163 | J175: kiri | L175: =SUM(K171:K173)/163 | O175: tengah | Q175: =SUM(P171:P173)/163 | T175: tengah | V175: =SUM(U171:U173)/163
E176: tengah | G176: =G174*G175 | J176: kiri | L176: =L174*L175 | O176: tengah | Q176: =Q174*Q175 | T176: tengah | V176: =V174*V175
E177: kiri | J177: tengah | O177: tengah | T177: tengah
E178: tengah | J178: tengah | O178: kiri | T178: kanan
E179: kiri | F179: Kiri<17.96 | J179: tengah | K179: Kiri<2.65 | O179: kiri | P179: Kiri<13.35 | T179: tengah | U179: Kiri<0
E180: kanan | F180: =COUNTIFS($E$170:$E$332,"Kiri",$M$2:$M$164,"Tinggi") | G180: =F180/41 | J180: kanan | K180: =COUNTIFS($J$170:$J$332,"Kiri",$M$2:$M$164,"Tinggi") | L180: =K180/25 | O180: kanan | P180: =COUNTIFS($O$170:$O$332,"Kiri",$M$2:$M$164,"Tinggi") | Q180: =P180/57 | T180: kanan | U180: =COUNTIFS($T$170:$T$332,"Kiri",$M$2:$M$164,"Tinggi") | V180: =U180/57
E181: kiri | F181: =COUNTIFS($E$170:$E$332,"Kiri",$M$2:$M$164,"Sedang") | G181: =F181/41 | J181: tengah | K181: =COUNTIFS($J$170:$J$332,"Kiri",$M$2:$M$164,"Sedang") | L181: =K181/25 | O181: kanan | P181: =COUNTIFS($O$170:$O$332,"Kiri",$M$2:$M$164,"Sedang") | Q181: =P181/57 | T181: kanan | U181: =COUNTIFS($T$170:$T$332,"Kiri",$M$2:$M$164,"Sedang") | V181: =U181/57
E182: tengah | F182: =COUNTIFS($E$170:$E$332,"Kiri",$M$2:$M$164,"Rendah") | G182: =F182/41 | J182: tengah | K182: =COUNTIFS($J$170:$J$332,"Kiri",$M$2:$M$164,"Rendah") | L182: =K182/25 | O182: kanan | P182: =COUNTIFS($O$170:$O$332,"Kiri",$M$2:$M$164,"Rendah") | Q182: =P182/57 | T182: kanan | U182: =COUNTIFS($T$170:$T$332,"Kiri",$M$2:$M$164,"Rendah") | V182: =U182/57
E183: tengah | F183: Entropy | G183: =-(IFERROR(G180*LOG(G180,2),0)+IFERROR(G181*LOG(G181,2),0)+IFERROR(G182*LOG(G182,2),0)) | J183: kanan | K183: Entropy | L183: =-(IFERROR(L180*LOG(L180,2),0)+IFERROR(L181*LOG(L181,2),0)+IFERROR(L182*LOG(L182,2),0)) | O183: kiri | P183: Entropy | Q183: =-(IFERROR(Q180*LOG(Q180,2),0)+IFERROR(Q181*LOG(Q181,2),0)+IFERROR(Q182*LOG(Q182,2),0)) | T183: tengah | U183: Entropy | V183: =-(IFERROR(V180*LOG(V180,2),0)+IFERROR(V181*LOG(V181,2),0)+IFERROR(V182*LOG(V182,2),0))
E184: kanan | G184: =SUM(F180:F182)/163 | J184: tengah | L184: =SUM(K180:K182)/163 | O184: kiri | Q184: =SUM(P180:P182)/163 | T184: tengah | V184: =SUM(U180:U182)/163
E185: tengah | G185: =G183*G184 | J185: kiri | L185: =L183*L184 | O185: kanan | Q185: =Q183*Q184 | T185: tengah | V185: =V183*V184
E186: kanan | J186: kanan | O186: tengah | T186: kanan
E187: tengah | J187: kiri | O187: kiri | T187: tengah
...

Sheet Pohon 2
A1: No | B1: Usia | C1: Lama Rawat Inap | D1: Jenis Kelamin | E1: Tingkat Resiko | H1: No | I1: Usia | J1: Lama Rawat Inap | K1: Jenis Kelamin | L1: Tingkat Resiko | O1: Perhitungan root
A2: =RANDBETWEEN(2,164) | B2: {=INDEX(Data_DBD!$B:$B,$A2)} | C2: {=INDEX(Data_DBD!$C:$C,$A2)} | D2: {=INDEX(Data_DBD!$E:$E,$A2)} | E2: {=INDEX(Data_DBD!$F:$F,$A2)} | H2: 95 | I2: 11 | J2: 3 | K2: 1 | L2: Tinggi | O2: Tinggi | P2: =COUNTIF(L2:L164,"Tinggi") | Q2: =P2/163
A3: =RANDBETWEEN(2,164) | B3: {=INDEX(Data_DBD!$B:$B,$A3)} | C3: {=INDEX(Data_DBD!$C:$C,$A3)} | D3: {=INDEX(Data_DBD!$E:$E,$A3)} | E3: {=INDEX(Data_DBD!$F:$F,$A3)} | H3: 12 | I3: 23 | J3: 3 | K3: 0 | L3: Sedang | O3: Sedang | P3: =COUNTIF(L2:L164,"Sedang") | Q3: =P3/163
A4: =RANDBETWEEN(2,164) | B4: {=INDEX(Data_DBD!$B:$B,$A4)} | C4: {=INDEX(Data_DBD!$C:$C,$A4)} | D4: {=INDEX(Data_DBD!$E:$E,$A4)} | E4: {=INDEX(Data_DBD!$F:$F,$A4)} | H4: 30 | I4: 3 | J4: 2 | K4: 1 | L4: Sedang | O4: Rendah | P4: =COUNTIF(L2:L164,"Rendah") | Q4: =P4/163
A5: =RANDBETWEEN(2,164) | B5: {=INDEX(Data_DBD!$B:$B,$A5)} | C5: {=INDEX(Data_DBD!$C:$C,$A5)} | D5: {=INDEX(Data_DBD!$E:$E,$A5)} | E5: {=INDEX(Data_DBD!$F:$F,$A5)} | H5: 76 | I5: 70 | J5: 2 | K5: 0 | L5: Sedang | O5: Entropy Root | P5: =-(IFERROR(Q2*LOG(Q2,2),0)+IFERROR(Q3*LOG(Q3,2),0)+IFERROR(Q4*LOG(Q4,2),0))
A6: =RANDBETWEEN(2,164) | B6: {=INDEX(Data_DBD!$B:$B,$A6)} | C6: {=INDEX(Data_DBD!$C:$C,$A6)} | D6: {=INDEX(Data_DBD!$E:$E,$A6)} | E6: {=INDEX(Data_DBD!$F:$F,$A6)} | H6: 85 | I6: 27 | J6: 9 | K6: 0 | L6: Sedang
A7: =RANDBETWEEN(2,164) | B7: {=INDEX(Data_DBD!$B:$B,$A7)} | C7: {=INDEX(Data_DBD!$C:$C,$A7)} | D7: {=INDEX(Data_DBD!$E:$E,$A7)} | E7: {=INDEX(Data_DBD!$F:$F,$A7)} | H7: 55 | I7: 7 | J7: 4 | K7: 1 | L7: Sedang
A8: =RANDBETWEEN(2,164) | B8: {=INDEX(Data_DBD!$B:$B,$A8)} | C8: {=INDEX(Data_DBD!$C:$C,$A8)} | D8: {=INDEX(Data_DBD!$E:$E,$A8)} | E8: {=INDEX(Data_DBD!$F:$F,$A8)} | H8: 51 | I8: 48 | J8: 4 | K8: 0 | L8: Sedang
A9: =RANDBETWEEN(2,164) | B9: {=INDEX(Data_DBD!$B:$B,$A9)} | C9: {=INDEX(Data_DBD!$C:$C,$A9)} | D9: {=INDEX(Data_DBD!$E:$E,$A9)} | E9: {=INDEX(Data_DBD!$F:$F,$A9)} | H9: 108 | I9: 69 | J9: 7 | K9: 1 | L9: Tinggi
A10: =RANDBETWEEN(2,164) | B10: {=INDEX(Data_DBD!$B:$B,$A10)} | C10: {=INDEX(Data_DBD!$C:$C,$A10)} | D10: {=INDEX(Data_DBD!$E:$E,$A10)} | E10: {=INDEX(Data_DBD!$F:$F,$A10)} | H10: 72 | I10: 3 | J10: 5 | K10: 1 | L10: Sedang
A11: =RANDBETWEEN(2,164) | B11: {=INDEX(Data_DBD!$B:$B,$A11)} | C11: {=INDEX(Data_DBD!$C:$C,$A11)} | D11: {=INDEX(Data_DBD!$E:$E,$A11)} | E11: {=INDEX(Data_DBD!$F:$F,$A11)} | H11: 147 | I11: 66 | J11: 10 | K11: 1 | L11: Tinggi
A12: =RANDBETWEEN(2,164) | B12: {=INDEX(Data_DBD!$B:$B,$A12)} | C12: {=INDEX(Data_DBD!$C:$C,$A12)} | D12: {=INDEX(Data_DBD!$E:$E,$A12)} | E12: {=INDEX(Data_DBD!$F:$F,$A12)} | H12: 69 | I12: 24 | J12: 4 | K12: 1 | L12: Sedang
A13: =RANDBETWEEN(2,164) | B13: {=INDEX(Data_DBD!$B:$B,$A13)} | C13: {=INDEX(Data_DBD!$C:$C,$A13)} | D13: {=INDEX(Data_DBD!$E:$E,$A13)} | E13: {=INDEX(Data_DBD!$F:$F,$A13)} | H13: 4 | I13: 23 | J13: 5 | K13: 0 | L13: Sedang
A14: =RANDBETWEEN(2,164) | B14: {=INDEX(Data_DBD!$B:$B,$A14)} | C14: {=INDEX(Data_DBD!$C:$C,$A14)} | D14: {=INDEX(Data_DBD!$E:$E,$A14)} | E14: {=INDEX(Data_DBD!$F:$F,$A14)} | H14: 6 | I14: 14 | J14: 4 | K14: 0 | L14: Sedang
A15: =RANDBETWEEN(2,164) | B15: {=INDEX(Data_DBD!$B:$B,$A15)} | C15: {=INDEX(Data_DBD!$C:$C,$A15)} | D15: {=INDEX(Data_DBD!$E:$E,$A15)} | E15: {=INDEX(Data_DBD!$F:$F,$A15)} | H15: 13 | I15: 47 | J15: 2 | K15: 0 | L15: Sedang
A16: =RANDBETWEEN(2,164) | B16: {=INDEX(Data_DBD!$B:$B,$A16)} | C16: {=INDEX(Data_DBD!$C:$C,$A16)} | D16: {=INDEX(Data_DBD!$E:$E,$A16)} | E16: {=INDEX(Data_DBD!$F:$F,$A16)} | H16: 142 | I16: 39 | J16: 2 | K16: 1 | L16: Tinggi
A17: =RANDBETWEEN(2,164) | B17: {=INDEX(Data_DBD!$B:$B,$A17)} | C17: {=INDEX(Data_DBD!$C:$C,$A17)} | D17: {=INDEX(Data_DBD!$E:$E,$A17)} | E17: {=INDEX(Data_DBD!$F:$F,$A17)} | H17: 159 | I17: 17 | J17: 2 | K17: 0 | L17: Tinggi
... A164: =RANDBETWEEN(2,164) | B164: {=INDEX(Data_DBD!$B:$B,$A164)} | C164: {=INDEX(Data_DBD!$C:$C,$A164)} | D164: {=INDEX(Data_DBD!$E:$E,$A164)} | E164: {=INDEX(Data_DBD!$F:$F,$A164)} | H164: 138 | I164: 13 | J164: 3 | K164: 1 | L164: Tinggi
I165: =AVERAGE(I2:I164) | J165: =AVERAGE(J2:J164) | K165: =AVERAGE(K2:K164)
B167: 2
E168: USIA | J168: LAMA RAWAT INAP | T168: JENIS KELAMIN
E169: Usia | F169: =AVERAGEIF($I$2:$I$164,"<="&$I$165) | G169: =AVERAGEIF($I$2:$I$164,">"&$I$165) | J169: Lama rawat inap | K169: =AVERAGEIF($J$2:$J$164,"<="&$J$165) | L169: =AVERAGEIF($J$2:$J$164,">"&$J$165) | T169: Jenis kelamin | U169: =AVERAGEIF($K$2:$K$164,"<="&$K$165) | V169: =AVERAGEIF($K$2:$K$164,">"&$K$165)
E170: {=IF($I$2:$I$164<$F$169,"kiri",IF($I$2:$I$164<$G$169,"tengah","kanan"))} | F170: Kanan > 54.4 | J170: {=IF($J$2:$J$164<$K$169,"kiri",IF($J$2:$J$164<$L$169,"tengah","kanan"))} | K170: Kanan > 4.74 | T170: {=IF($K$2:$K$164<$U$169,"kiri",IF($K$2:$K$164<$V$169,"tengah","kanan"))} | U170: Kanan > 1
E171: tengah | F171: =COUNTIFS($E$170:$E$332,"Kanan",$L$2:$L$164,"Tinggi") | G171: =F171/30 | J171: tengah | K171: =COUNTIFS($J$170:$J$332,"Kanan",$L$2:$L$164,"Tinggi") | L171: =K171/27 | T171: tengah | U171: =COUNTIFS($T$170:$T$332,"Kanan",$L$2:$L$164,"Tinggi") | V171: =U171/85
E172: kiri | F172: =COUNTIFS($E$170:$E$332,"Kanan",$L$2:$L$164,"Sedang") | G172: =F172/30 | J172: kiri | K172: =COUNTIFS($J$170:$J$332,"Kanan",$L$2:$L$164,"Sedang") | L172: =K172/27 | T172: kanan | U172: =COUNTIFS($T$170:$T$332,"Kanan",$L$2:$L$164,"Sedang") | V172: =U172/85
E173: kanan | F173: =COUNTIFS($E$170:$E$332,"Kanan",$L$2:$L$164,"Rendah") | G173: =F173/30 | J173: kiri | K173: =COUNTIFS($J$170:$J$332,"Kanan",$L$2:$L$164,"Rendah") | L173: =K173/27 | T173: tengah | U173: =COUNTIFS($T$170:$T$332,"Kanan",$L$2:$L$164,"Rendah") | V173: =U173/85
E174: tengah | F174: Entropy | G174: =-(IFERROR(G171*LOG(G171,2),0)+IFERROR(G172*LOG(G172,2),0)+IFERROR(G173*LOG(G173,2),0)) | J174: kanan | K174: Entropy | L174: =-(IFERROR(L171*LOG(L171,2),0)+IFERROR(L172*LOG(L172,2),0)+IFERROR(L173*LOG(L173,2),0)) | T174: tengah | U174: Entropy | V174: =-(IFERROR(V171*LOG(V171,2),0)+IFERROR(V172*LOG(V172,2),0)+IFERROR(V173*LOG(V173,2),0))
E175: kiri | G175: =SUM(F171:F173)/163 | J175: tengah | L175: =SUM(K171:K173)/163 | T175: kanan | V175: =SUM(U171:U173)/163
E176: tengah | G176: =G174*G175 | J176: tengah | L176: =L174*L175 | T176: tengah | V176: =V174*V175
E177: kanan | J177: kanan | T177: kanan
E178: kiri | J178: kanan | T178: kanan
E179: kanan | F179: Kiri<16.61 | J179: kanan | K179: Kiri<2.61 | T179: kanan | U179: Kiri<0
E180: tengah | F180: =COUNTIFS($E$170:$E$332,"Kiri",$L$2:$L$164,"Tinggi") | G180: =F180/48 | J180: tengah | K180: =COUNTIFS($J$170:$J$332,"Kiri",$L$2:$L$164,"Tinggi") | L180: =K180/27 | T180: kanan | U180: =COUNTIFS($T$170:$T$332,"Kiri",$L$2:$L$164,"Tinggi") | V180: =U180/57
E181: tengah | F181: =COUNTIFS($E$170:$E$332,"Kiri",$L$2:$L$164,"Sedang") | G181: =F181/48 | J181: kanan | K181: =COUNTIFS($J$170:$J$332,"Kiri",$L$2:$L$164,"Sedang") | L181: =K181/27 | T181: tengah | U181: =COUNTIFS($T$170:$T$332,"Kiri",$L$2:$L$164,"Sedang") | V181: =U181/57
E182: kiri | F182: =COUNTIFS($E$170:$E$332,"Kiri",$L$2:$L$164,"Rendah") | G182: =F182/48 | J182: tengah | K182: =COUNTIFS($J$170:$J$332,"Kiri",$L$2:$L$164,"Rendah") | L182: =K182/27 | T182: tengah | U182: =COUNTIFS($T$170:$T$332,"Kiri",$L$2:$L$164,"Rendah") | V182: =U182/57
E183: tengah | F183: Entropy | G183: =-(IFERROR(G180*LOG(G180,2),0)+IFERROR(G181*LOG(G181,2),0)+IFERROR(G182*LOG(G182,2),0)) | J183: kiri | K183: Entropy | L183: =-(IFERROR(L180*LOG(L180,2),0)+IFERROR(L181*LOG(L181,2),0)+IFERROR(L182*LOG(L182,2),0)) | T183: tengah | U183: Entropy | V183: =-(IFERROR(V180*LOG(V180,2),0)+IFERROR(V181*LOG(V181,2),0)+IFERROR(V182*LOG(V182,2),0))
E184: tengah | G184: =SUM(F180:F182)/163 | J184: kiri | L184: =SUM(K180:K182)/163 | T184: kanan | V184: =SUM(U180:U182)/163
E185: tengah | G185: =G183*G184 | J185: kiri | L185: =L183*L184 | T185: tengah | V185: =V183*V184
E186: kiri | J186: kiri | T186: tengah
E187: kanan | J187: tengah | T187: kanan
...

Sheet Pohon 3
A1: No | B1: Lama Rawat Inap | C1: Jenis Kelamin | D1: Tingkat Resiko | H1: No | I1: Lama Rawat Inap | J1: Jenis Kelamin | K1: Tingkat Resiko | O1: Perhitungan root
A2: =RANDBETWEEN(2,164) | B2: {=INDEX(Data_DBD!$C:$C,$A2)} | C2: {=INDEX(Data_DBD!$E:$E,$A2)} | D2: {=INDEX(Data_DBD!$F:$F,$A2)} | H2: 98 | I2: 2 | J2: 1 | K2: Tinggi | O2: Tinggi | P2: =COUNTIF(K2:K164,"Tinggi") | Q2: =P2/163
A3: =RANDBETWEEN(2,164) | B3: {=INDEX(Data_DBD!$C:$C,$A3)} | C3: {=INDEX(Data_DBD!$E:$E,$A3)} | D3: {=INDEX(Data_DBD!$F:$F,$A3)} | H3: 126 | I3: 3 | J3: 1 | K3: Tinggi | O3: Sedang | P3: =COUNTIF(K2:K164,"Sedang") | Q3: =P3/163
A4: =RANDBETWEEN(2,164) | B4: {=INDEX(Data_DBD!$C:$C,$A4)} | C4: {=INDEX(Data_DBD!$E:$E,$A4)} | D4: {=INDEX(Data_DBD!$F:$F,$A4)} | H4: 49 | I4: 5 | J4: 0 | K4: Sedang | O4: Rendah | P4: =COUNTIF(K2:K164,"Rendah") | Q4: =P4/163
A5: =RANDBETWEEN(2,164) | B5: {=INDEX(Data_DBD!$C:$C,$A5)} | C5: {=INDEX(Data_DBD!$E:$E,$A5)} | D5: {=INDEX(Data_DBD!$F:$F,$A5)} | H5: 14 | I5: 4 | J5: 1 | K5: Rendah | O5: Entropy Root | P5: =-(IFERROR(Q2*LOG(Q2,2),0)+IFERROR(Q3*LOG(Q3,2),0)+IFERROR(Q4*LOG(Q4,2),0))
A6: =RANDBETWEEN(2,164) | B6: {=INDEX(Data_DBD!$C:$C,$A6)} | C6: {=INDEX(Data_DBD!$E:$E,$A6)} | D6: {=INDEX(Data_DBD!$F:$F,$A6)} | H6: 54 | I6: 3 | J6: 0 | K6: Sedang
A7: =RANDBETWEEN(2,164) | B7: {=INDEX(Data_DBD!$C:$C,$A7)} | C7: {=INDEX(Data_DBD!$E:$E,$A7)} | D7: {=INDEX(Data_DBD!$F:$F,$A7)} | H7: 80 | I7: 3 | J7: 1 | K7: Sedang
A8: =RANDBETWEEN(2,164) | B8: {=INDEX(Data_DBD!$C:$C,$A8)} | C8: {=INDEX(Data_DBD!$E:$E,$A8)} | D8: {=INDEX(Data_DBD!$F:$F,$A8)} | H8: 36 | I8: 1 | J8: 1 | K8: Rendah
A9: =RANDBETWEEN(2,164) | B9: {=INDEX(Data_DBD!$C:$C,$A9)} | C9: {=INDEX(Data_DBD!$E:$E,$A9)} | D9: {=INDEX(Data_DBD!$F:$F,$A9)} | H9: 105 | I9: 3 | J9: 1 | K9: Tinggi
A10: =RANDBETWEEN(2,164) | B10: {=INDEX(Data_DBD!$C:$C,$A10)} | C10: {=INDEX(Data_DBD!$E:$E,$A10)} | D10: {=INDEX(Data_DBD!$F:$F,$A10)} | H10: 26 | I10: 4 | J10: 1 | K10: Sedang
A11: =RANDBETWEEN(2,164) | B11: {=INDEX(Data_DBD!$C:$C,$A11)} | C11: {=INDEX(Data_DBD!$E:$E,$A11)} | D11: {=INDEX(Data_DBD!$F:$F,$A11)} | H11: 63 | I11: 3 | J11: 0 | K11: Sedang
A12: =RANDBETWEEN(2,164) | B12: {=INDEX(Data_DBD!$C:$C,$A12)} | C12: {=INDEX(Data_DBD!$E:$E,$A12)} | D12: {=INDEX(Data_DBD!$F:$F,$A12)} | H12: 107 | I12: 5 | J12: 0 | K12: Tinggi
A13: =RANDBETWEEN(2,164) | B13: {=INDEX(Data_DBD!$C:$C,$A13)} | C13: {=INDEX(Data_DBD!$E:$E,$A13)} | D13: {=INDEX(Data_DBD!$F:$F,$A13)} | H13: 50 | I13: 5 | J13: 0 | K13: Sedang
A14: =RANDBETWEEN(2,164) | B14: {=INDEX(Data_DBD!$C:$C,$A14)} | C14: {=INDEX(Data_DBD!$E:$E,$A14)} | D14: {=INDEX(Data_DBD!$F:$F,$A14)} | H14: 99 | I14: 2 | J14: 1 | K14: Tinggi
A15: =RANDBETWEEN(2,164) | B15: {=INDEX(Data_DBD!$C:$C,$A15)} | C15: {=INDEX(Data_DBD!$E:$E,$A15)} | D15: {=INDEX(Data_DBD!$F:$F,$A15)} | H15: 149 | I15: 5 | J15: 0 | K15: Tinggi
A16: =RANDBETWEEN(2,164) | B16: {=INDEX(Data_DBD!$C:$C,$A16)} | C16: {=INDEX(Data_DBD!$E:$E,$A16)} | D16: {=INDEX(Data_DBD!$F:$F,$A16)} | H16: 72 | I16: 5 | J16: 1 | K16: Sedang
A17: =RANDBETWEEN(2,164) | B17: {=INDEX(Data_DBD!$C:$C,$A17)} | C17: {=INDEX(Data_DBD!$E:$E,$A17)} | D17: {=INDEX(Data_DBD!$F:$F,$A17)} | H17: 109 | I17: 3 | J17: 1 | K17: Tinggi
... A164: =RANDBETWEEN(2,164) | B164: {=INDEX(Data_DBD!$C:$C,$A164)} | C164: {=INDEX(Data_DBD!$E:$E,$A164)} | D164: {=INDEX(Data_DBD!$F:$F,$A164)} | H164: 137 | I164: 1 | J164: 1 | K164: Tinggi
I165: =AVERAGE(I2:I164) | J165: =AVERAGE(J2:J164)
B167: 6
I168: LAMA RAWAT INAP | N168: JENIS KELAMIN
I169: Lama rawat inap | J169: =AVERAGEIF($I$2:$I$164,"<="&$I$165) | K169: =AVERAGEIF($I$2:$I$164,">"&$I$165) | N169: Jenis kelamin | O169: =AVERAGEIF($J$2:$J$164,"<="&$J$165) | P169: =AVERAGEIF($J$2:$J$164,">"&$J$165)
I170: {=IF($I$2:$I$164<$J$169,"kiri",IF($I$2:$I$164<$K$169,"tengah","kanan"))} | J170: Kanan > 4.68 | N170: {=IF($J$2:$J$164<$O$169,"kiri",IF($J$2:$J$164<$P$169,"tengah","kanan"))} | O170: Kanan > 1
I171: tengah | J171: =COUNTIFS($I$170:$I$332,"Kanan",$K$2:$K$164,"Tinggi") | K171: =J171/40 | N171: kanan | O171: =COUNTIFS($N$170:$N$332,"Kanan",$K$2:$K$164,"Tinggi") | P171: =O171/92
I172: kanan | J172: =COUNTIFS($I$170:$I$332,"Kanan",$K$2:$K$164,"Sedang") | K172: =J172/40 | N172: tengah | O172: =COUNTIFS($N$170:$N$332,"Kanan",$K$2:$K$164,"Sedang") | P172: =O172/92
I173: tengah | J173: =COUNTIFS($I$170:$I$332,"Kanan",$K$2:$K$164,"Rendah") | K173: =J173/40 | N173: kanan | O173: =COUNTIFS($N$170:$N$332,"Kanan",$K$2:$K$164,"Rendah") | P173: =O173/92
I174: tengah | J174: Entropy | K174: =-(IFERROR(K171*LOG(K171,2),0)+IFERROR(K172*LOG(K172,2),0)+IFERROR(K173*LOG(K173,2),0)) | N174: tengah | O174: Entropy | P174: =-(IFERROR(P171*LOG(P171,2),0)+IFERROR(P172*LOG(P172,2),0)+IFERROR(P173*LOG(P173,2),0))
I175: tengah | K175: =SUM(J171:J173)/163 | N175: kanan | P175: =SUM(O171:O173)/163
I176: kiri | K176: =K174*K175 | N176: kanan | P176: =P174*P175
I177: tengah | N177: kanan
I178: tengah | N178: kanan
I179: tengah | J179: Kiri<2.44 | N179: tengah | O179: Kiri<0
I180: kanan | J180: =COUNTIFS($I$170:$I$332,"Kiri",$K$2:$K$164,"Tinggi") | K180: =J180/36 | N180: tengah | O180: =COUNTIFS($N$170:$N$332,"Kiri",$K$2:$K$164,"Tinggi") | P180: =O180/57
I181: kanan | J181: =COUNTIFS($I$170:$I$332,"Kiri",$K$2:$K$164,"Sedang") | K181: =J181/36 | N181: tengah | O181: =COUNTIFS($N$170:$N$332,"Kiri",$K$2:$K$164,"Sedang") | P181: =O181/57
I182: kiri | J182: =COUNTIFS($I$170:$I$332,"Kiri",$K$2:$K$164,"Rendah") | K182: =J182/36 | N182: kanan | O182: =COUNTIFS($N$170:$N$332,"Kiri",$K$2:$K$164,"Rendah") | P182: =O182/57
I183: kanan | J183: Entropy | K183: =-(IFERROR(K180*LOG(K180,2),0)+IFERROR(K181*LOG(K181,2),0)+IFERROR(K182*LOG(K182,2),0)) | N183: tengah | O183: Entropy | P183: =-(IFERROR(P180*LOG(P180,2),0)+IFERROR(P181*LOG(P181,2),0)+IFERROR(P182*LOG(P182,2),0))
I184: kanan | K184: =SUM(J180:J182)/163 | N184: kanan | P184: =SUM(O180:O182)/163
I185: tengah | K185: =K183*K184 | N185: kanan | P185: =P183*P184
I186: tengah | N186: kanan
I187: tengah | N187: tengah
...

Sheet Pohon 4
A1: No | B1: Jenis Kelamin | C1: Tingkat Resiko | H1: No | I1: Jenis Kelamin | J1: Tingkat Resiko | O1: Perhitungan root
A2: =RANDBETWEEN(2,164) | B2: {=INDEX(Data_DBD!$E:$E,$A2)} | C2: {=INDEX(Data_DBD!$F:$F,$A2)} | H2: 150 | I2: 1 | J2: Tinggi | O2: Tinggi | P2: =COUNTIF(J2:J164,"Tinggi") | Q2: =P2/163
A3: =RANDBETWEEN(2,164) | B3: {=INDEX(Data_DBD!$E:$E,$A3)} | C3: {=INDEX(Data_DBD!$F:$F,$A3)} | H3: 88 | I3: 1 | J3: Sedang | O3: Sedang | P3: =COUNTIF(J2:J164,"Sedang") | Q3: =P3/163
A4: =RANDBETWEEN(2,164) | B4: {=INDEX(Data_DBD!$E:$E,$A4)} | C4: {=INDEX(Data_DBD!$F:$F,$A4)} | H4: 120 | I4: 1 | J4: Tinggi | O4: Rendah | P4: =COUNTIF(J2:J164,"Rendah") | Q4: =P4/163
A5: =RANDBETWEEN(2,164) | B5: {=INDEX(Data_DBD!$E:$E,$A5)} | C5: {=INDEX(Data_DBD!$F:$F,$A5)} | H5: 62 | I5: 1 | J5: Sedang | O5: Entropy Root | P5: =-(IFERROR(Q2*LOG(Q2,2),0)+IFERROR(Q3*LOG(Q3,2),0)+IFERROR(Q4*LOG(Q4,2),0))
A6: =RANDBETWEEN(2,164) | B6: {=INDEX(Data_DBD!$E:$E,$A6)} | C6: {=INDEX(Data_DBD!$F:$F,$A6)} | H6: 153 | I6: 1 | J6: Tinggi
A7: =RANDBETWEEN(2,164) | B7: {=INDEX(Data_DBD!$E:$E,$A7)} | C7: {=INDEX(Data_DBD!$F:$F,$A7)} | H7: 6 | I7: 0 | J7: Sedang
A8: =RANDBETWEEN(2,164) | B8: {=INDEX(Data_DBD!$E:$E,$A8)} | C8: {=INDEX(Data_DBD!$F:$F,$A8)} | H8: 95 | I8: 1 | J8: Tinggi
A9: =RANDBETWEEN(2,164) | B9: {=INDEX(Data_DBD!$E:$E,$A9)} | C9: {=INDEX(Data_DBD!$F:$F,$A9)} | H9: 69 | I9: 1 | J9: Sedang
A10: =RANDBETWEEN(2,164) | B10: {=INDEX(Data_DBD!$E:$E,$A10)} | C10: {=INDEX(Data_DBD!$F:$F,$A10)} | H10: 138 | I10: 1 | J10: Tinggi
A11: =RANDBETWEEN(2,164) | B11: {=INDEX(Data_DBD!$E:$E,$A11)} | C11: {=INDEX(Data_DBD!$F:$F,$A11)} | H11: 81 | I11: 1 | J11: Sedang
A12: =RANDBETWEEN(2,164) | B12: {=INDEX(Data_DBD!$E:$E,$A12)} | C12: {=INDEX(Data_DBD!$F:$F,$A12)} | H12: 88 | I12: 1 | J12: Sedang
A13: =RANDBETWEEN(2,164) | B13: {=INDEX(Data_DBD!$E:$E,$A13)} | C13: {=INDEX(Data_DBD!$F:$F,$A13)} | H13: 56 | I13: 0 | J13: Sedang
A14: =RANDBETWEEN(2,164) | B14: {=INDEX(Data_DBD!$E:$E,$A14)} | C14: {=INDEX(Data_DBD!$F:$F,$A14)} | H14: 58 | I14: 0 | J14: Sedang
A15: =RANDBETWEEN(2,164) | B15: {=INDEX(Data_DBD!$E:$E,$A15)} | C15: {=INDEX(Data_DBD!$F:$F,$A15)} | H15: 138 | I15: 1 | J15: Tinggi
A16: =RANDBETWEEN(2,164) | B16: {=INDEX(Data_DBD!$E:$E,$A16)} | C16: {=INDEX(Data_DBD!$F:$F,$A16)} | H16: 25 | I16: 0 | J16: Sedang
A17: =RANDBETWEEN(2,164) | B17: {=INDEX(Data_DBD!$E:$E,$A17)} | C17: {=INDEX(Data_DBD!$F:$F,$A17)} | H17: 9 | I17: 1 | J17: Sedang
... A164: =RANDBETWEEN(2,164) | B164: {=INDEX(Data_DBD!$E:$E,$A164)} | C164: {=INDEX(Data_DBD!$F:$F,$A164)} | H164: 56 | I164: 0 | J164: Sedang
I165: =AVERAGE(I2:I164)
B166: 10
H168: JENIS KELAMIN
H169: Jenis kelamin | I169: =AVERAGEIF($I$2:$I$164,"<="&$I$165) | J169: =AVERAGEIF($I$2:$I$164,">"&$I$165)
H170: {=IF($I$2:$I$164<$I$169,"kiri",IF($I$2:$I$164<$J$169,"tengah","kanan"))} | I170: Kanan > 1
H171: kanan | I171: =COUNTIFS($H$170:$H$332,"Kanan",$J$2:$J$164,"Tinggi") | J171: =I171/80
H172: kanan | I172: =COUNTIFS($H$170:$H$332,"Kanan",$J$2:$J$164,"Sedang") | J172: =I172/80
H173: kanan | I173: =COUNTIFS($H$170:$H$332,"Kanan",$J$2:$J$164,"Rendah") | J173: =I173/80
H174: kanan | I174: Entropy | J174: =-(IFERROR(J171*LOG(J171,2),0)+IFERROR(J172*LOG(J172,2),0)+IFERROR(J173*LOG(J173,2),0))
H175: tengah | J175: =SUM(I171:I173)/163
H176: kanan | J176: =J174*J175
H177: kanan
H178: kanan
H179: kanan | I179: Kiri<0
H180: kanan | I180: =COUNTIFS($H$170:$H$332,"Kiri",$J$2:$J$164,"Tinggi") | J180: =I180/57
H181: tengah | I181: =COUNTIFS($H$170:$H$332,"Kiri",$J$2:$J$164,"Sedang") | J181: =I181/57
H182: tengah | I182: =COUNTIFS($H$170:$H$332,"Kiri",$J$2:$J$164,"Rendah") | J182: =I182/57
H183: kanan | I183: Entropy | J183: =-(IFERROR(J180*LOG(J180,2),0)+IFERROR(J181*LOG(J181,2),0)+IFERROR(J182*LOG(J182,2),0))
H184: tengah | J184: =SUM(I180:I182)/163
H185: kanan | J185: =J183*J184
H186: tengah
H187: kanan
...

Sheet Pohon 5
A1: No | B1: Usia | C1: Lama Rawat Inap | D1: Jumlah Kasus Per Bulan | E1: Jenis Kelamin | F1: Tingkat Resiko | H1: No | I1: Usia | J1: Lama Rawat Inap | K1: Jumlah Kasus Per Bulan | L1: Jenis Kelamin | M1: Tingkat Resiko | O1: Perhitungan root
A2: =RANDBETWEEN(2,164) | B2: {=INDEX(Data_DBD!$B:$B,$A2)} | C2: {=INDEX(Data_DBD!$C:$C,$A2)} | D2: {=INDEX(Data_DBD!$D:$D,$A2)} | E2: {=INDEX(Data_DBD!$E:$E,$A2)} | F2: {=INDEX(Data_DBD!$F:$F,$A2)} | H2: 14 | I2: 49 | J2: 4 | K2: 7 | L2: 1 | M2: Rendah | O2: Tinggi | P2: =COUNTIF(M2:M164,"Tinggi") | Q2: =P2/163
A3: =RANDBETWEEN(2,164) | B3: {=INDEX(Data_DBD!$B:$B,$A3)} | C3: {=INDEX(Data_DBD!$C:$C,$A3)} | D3: {=INDEX(Data_DBD!$D:$D,$A3)} | E3: {=INDEX(Data_DBD!$E:$E,$A3)} | F3: {=INDEX(Data_DBD!$F:$F,$A3)} | H3: 127 | I3: 21 | J3: 2 | K3: 33 | L3: 0 | M3: Tinggi | O3: Sedang | P3: =COUNTIF(M2:M164,"Sedang") | Q3: =P3/163
A4: =RANDBETWEEN(2,164) | B4: {=INDEX(Data_DBD!$B:$B,$A4)} | C4: {=INDEX(Data_DBD!$C:$C,$A4)} | D4: {=INDEX(Data_DBD!$D:$D,$A4)} | E4: {=INDEX(Data_DBD!$E:$E,$A4)} | F4: {=INDEX(Data_DBD!$F:$F,$A4)} | H4: 62 | I4: 43 | J4: 4 | K4: 15 | L4: 1 | M4: Sedang | O4: Rendah | P4: =COUNTIF(M2:M164,"Rendah") | Q4: =P4/163
A5: =RANDBETWEEN(2,164) | B5: {=INDEX(Data_DBD!$B:$B,$A5)} | C5: {=INDEX(Data_DBD!$C:$C,$A5)} | D5: {=INDEX(Data_DBD!$D:$D,$A5)} | E5: {=INDEX(Data_DBD!$E:$E,$A5)} | F5: {=INDEX(Data_DBD!$F:$F,$A5)} | H5: 137 | I5: 3 | J5: 1 | K5: 33 | L5: 1 | M5: Tinggi | O5: Entropy Root | P5: =-(IFERROR(Q2*LOG(Q2,2),0)+IFERROR(Q3*LOG(Q3,2),0)+IFERROR(Q4*LOG(Q4,2),0))
A6: =RANDBETWEEN(2,164) | B6: {=INDEX(Data_DBD!$B:$B,$A6)} | C6: {=INDEX(Data_DBD!$C:$C,$A6)} | D6: {=INDEX(Data_DBD!$D:$D,$A6)} | E6: {=INDEX(Data_DBD!$E:$E,$A6)} | F6: {=INDEX(Data_DBD!$F:$F,$A6)} | H6: 25 | I6: 81 | J6: 5 | K6: 14 | L6: 0 | M6: Sedang
A7: =RANDBETWEEN(2,164) | B7: {=INDEX(Data_DBD!$B:$B,$A7)} | C7: {=INDEX(Data_DBD!$C:$C,$A7)} | D7: {=INDEX(Data_DBD!$D:$D,$A7)} | E7: {=INDEX(Data_DBD!$E:$E,$A7)} | F7: {=INDEX(Data_DBD!$F:$F,$A7)} | H7: 151 | I7: 24 | J7: 3 | K7: 21 | L7: 0 | M7: Tinggi
A8: =RANDBETWEEN(2,164) | B8: {=INDEX(Data_DBD!$B:$B,$A8)} | C8: {=INDEX(Data_DBD!$C:$C,$A8)} | D8: {=INDEX(Data_DBD!$D:$D,$A8)} | E8: {=INDEX(Data_DBD!$E:$E,$A8)} | F8: {=INDEX(Data_DBD!$F:$F,$A8)} | H8: 138 | I8: 13 | J8: 3 | K8: 33 | L8: 1 | M8: Tinggi
A9: =RANDBETWEEN(2,164) | B9: {=INDEX(Data_DBD!$B:$B,$A9)} | C9: {=INDEX(Data_DBD!$C:$C,$A9)} | D9: {=INDEX(Data_DBD!$D:$D,$A9)} | E9: {=INDEX(Data_DBD!$E:$E,$A9)} | F9: {=INDEX(Data_DBD!$F:$F,$A9)} | H9: 69 | I9: 24 | J9: 4 | K9: 10 | L9: 1 | M9: Sedang
A10: =RANDBETWEEN(2,164) | B10: {=INDEX(Data_DBD!$B:$B,$A10)} | C10: {=INDEX(Data_DBD!$C:$C,$A10)} | D10: {=INDEX(Data_DBD!$D:$D,$A10)} | E10: {=INDEX(Data_DBD!$E:$E,$A10)} | F10: {=INDEX(Data_DBD!$F:$F,$A10)} | H10: 23 | I10: 28 | J10: 4 | K10: 14 | L10: 1 | M10: Sedang
A11: =RANDBETWEEN(2,164) | B11: {=INDEX(Data_DBD!$B:$B,$A11)} | C11: {=INDEX(Data_DBD!$C:$C,$A11)} | D11: {=INDEX(Data_DBD!$D:$D,$A11)} | E11: {=INDEX(Data_DBD!$E:$E,$A11)} | F11: {=INDEX(Data_DBD!$F:$F,$A11)} | H11: 87 | I11: 21 | J11: 3 | K11: 13 | L11: 0 | M11: Sedang
A12: =RANDBETWEEN(2,164) | B12: {=INDEX(Data_DBD!$B:$B,$A12)} | C12: {=INDEX(Data_DBD!$C:$C,$A12)} | D12: {=INDEX(Data_DBD!$D:$D,$A12)} | E12: {=INDEX(Data_DBD!$E:$E,$A12)} | F12: {=INDEX(Data_DBD!$F:$F,$A12)} | H12: 34 | I12: 55 | J12: 3 | K12: 14 | L12: 0 | M12: Sedang
A13: =RANDBETWEEN(2,164) | B13: {=INDEX(Data_DBD!$B:$B,$A13)} | C13: {=INDEX(Data_DBD!$C:$C,$A13)} | D13: {=INDEX(Data_DBD!$D:$D,$A13)} | E13: {=INDEX(Data_DBD!$E:$E,$A13)} | F13: {=INDEX(Data_DBD!$F:$F,$A13)} | H13: 29 | I13: 19 | J13: 2 | K13: 14 | L13: 1 | M13: Sedang
A14: =RANDBETWEEN(2,164) | B14: {=INDEX(Data_DBD!$B:$B,$A14)} | C14: {=INDEX(Data_DBD!$C:$C,$A14)} | D14: {=INDEX(Data_DBD!$D:$D,$A14)} | E14: {=INDEX(Data_DBD!$E:$E,$A14)} | F14: {=INDEX(Data_DBD!$F:$F,$A14)} | H14: 154 | I14: 18 | J14: 5 | K14: 21 | L14: 1 | M14: Tinggi
A15: =RANDBETWEEN(2,164) | B15: {=INDEX(Data_DBD!$B:$B,$A15)} | C15: {=INDEX(Data_DBD!$C:$C,$A15)} | D15: {=INDEX(Data_DBD!$D:$D,$A15)} | E15: {=INDEX(Data_DBD!$E:$E,$A15)} | F15: {=INDEX(Data_DBD!$F:$F,$A15)} | H15: 136 | I15: 6 | J15: 2 | K15: 33 | L15: 0 | M15: Tinggi
A16: =RANDBETWEEN(2,164) | B16: {=INDEX(Data_DBD!$B:$B,$A16)} | C16: {=INDEX(Data_DBD!$C:$C,$A16)} | D16: {=INDEX(Data_DBD!$D:$D,$A16)} | E16: {=INDEX(Data_DBD!$E:$E,$A16)} | F16: {=INDEX(Data_DBD!$F:$F,$A16)} | H16: 111 | I16: 25 | J16: 4 | K16: 33 | L16: 0 | M16: Tinggi
A17: =RANDBETWEEN(2,164) | B17: {=INDEX(Data_DBD!$B:$B,$A17)} | C17: {=INDEX(Data_DBD!$C:$C,$A17)} | D17: {=INDEX(Data_DBD!$D:$D,$A17)} | E17: {=INDEX(Data_DBD!$E:$E,$A17)} | F17: {=INDEX(Data_DBD!$F:$F,$A17)} | H17: 163 | I17: 34 | J17: 4 | K17: 3 | L17: 1 | M17: Rendah
... A164: =RANDBETWEEN(2,164) | B164: {=INDEX(Data_DBD!$B:$B,$A164)} | C164: {=INDEX(Data_DBD!$C:$C,$A164)} | D164: {=INDEX(Data_DBD!$D:$D,$A164)} | E164: {=INDEX(Data_DBD!$E:$E,$A164)} | F164: {=INDEX(Data_DBD!$F:$F,$A164)} | H164: 57 | I164: 2 | J164: 2 | K164: 15 | L164: 1 | M164: Sedang
I165: =AVERAGE(I2:I164) | J165: =AVERAGE(J2:J164) | K165: =AVERAGE(K2:K164) | L165: =AVERAGE(L2:L164)
B167: 18
E168: USIA | J168: LAMA RAWAT INAP | O168: JUMLAH KASUS PER BULAN | T168: JENIS KELAMIN
E169: Usia | F169: =AVERAGEIF($I$2:$I$164,"<="&$I$165) | G169: =AVERAGEIF($I$2:$I$164,">"&$I$165) | J169: Lama rawat inap | K169: =AVERAGEIF($J$2:$J$164,"<="&$J$165) | L169: =AVERAGEIF($J$2:$J$164,">"&$J$165) | O169: Jumlah kasus perbulan | P169: =AVERAGEIF($K$2:$K$164,"<="&$K$165) | Q169: =AVERAGEIF($K$2:$K$164,">"&$K$165) | T169: Jenis kelamin | U169: =AVERAGEIF($L$2:$L$164,"<="&$L$165) | V169: =AVERAGEIF($L$2:$L$164,">"&$L$165)
E170: {=IF($I$2:$I$164<$F$169,"kiri",IF($I$2:$I$164<$G$169,"tengah","kanan"))} | F170: Kanan > 54.7 | J170: {=IF($J$2:$J$164<$K$169,"kiri",IF($J$2:$J$164<$L$169,"tengah","kanan"))} | K170: Kanan > 4.72 | O170: {=IF($K$2:$K$164<$P$169,"kiri",IF($K$2:$K$164<$Q$169,"tengah","kanan"))} | P170: Kanan > 29.21 | T170: {=IF($L$2:$L$164<$U$169,"kiri",IF($L$2:$L$164<$V$169,"tengah","kanan"))} | U170: Kanan > 1
E171: tengah | F171: =COUNTIFS($E$170:$E$332,"Kanan",$M$2:$M$164,"Tinggi") | G171: =F171/34 | J171: kiri | K171: =COUNTIFS($J$170:$J$332,"Kanan",$M$2:$M$164,"Tinggi") | L171: =K171/33 | O171: kanan | P171: =COUNTIFS($O$170:$O$332,"Kanan",$M$2:$M$164,"Tinggi") | Q171: =P171/39 | T171: tengah | U171: =COUNTIFS($T$170:$T$332,"Kanan",$M$2:$M$164,"Tinggi") | V171: =U171/95
E172: tengah | F172: =COUNTIFS($E$170:$E$332,"Kanan",$M$2:$M$164,"Sedang") | G172: =F172/34 | J172: tengah | K172: =COUNTIFS($J$170:$J$332,"Kanan",$M$2:$M$164,"Sedang") | L172: =K172/33 | O172: tengah | P172: =COUNTIFS($O$170:$O$332,"Kanan",$M$2:$M$164,"Sedang") | Q172: =P172/39 | T172: kanan | U172: =COUNTIFS($T$170:$T$332,"Kanan",$M$2:$M$164,"Sedang") | V172: =U172/95
E173: kiri | F173: =COUNTIFS($E$170:$E$332,"Kanan",$M$2:$M$164,"Rendah") | G173: =F173/34 | J173: kiri | K173: =COUNTIFS($J$170:$J$332,"Kanan",$M$2:$M$164,"Rendah") | L173: =K173/33 | O173: kanan | P173: =COUNTIFS($O$170:$O$332,"Kanan",$M$2:$M$164,"Rendah") | Q173: =P173/29 | T173: kanan | U173: =COUNTIFS($T$170:$T$332,"Kanan",$M$2:$M$164,"Rendah") | V173: =U173/95
E174: kanan | F174: Entropy | G174: =-(IFERROR(G171*LOG(G171,2),0)+IFERROR(G172*LOG(G172,2),0)+IFERROR(G173*LOG(G173,2),0)) | J174: kanan | K174: Entropy | L174: =-(IFERROR(L171*LOG(L171,2),0)+IFERROR(L172*LOG(L172,2),0)+IFERROR(L173*LOG(L173,2),0)) | O174: tengah | P174: Entropy | Q174: =-(IFERROR(Q171*LOG(Q171,2),0)+IFERROR(Q172*LOG(Q172,2),0)+IFERROR(Q173*LOG(Q173,2),0)) | T174: tengah | U174: Entropy | V174: =-(IFERROR(V171*LOG(V171,2),0)+IFERROR(V172*LOG(V172,2),0)+IFERROR(V173*LOG(V173,2),0))
E175: tengah | G175: =SUM(F171:F173)/163 | J175: tengah | L175: =SUM(K171:K173)/163 | O175: tengah | Q175: =SUM(P171:P173)/163 | T175: tengah | V175: =SUM(U171:U173)/163
E176: kiri | G176: =G174*G175 | J176: tengah | L176: =L174*L175 | O176: kanan | Q176: =Q174*Q175 | T176: kanan | V176: =V174*V175
E177: tengah | J177: tengah | O177: kiri | T177: kanan
E178: tengah | J178: tengah | O178: tengah | T178: kanan
E179: tengah | F179: Kiri<17.15 | J179: tengah | K179: Kiri<2.48 | O179: tengah | P179: Kiri<12.60 | T179: tengah | U179: Kiri<0
E180: kanan | F180: =COUNTIFS($E$170:$E$332,"Kiri",$M$2:$M$164,"Tinggi") | G180: =F180/44 | J180: tengah | K180: =COUNTIFS($J$170:$J$332,"Kiri",$M$2:$M$164,"Tinggi") | L180: =K180/31 | O180: tengah | P180: =COUNTIFS($O$170:$O$332,"Kiri",$M$2:$M$164,"Tinggi") | Q180: =P180/57 | T180: tengah | U180: =COUNTIFS($T$170:$T$332,"Kiri",$M$2:$M$164,"Tinggi") | V180: =U180/95
E181: tengah | F181: =COUNTIFS($E$170:$E$332,"Kiri",$M$2:$M$164,"Sedang") | G181: =F181/44 | J181: kiri | K181: =COUNTIFS($J$170:$J$332,"Kiri",$M$2:$M$164,"Sedang") | L181: =K181/31 | O181: tengah | P181: =COUNTIFS($O$170:$O$332,"Kiri",$M$2:$M$164,"Sedang") | Q181: =P181/31 | T181: kanan | U181: =COUNTIFS($T$170:$T$332,"Kiri",$M$2:$M$164,"Sedang") | V181: =U181/95
E182: tengah | F182: =COUNTIFS($E$170:$E$332,"Kiri",$M$2:$M$164,"Rendah") | G182: =F182/44 | J182: kanan | K182: =COUNTIFS($J$170:$J$332,"Kiri",$M$2:$M$164,"Rendah") | L182: =K182/31 | O182: tengah | P182: =COUNTIFS($O$170:$O$332,"Kiri",$M$2:$M$164,"Rendah") | Q182: =P182/31 | T182: kanan | U182: =COUNTIFS($T$170:$T$332,"Kiri",$M$2:$M$164,"Rendah") | V182: =U182/95
E183: kiri | F183: Entropy | G183: =-(IFERROR(G180*LOG(G180,2),0)+IFERROR(G181*LOG(G181,2),0)+IFERROR(G182*LOG(G182,2),0)) | J183: kiri | K183: Entropy | L183: =-(IFERROR(L180*LOG(L180,2),0)+IFERROR(L181*LOG(L181,2),0)+IFERROR(L182*LOG(L182,2),0)) | O183: kanan | P183: Entropy | Q183: =-(IFERROR(Q180*LOG(Q180,2),0)+IFERROR(Q181*LOG(Q181,2),0)+IFERROR(Q182*LOG(Q182,2),0)) | T183: tengah | U183: Entropy | V183: =-(IFERROR(V180*LOG(V180,2),0)+IFERROR(V181*LOG(V181,2),0)+IFERROR(V182*LOG(V182,2),0))
E184: tengah | G184: =SUM(F180:F182)/163 | J184: tengah | L184: =SUM(K180:K182)/163 | O184: kanan | Q184: =SUM(P180:P182)/163 | T184: tengah | V184: =SUM(U180:U182)/163
E185: tengah | G185: =G183*G184 | J185: tengah | L185: =L183*L184 | O185: kiri | Q185: =Q183*Q184 | T185: kanan | V185: =V183*V184
E186: kiri | J186: tengah | O186: kiri | T186: tengah
E187: kiri | J187: tengah | O187: kanan | T187: kanan
...

Sheet Pohon 6
A1: No | B1: Usia | C1: Lama Rawat Inap | D1: Jenis Kelamin | E1: Tingkat Resiko | H1: No | I1: Usia | J1: Lama Rawat Inap | K1: Jenis Kelamin | L1: Tingkat Resiko | O1: Perhitungan root
A2: =RANDBETWEEN(2,164) | H2: 42 | I2: 21 | J2: 5 | K2: 1 | L2: Sedang | O2: Tinggi | P2: =COUNTIF(L2:L164,"Tinggi") | Q2: =P2/163
A3: =RANDBETWEEN(2,164) | H3: 30 | I3: 3 | J3: 2 | K3: 1 | L3: Sedang | O3: Sedang | P3: =COUNTIF(L2:L164,"Sedang") | Q3: =P3/163
A4: =RANDBETWEEN(2,164) | H4: 139 | I4: 52 | J4: 7 | K4: 0 | L4: Tinggi | O4: Rendah | P4: =COUNTIF(L2:L164,"Rendah") | Q4: =P4/163
A5: =RANDBETWEEN(2,164) | H5: 60 | I5: 68 | J5: 4 | K5: 0 | L5: Sedang | O5: Entropy Root | P5: =-(IFERROR(Q2*LOG(Q2,2),0)+IFERROR(Q3*LOG(Q3,2),0)+IFERROR(Q4*LOG(Q4,2),0))
A6: =RANDBETWEEN(2,164) | H6: 76 | I6: 70 | J6: 2 | K6: 0 | L6: Sedang
A7: =RANDBETWEEN(2,164) | H7: 157 | I7: 15 | J7: 4 | K7: 1 | L7: Tinggi
A8: =RANDBETWEEN(2,164) | H8: 48 | I8: 50 | J8: 5 | K8: 1 | L8: Sedang
A9: =RANDBETWEEN(2,164) | H9: 60 | I9: 68 | J9: 4 | K9: 0 | L9: Sedang
A10: =RANDBETWEEN(2,164) | H10: 8 | I10: 4 | J10: 2 | K10: 0 | L10: Sedang
A11: =RANDBETWEEN(2,164) | H11: 149 | I11: 19 | J11: 5 | K11: 0 | L11: Tinggi
A12: =RANDBETWEEN(2,164) | H12: 141 | I12: 36 | J12: 2 | K12: 0 | L12: Tinggi
A13: =RANDBETWEEN(2,164) | H13: 6 | I13: 14 | J13: 4 | K13: 0 | L13: Sedang
A14: =RANDBETWEEN(2,164) | H14: 39 | I14: 12 | J14: 5 | K14: 1 | L14: Sedang
A15: =RANDBETWEEN(2,164) | H15: 54 | I15: 7 | J15: 3 | K15: 0 | L15: Sedang
A16: =RANDBETWEEN(2,164) | H16: 8 | I16: 4 | J16: 2 | K16: 0 | L16: Sedang
A17: =RANDBETWEEN(2,164) | H17: 44 | I17: 28 | J17: 5 | K17: 1 | L17: Sedang
... A164: =RANDBETWEEN(2,164) | H164: 139 | I164: 52 | J164: 7 | K164: 0 | L164: Tinggi
I165: =AVERAGE(I2:I164) | J165: =AVERAGE(J2:J164) | K165: =AVERAGE(K2:K164)
B166: 60
E168: USIA | J168: LAMA RAWAT INAP | T168: JENIS KELAMIN
E169: Usia | F169: =AVERAGEIF($I$2:$I$164,"<="&$I$165) | G169: =AVERAGEIF($I$2:$I$164,">"&$I$165) | J169: Lama rawat inap | K169: =AVERAGEIF($J$2:$J$164,"<="&$J$165) | L169: =AVERAGEIF($J$2:$J$164,">"&$J$165) | T169: Jenis kelamin | U169: =AVERAGEIF($K$2:$K$164,"<="&$K$165) | V169: =AVERAGEIF($K$2:$K$164,">"&$K$165)
E170: {=IF($I$2:$I$164<$F$169,"kiri",IF($I$2:$I$164<$G$169,"tengah","kanan"))} | F170: Kanan > 55.47 | J170: {=IF($J$2:$J$164<$K$169,"kiri",IF($J$2:$J$164<$L$169,"tengah","kanan"))} | K170: Kanan > 4.67 | T170: {=IF($K$2:$K$164<$U$169,"kiri",IF($K$2:$K$164<$V$169,"tengah","kanan"))} | U170: Kanan > 1
E171: kiri | F171: =COUNTIFS($E$170:$E$332,"Kanan",$L$2:$L$164,"Tinggi") | G171: =F171/31 | J171: kiri | K171: =COUNTIFS($J$170:$J$332,"Kanan",$L$2:$L$164,"Tinggi") | L171: =K171/41 | T171: kanan | U171: =COUNTIFS($T$170:$T$332,"Kanan",$L$2:$L$164,"Tinggi") | V171: =U171/87
E172: tengah | F172: =COUNTIFS($E$170:$E$332,"Kanan",$L$2:$L$164,"Sedang") | G172: =F172/31 | J172: kanan | K172: =COUNTIFS($J$170:$J$332,"Kanan",$L$2:$L$164,"Sedang") | L172: =K172/41 | T172: tengah | U172: =COUNTIFS($T$170:$T$332,"Kanan",$L$2:$L$164,"Sedang") | V172: =U172/87
E173: kanan | F173: =COUNTIFS($E$170:$E$332,"Kanan",$L$2:$L$164,"Rendah") | G173: =F173/31 | J173: tengah | K173: =COUNTIFS($J$170:$J$332,"Kanan",$L$2:$L$164,"Rendah") | L173: =K173/41 | T173: tengah | U173: =COUNTIFS($T$170:$T$332,"Kanan",$L$2:$L$164,"Rendah") | V173: =U173/87
E174: kanan | F174: Entropy | G174: =-(IFERROR(G171*LOG(G171,2),0)+IFERROR(G172*LOG(G172,2),0)+IFERROR(G173*LOG(G173,2),0)) | J174: kiri | K174: Entropy | L174: =-(IFERROR(L171*LOG(L171,2),0)+IFERROR(L172*LOG(L172,2),0)+IFERROR(L173*LOG(L173,2),0)) | T174: tengah | U174: Entropy | V174: =-(IFERROR(V171*LOG(V171,2),0)+IFERROR(V172*LOG(V172,2),0)+IFERROR(V173*LOG(V173,2),0))
E175: kiri | G175: =SUM(F171:F173)/163 | J175: tengah | L175: =SUM(K171:K173)/163 | T175: kanan | V175: =SUM(U171:U173)/163
E176: tengah | G176: =G174*G175 | J176: kanan | L176: =L174*L175 | T176: kanan | V176: =V174*V175
E177: kanan | J177: tengah | T177: tengah
E178: kiri | J178: kiri | T178: tengah
E179: tengah | F179: Kiri<16.08 | J179: kanan | K179: Kiri<2.5 | T179: tengah | U179: Kiri<0
E180: tengah | F180: =COUNTIFS($E$170:$E$332,"Kiri",$L$2:$L$164,"Tinggi") | G180: =F180/50 | J180: kiri | K180: =COUNTIFS($J$170:$J$332,"Kiri",$L$2:$L$164,"Tinggi") | L180: =K180/28 | T180: tengah | U180: =COUNTIFS($T$170:$T$332,"Kiri",$L$2:$L$164,"Tinggi") | V180: =U180/87
E181: kiri | F181: =COUNTIFS($E$170:$E$332,"Kiri",$L$2:$L$164,"Sedang") | G181: =F181/50 | J181: tengah | K181: =COUNTIFS($J$170:$J$332,"Kiri",$L$2:$L$164,"Sedang") | L181: =K181/28 | T181: tengah | U181: =COUNTIFS($T$170:$T$332,"Kiri",$L$2:$L$164,"Sedang") | V181: =U181/87
E182: kiri | F182: =COUNTIFS($E$170:$E$332,"Kiri",$L$2:$L$164,"Rendah") | G182: =F182/50 | J182: kanan | K182: =COUNTIFS($J$170:$J$332,"Kiri",$L$2:$L$164,"Rendah") | L182: =K182/28 | T182: kanan | U182: =COUNTIFS($T$170:$T$332,"Kiri",$L$2:$L$164,"Rendah") | V182: =U182/87
E183: kiri | F183: Entropy | G183: =-(IFERROR(G180*LOG(G180,2),0)+IFERROR(G181*LOG(G181,2),0)+IFERROR(G182*LOG(G182,2),0)) | J183: tengah | K183: Entropy | L183: =-(IFERROR(L180*LOG(L180,2),0)+IFERROR(L181*LOG(L181,2),0)+IFERROR(L182*LOG(L182,2),0)) | T183: tengah | U183: Entropy | V183: =-(IFERROR(V180*LOG(V180,2),0)+IFERROR(V181*LOG(V181,2),0)+IFERROR(V182*LOG(V182,2),0))
E184: kiri | G184: =SUM(F180:F182)/163 | J184: kiri | L184: =SUM(K180:K182)/163 | T184: tengah | V184: =SUM(U180:U182)/163
E185: tengah | G185: =G183*G184 | J185: kanan | L185: =L183*L184 | T185: kanan | V185: =V183*V184
E186: kanan | J186: tengah | T186: kanan
E187: kanan | J187: tengah | T187: tengah
...

Sheet Pohon 7(BP)
A1: No | B1: Usia | C1: Jenis Kelamin | D1: Tingkat Resiko | H1: No | I1: Usia | J1: Jenis Kelamin | K1: Tingkat Resiko | O1: Perhitungan root
A2: =RANDBETWEEN(2,164) | H2: 105 | I2: 61 | J2: 1 | K2: Tinggi | O2: Tinggi | P2: =COUNTIF(K2:K164,"Tinggi") | Q2: =P2/163
A3: =RANDBETWEEN(2,164) | H3: 71 | I3: 84 | J3: 0 | K3: Sedang | O3: Sedang | P3: =COUNTIF(K2:K164,"Sedang") | Q3: =P3/163
A4: =RANDBETWEEN(2,164) | H4: 73 | I4: 15 | J4: 1 | K4: Sedang | O4: Rendah | P4: =COUNTIF(K2:K164,"Rendah") | Q4: =P4/163
A5: =RANDBETWEEN(2,164) | H5: 36 | I5: 27 | J5: 1 | K5: Rendah | O5: Entropy Root | P5: =-(IFERROR(Q2*LOG(Q2,2),0)+IFERROR(Q3*LOG(Q3,2),0)+IFERROR(Q4*LOG(Q4,2),0))
A6: =RANDBETWEEN(2,164) | H6: 15 | I6: 21 | J6: 0 | K6: Rendah
A7: =RANDBETWEEN(2,164) | H7: 49 | I7: 64 | J7: 0 | K7: Sedang
A8: =RANDBETWEEN(2,164) | H8: 106 | I8: 23 | J8: 1 | K8: Tinggi
A9: =RANDBETWEEN(2,164) | H9: 96 | I9: 56 | J9: 0 | K9: Tinggi
A10: =RANDBETWEEN(2,164) | H10: 137 | I10: 3 | J10: 1 | K10: Tinggi
A11: =RANDBETWEEN(2,164) | H11: 33 | I11: 19 | J11: 1 | K11: Sedang
A12: =RANDBETWEEN(2,164) | H12: 74 | I12: 9 | J12: 0 | K12: Sedang
A13: =RANDBETWEEN(2,164) | H13: 164 | I13: 10 | J13: 0 | K13: Rendah
A14: =RANDBETWEEN(2,164) | H14: 89 | I14: 32 | J14: 0 | K14: Sedang
A15: =RANDBETWEEN(2,164) | H15: 15 | I15: 21 | J15: 0 | K15: Rendah
A16: =RANDBETWEEN(2,164) | H16: 75 | I16: 2 | J16: 1 | K16: Sedang
A17: =RANDBETWEEN(2,164) | H17: 24 | I17: 60 | J17: 0 | K17: Sedang
... A164: =RANDBETWEEN(2,164) | H164: 81 | I164: 23 | J164: 1 | K164: Sedang
I165: =AVERAGE(I2:I164) | J165: =AVERAGE(J2:J164)
B166: 63
E168: USIA | N168: JENIS KELAMIN
E169: Usia | F169: =AVERAGEIF($I$2:$I$164,"<="&$I$165) | G169: =AVERAGEIF($I$2:$I$164,">"&$I$165) | N169: Jenis kelamin | O169: =AVERAGEIF($J$2:$J$164,"<="&$J$165) | P169: =AVERAGEIF($J$2:$J$164,">"&$J$165)
E170: {=IF($I$2:$I$164<$F$169,"kiri",IF($I$2:$I$164<$G$169,"tengah","kanan"))} | F170: Kanan > 52.6 | N170: {=IF($J$2:$J$164<$O$169,"kiri",IF($J$2:$J$164<$P$169,"tengah","kanan"))} | O170: Kanan > 1
E171: kanan | F171: =COUNTIFS($E$170:$E$332,"Kanan",$K$2:$K$164,"Tinggi") | G171: =F171/29 | N171: tengah | O171: =COUNTIFS($N$170:$N$332,"Kanan",$K$2:$K$164,"Tinggi") | P171: =O171/97
E172: kiri | F172: =COUNTIFS($E$170:$E$332,"Kanan",$K$2:$K$164,"Sedang") | G172: =F172/29 | N172: kanan | O172: =COUNTIFS($N$170:$N$332,"Kanan",$K$2:$K$164,"Sedang") | P172: =O172/97
E173: tengah | F173: =COUNTIFS($E$170:$E$332,"Kanan",$K$2:$K$164,"Rendah") | G173: =F173/29 | N173: kanan | O173: =COUNTIFS($N$170:$N$332,"Kanan",$K$2:$K$164,"Rendah") | P173: =O173/97
E174: tengah | F174: Entropy | G174: =-(IFERROR(G171*LOG(G171,2),0)+IFERROR(G172*LOG(G172,2),0)+IFERROR(G173*LOG(G173,2),0)) | N174: tengah | O174: Entropy | P174: =-(IFERROR(P171*LOG(P171,2),0)+IFERROR(P172*LOG(P172,2),0)+IFERROR(P173*LOG(P173,2),0))
E175: kanan | G175: =SUM(F171:F173)/163 | N175: tengah | P175: =SUM(O171:O173)/163
E176: tengah | G176: =G174*G175 | N176: kanan | P176: =P174*P175
E177: kanan | N177: tengah
E178: kiri | N178: kanan
E179: tengah | F179: Kiri<15.89 | N179: kanan | O179: Kiri<0
E180: kiri | F180: =COUNTIFS($E$170:$E$332,"Kiri",$K$2:$K$164,"Tinggi") | G180: =F180/46 | N180: tengah | O180: =COUNTIFS($N$170:$N$332,"Kiri",$K$2:$K$164,"Tinggi") | P180: =O180/97
E181: kiri | F181: =COUNTIFS($E$170:$E$332,"Kiri",$K$2:$K$164,"Sedang") | G181: =F181/46 | N181: tengah | O181: =COUNTIFS($N$170:$N$332,"Kiri",$K$2:$K$164,"Sedang") | P181: =O181/97
E182: tengah | F182: =COUNTIFS($E$170:$E$332,"Kiri",$K$2:$K$164,"Rendah") | G182: =F182/46 | N182: tengah | O182: =COUNTIFS($N$170:$N$332,"Kiri",$K$2:$K$164,"Rendah") | P182: =O182/97
E183: tengah | F183: Entropy | G183: =-(IFERROR(G180*LOG(G180,2),0)+IFERROR(G181*LOG(G181,2),0)+IFERROR(G182*LOG(G182,2),0)) | N183: tengah | O183: Entropy | P183: =-(IFERROR(P180*LOG(P180,2),0)+IFERROR(P181*LOG(P181,2),0)+IFERROR(P182*LOG(P182,2),0))
E184: kiri | G184: =SUM(F180:F182)/163 | N184: kanan | P184: =SUM(O180:O182)/163
E185: kanan | G185: =G183*G184 | N185: tengah | P185: =P183*P184
E186: tengah | N186: kanan
E187: tengah | N187: kanan
...

Sheet Pohon 8 (BP)
A1: No | B1: Usia | C1: Tingkat Resiko | H1: No | I1: Usia | J1: Tingkat Resiko | O1: Perhitungan root
A2: =RANDBETWEEN(2,164) | H2: 102 | I2: 41 | J2: Tinggi | O2: Tinggi | P2: =COUNTIF(J2:J164,"Tinggi") | Q2: =P2/163
A3: =RANDBETWEEN(2,164) | H3: 76 | I3: 70 | J3: Sedang | O3: Sedang | P3: =COUNTIF(J2:J164,"Sedang") | Q3: =P3/163
A4: =RANDBETWEEN(2,164) | H4: 163 | I4: 34 | J4: Rendah | O4: Rendah | P4: =COUNTIF(J2:J164,"Rendah") | Q4: =P4/163
A5: =RANDBETWEEN(2,164) | H5: 28 | I5: 22 | J5: Sedang | O5: Entropy Root | P5: =-(IFERROR(Q2*LOG(Q2,2),0)+IFERROR(Q3*LOG(Q3,2),0)+IFERROR(Q4*LOG(Q4,2),0))
A6: =RANDBETWEEN(2,164) | H6: 161 | I6: 12 | J6: Tinggi
A7: =RANDBETWEEN(2,164) | H7: 148 | I7: 55 | J7: Tinggi
A8: =RANDBETWEEN(2,164) | H8: 81 | I8: 23 | J8: Sedang
A9: =RANDBETWEEN(2,164) | H9: 8 | I9: 4 | J9: Sedang
A10: =RANDBETWEEN(2,164) | H10: 116 | I10: 32 | J10: Tinggi
A11: =RANDBETWEEN(2,164) | H11: 17 | I11: 2 | J11: Rendah
A12: =RANDBETWEEN(2,164) | H12: 162 | I12: 22 | J12: Rendah
A13: =RANDBETWEEN(2,164) | H13: 7 | I13: 12 | J13: Sedang
A14: =RANDBETWEEN(2,164) | H14: 25 | I14: 81 | J14: Sedang
A15: =RANDBETWEEN(2,164) | H15: 143 | I15: 20 | J15: Tinggi
A16: =RANDBETWEEN(2,164) | H16: 22 | I16: 6 | J16: Sedang
A17: =RANDBETWEEN(2,164) | H17: 86 | I17: 23 | J17: Sedang
... A164: =RANDBETWEEN(2,164) | H164: 60 | I164: 68 | J164: Sedang
I165: =AVERAGE(I2:I164)
B166: 99
E168: USIA
E169: Usia | F169: =AVERAGEIF($I$2:$I$164,"<="&$I$165) | G169: =AVERAGEIF($I$2:$I$164,">"&$I$165)
E170: {=IF($I$2:$I$164<$F$169,"kiri",IF($I$2:$I$164<$G$169,"tengah","kanan"))} | F170: Kanan > 54.27
E171: kanan | F171: =COUNTIFS($E$170:$E$332,"Kanan",$J$2:$J$164,"Tinggi") | G171: =F171/32
E172: tengah | F172: =COUNTIFS($E$170:$E$332,"Kanan",$J$2:$J$164,"Sedang") | G172: =F172/32
E173: tengah | F173: =COUNTIFS($E$170:$E$332,"Kanan",$J$2:$J$164,"Rendah") | G173: =F173/32
E174: kiri | F174: Entropy | G174: =-(IFERROR(G171*LOG(G171,2),0)+IFERROR(G172*LOG(G172,2),0)+IFERROR(G173*LOG(G173,2),0))
E175: kanan | G175: =SUM(F171:F173)/163
E176: tengah | G176: =G174*G175
E177: kiri
E178: tengah
E179: kiri | F179: Kiri<15.70
E180: tengah | F180: =COUNTIFS($E$170:$E$332,"Kiri",$J$2:$J$164,"Tinggi") | G180: =F180/46
E181: kiri | F181: =COUNTIFS($E$170:$E$332,"Kiri",$J$2:$J$164,"Sedang") | G181: =F181/46
E182: kanan | F182: =COUNTIFS($E$170:$E$332,"Kiri",$J$2:$J$164,"Rendah") | G182: =F182/46
E183: tengah | F183: Entropy | G183: =-(IFERROR(G180*LOG(G180,2),0)+IFERROR(G181*LOG(G181,2),0)+IFERROR(G182*LOG(G182,2),0))
E184: kiri | G184: =SUM(F180:F182)/163
E185: tengah | G185: =G183*G184
E186: kanan
E187: kiri
...

Sheet Pohon 9
A1: No | B1: Usia | C1: Lama Rawat Inap | D1: Jumlah Kasus Per Bulan | E1: Jenis Kelamin | F1: Tingkat Resiko | H1: No | I1: Usia | J1: Lama Rawat Inap | K1: Jumlah Kasus Per Bulan | L1: Jenis Kelamin | M1: Tingkat Resiko | O1: Perhitungan root
A2: =RANDBETWEEN(2,164) | B2: {=INDEX(Data_DBD!$B:$B,$A2)} | C2: {=INDEX(Data_DBD!$C:$C,$A2)} | D2: {=INDEX(Data_DBD!$D:$D,$A2)} | E2: {=INDEX(Data_DBD!$E:$E,$A2)} | F2: {=INDEX(Data_DBD!$F:$F,$A2)} | H2: 76 | I2: 70 | J2: 2 | K2: 10 | L2: 0 | M2: Sedang | O2: Tinggi | P2: =COUNTIF(M2:M164,"Tinggi") | Q2: =P2/163
A3: =RANDBETWEEN(2,164) | B3: {=INDEX(Data_DBD!$B:$B,$A3)} | C3: {=INDEX(Data_DBD!$C:$C,$A3)} | D3: {=INDEX(Data_DBD!$D:$D,$A3)} | E3: {=INDEX(Data_DBD!$E:$E,$A3)} | F3: {=INDEX(Data_DBD!$F:$F,$A3)} | H3: 125 | I3: 39 | J3: 4 | K3: 33 | L3: 0 | M3: Tinggi | O3: Sedang | P3: =COUNTIF(M2:M164,"Sedang") | Q3: =P3/163
A4: =RANDBETWEEN(2,164) | B4: {=INDEX(Data_DBD!$B:$B,$A4)} | C4: {=INDEX(Data_DBD!$C:$C,$A4)} | D4: {=INDEX(Data_DBD!$D:$D,$A4)} | E4: {=INDEX(Data_DBD!$E:$E,$A4)} | F4: {=INDEX(Data_DBD!$F:$F,$A4)} | H4: 126 | I4: 51 | J4: 3 | K4: 33 | L4: 1 | M4: Tinggi | O4: Rendah | P4: =COUNTIF(M2:M164,"Rendah") | Q4: =P4/163
A5: =RANDBETWEEN(2,164) | B5: {=INDEX(Data_DBD!$B:$B,$A5)} | C5: {=INDEX(Data_DBD!$C:$C,$A5)} | D5: {=INDEX(Data_DBD!$D:$D,$A5)} | E5: {=INDEX(Data_DBD!$E:$E,$A5)} | F5: {=INDEX(Data_DBD!$F:$F,$A5)} | H5: 140 | I5: 74 | J5: 5 | K5: 21 | L5: 1 | M5: Tinggi | O5: Entropy Root | P5: =-(IFERROR(Q2*LOG(Q2,2),0)+IFERROR(Q3*LOG(Q3,2),0)+IFERROR(Q4*LOG(Q4,2),0))
A6: =RANDBETWEEN(2,164) | B6: {=INDEX(Data_DBD!$B:$B,$A6)} | C6: {=INDEX(Data_DBD!$C:$C,$A6)} | D6: {=INDEX(Data_DBD!$D:$D,$A6)} | E6: {=INDEX(Data_DBD!$E:$E,$A6)} | F6: {=INDEX(Data_DBD!$F:$F,$A6)} | H6: 73 | I6: 15 | J6: 3 | K6: 10 | L6: 1 | M6: Sedang
A7: =RANDBETWEEN(2,164) | B7: {=INDEX(Data_DBD!$B:$B,$A7)} | C7: {=INDEX(Data_DBD!$C:$C,$A7)} | D7: {=INDEX(Data_DBD!$D:$D,$A7)} | E7: {=INDEX(Data_DBD!$E:$E,$A7)} | F7: {=INDEX(Data_DBD!$F:$F,$A7)} | H7: 125 | I7: 39 | J7: 4 | K7: 33 | L7: 0 | M7: Tinggi
A8: =RANDBETWEEN(2,164) | B8: {=INDEX(Data_DBD!$B:$B,$A8)} | C8: {=INDEX(Data_DBD!$C:$C,$A8)} | D8: {=INDEX(Data_DBD!$D:$D,$A8)} | E8: {=INDEX(Data_DBD!$E:$E,$A8)} | F8: {=INDEX(Data_DBD!$F:$F,$A8)} | H8: 119 | I8: 30 | J8: 7 | K8: 33 | L8: 0 | M8: Tinggi
A9: =RANDBETWEEN(2,164) | B9: {=INDEX(Data_DBD!$B:$B,$A9)} | C9: {=INDEX(Data_DBD!$C:$C,$A9)} | D9: {=INDEX(Data_DBD!$D:$D,$A9)} | E9: {=INDEX(Data_DBD!$E:$E,$A9)} | F9: {=INDEX(Data_DBD!$F:$F,$A9)} | H9: 11 | I9: 24 | J9: 5 | K9: 12 | L9: 1 | M9: Sedang
A10: =RANDBETWEEN(2,164) | B10: {=INDEX(Data_DBD!$B:$B,$A10)} | C10: {=INDEX(Data_DBD!$C:$C,$A10)} | D10: {=INDEX(Data_DBD!$D:$D,$A10)} | E10: {=INDEX(Data_DBD!$E:$E,$A10)} | F10: {=INDEX(Data_DBD!$F:$F,$A10)} | H10: 125 | I10: 39 | J10: 4 | K10: 33 | L10: 0 | M10: Tinggi
A11: =RANDBETWEEN(2,164) | B11: {=INDEX(Data_DBD!$B:$B,$A11)} | C11: {=INDEX(Data_DBD!$C:$C,$A11)} | D11: {=INDEX(Data_DBD!$D:$D,$A11)} | E11: {=INDEX(Data_DBD!$E:$E,$A11)} | F11: {=INDEX(Data_DBD!$F:$F,$A11)} | H11: 39 | I11: 12 | J11: 5 | K11: 13 | L11: 1 | M11: Sedang
A12: =RANDBETWEEN(2,164) | B12: {=INDEX(Data_DBD!$B:$B,$A12)} | C12: {=INDEX(Data_DBD!$C:$C,$A12)} | D12: {=INDEX(Data_DBD!$D:$D,$A12)} | E12: {=INDEX(Data_DBD!$E:$E,$A12)} | F12: {=INDEX(Data_DBD!$F:$F,$A12)} | H12: 23 | I12: 28 | J12: 4 | K12: 14 | L12: 1 | M12: Sedang
A13: =RANDBETWEEN(2,164) | B13: {=INDEX(Data_DBD!$B:$B,$A13)} | C13: {=INDEX(Data_DBD!$C:$C,$A13)} | D13: {=INDEX(Data_DBD!$D:$D,$A13)} | E13: {=INDEX(Data_DBD!$E:$E,$A13)} | F13: {=INDEX(Data_DBD!$F:$F,$A13)} | H13: 129 | I13: 4 | J13: 3 | K13: 33 | L13: 0 | M13: Tinggi
A14: =RANDBETWEEN(2,164) | B14: {=INDEX(Data_DBD!$B:$B,$A14)} | C14: {=INDEX(Data_DBD!$C:$C,$A14)} | D14: {=INDEX(Data_DBD!$D:$D,$A14)} | E14: {=INDEX(Data_DBD!$E:$E,$A14)} | F14: {=INDEX(Data_DBD!$F:$F,$A14)} | H14: 86 | I14: 23 | J14: 3 | K14: 13 | L14: 0 | M14: Sedang
A15: =RANDBETWEEN(2,164) | B15: {=INDEX(Data_DBD!$B:$B,$A15)} | C15: {=INDEX(Data_DBD!$C:$C,$A15)} | D15: {=INDEX(Data_DBD!$D:$D,$A15)} | E15: {=INDEX(Data_DBD!$E:$E,$A15)} | F15: {=INDEX(Data_DBD!$F:$F,$A15)} | H15: 58 | I15: 17 | J15: 3 | K15: 15 | L15: 0 | M15: Sedang
A16: =RANDBETWEEN(2,164) | B16: {=INDEX(Data_DBD!$B:$B,$A16)} | C16: {=INDEX(Data_DBD!$C:$C,$A16)} | D16: {=INDEX(Data_DBD!$D:$D,$A16)} | E16: {=INDEX(Data_DBD!$E:$E,$A16)} | F16: {=INDEX(Data_DBD!$F:$F,$A16)} | H16: 134 | I16: 4 | J16: 2 | K16: 33 | L16: 1 | M16: Tinggi
A17: =RANDBETWEEN(2,164) | B17: {=INDEX(Data_DBD!$B:$B,$A17)} | C17: {=INDEX(Data_DBD!$C:$C,$A17)} | D17: {=INDEX(Data_DBD!$D:$D,$A17)} | E17: {=INDEX(Data_DBD!$E:$E,$A17)} | F17: {=INDEX(Data_DBD!$F:$F,$A17)} | H17: 102 | I17: 41 | J17: 4 | K17: 18 | L17: 0 | M17: Tinggi
... A164: =RANDBETWEEN(2,164) | B164: {=INDEX(Data_DBD!$B:$B,$A164)} | C164: {=INDEX(Data_DBD!$C:$C,$A164)} | D164: {=INDEX(Data_DBD!$D:$D,$A164)} | E164: {=INDEX(Data_DBD!$E:$E,$A164)} | F164: {=INDEX(Data_DBD!$F:$F,$A164)} | H164: 151 | I164: 24 | J164: 3 | K164: 21 | L164: 0 | M164: Tinggi
I165: =AVERAGE(I2:I164) | J165: =AVERAGE(J2:J164) | K165: =AVERAGE(K2:K164) | L165: =AVERAGE(L2:L164)
B166: 66
E168: USIA | J168: LAMA RAWAT INAP | O168: JUMLAH KASUS PER BULAN | T168: JENIS KELAMIN
E169: Usia | F169: =AVERAGEIF($I$2:$I$164,"<="&$I$165) | G169: =AVERAGEIF($I$2:$I$164,">"&$I$165) | J169: Lama rawat inap | K169: =AVERAGEIF($J$2:$J$164,"<="&$J$165) | L169: =AVERAGEIF($J$2:$J$164,">"&$J$165) | O169: Jumlah kasus perbulan | P169: =AVERAGEIF($K$2:$K$164,"<="&$K$165) | Q169: =AVERAGEIF($K$2:$K$164,">"&$K$165) | T169: Jenis kelamin | U169: =AVERAGEIF($L$2:$L$164,"<="&$L$165) | V169: =AVERAGEIF($L$2:$L$164,">"&$L$165)
E170: {=IF($I$2:$I$164<$F$169,"kiri",IF($I$2:$I$164<$G$169,"tengah","kanan"))} | F170: Kanan > 51.19 | J170: {=IF($J$2:$J$164<$K$169,"kiri",IF($J$2:$J$164<$L$169,"tengah","kanan"))} | K170: Kanan > 4.73 | O170: {=IF($K$2:$K$164<$P$169,"kiri",IF($K$2:$K$164<$Q$169,"tengah","kanan"))} | P170: Kanan > 25.95 | T170: {=IF($L$2:$L$164<$U$169,"kiri",IF($L$2:$L$164<$V$169,"tengah","kanan"))} | U170: Kanan > 1
E171: tengah | F171: =COUNTIFS($E$170:$E$332,"Kanan",$M$2:$M$164,"Tinggi") | G171: =F171/30 | J171: tengah | K171: =COUNTIFS($J$170:$J$332,"Kanan",$M$2:$M$164,"Tinggi") | L171: =K171/35 | O171: kanan | P171: =COUNTIFS($O$170:$O$332,"Kanan",$M$2:$M$164,"Tinggi") | Q171: =P171/34 | T171: tengah | U171: =COUNTIFS($T$170:$T$332,"Kanan",$M$2:$M$164,"Tinggi") | V171: =U171/79
E172: tengah | F172: =COUNTIFS($E$170:$E$332,"Kanan",$M$2:$M$164,"Sedang") | G172: =F172/30 | J172: tengah | K172: =COUNTIFS($J$170:$J$332,"Kanan",$M$2:$M$164,"Sedang") | L172: =K172/35 | O172: kanan | P172: =COUNTIFS($O$170:$O$332,"Kanan",$M$2:$M$164,"Sedang") | Q172: =P172/27 | T172: kanan | U172: =COUNTIFS($T$170:$T$332,"Kanan",$M$2:$M$164,"Sedang") | V172: =U172/79
E173: kanan | F173: =COUNTIFS($E$170:$E$332,"Kanan",$M$2:$M$164,"Rendah") | G173: =F173/30 | J173: kanan | K173: =COUNTIFS($J$170:$J$332,"Kanan",$M$2:$M$164,"Rendah") | L173: =K173/35 | O173: tengah | P173: =COUNTIFS($O$170:$O$332,"Kanan",$M$2:$M$164,"Rendah") | Q173: =P173/27 | T173: kanan | U173: =COUNTIFS($T$170:$T$332,"Kanan",$M$2:$M$164,"Rendah") | V173: =U173/79
E174: kiri | F174: Entropy | G174: =-(IFERROR(G171*LOG(G171,2),0)+IFERROR(G172*LOG(G172,2),0)+IFERROR(G173*LOG(G173,2),0)) | J174: tengah | K174: Entropy | L174: =-(IFERROR(L171*LOG(L171,2),0)+IFERROR(L172*LOG(L172,2),0)+IFERROR(L173*LOG(L173,2),0)) | O174: kiri | P174: Entropy | Q174: =-(IFERROR(Q171*LOG(Q171,2),0)+IFERROR(Q172*LOG(Q172,2),0)+IFERROR(Q173*LOG(Q173,2),0)) | T174: kanan | U174: Entropy | V174: =-(IFERROR(V171*LOG(V171,2),0)+IFERROR(V172*LOG(V172,2),0)+IFERROR(V173*LOG(V173,2),0))
E175: tengah | G175: =SUM(F171:F173)/163 | J175: tengah | L175: =SUM(K171:K173)/163 | O175: kanan | Q175: =SUM(P171:P173)/163 | T175: tengah | V175: =SUM(U171:U173)/163
E176: tengah | G176: =G174*G175 | J176: kanan | L176: =L174*L175 | O176: kanan | Q176: =Q174*Q175 | T176: tengah | V176: =V174*V175
E177: tengah | J177: kanan | O177: tengah | T177: kanan
