Workbook

Sheet Data_DBD
A1: Nama | B1: Usia | C1: Lama Rawat Inap | D1: Jumlah Kasus Perbulan | E1: Jenis Kelamin | F1: Terdeteksi
A2: Neni Sumetria | B2: 34 | C2: 3 | D2: 12 | E2: 0 | F2: 2
A3: Malki Amron | B3: 43 | C3: 3 | D3: 12 | E3: 1 | F3: 2
A4: Arifa Qyaratul | B4: 23 | C4: 5 | D4: 12 | E4: 0 | F4: 2
A5: Rezki Mhd | B5: 18 | C5: 2 | D5: 12 | E5: 1 | F5: 2
A6: Selfiolla | B6: 14 | C6: 4 | D6: 12 | E6: 0 | F6: 2
A7: M.Albiruni | B7: 12 | C7: 1 | D7: 12 | E7: 1 | F7: 2
A8: Yurika Azarine | B8: 4 | C8: 2 | D8: 12 | E8: 0 | F8: 2
A9: Rahmad Ihtiar | B9: 16 | C9: 6 | D9: 12 | E9: 1 | F9: 2
A10: Tiara Endiwa | B10: 18 | C10: 5 | D10: 12 | E10: 0 | F10: 2
A11: Boby | B11: 24 | C11: 5 | D11: 12 | E11: 1 | F11: 2
A12: Defi Putri | B12: 23 | C12: 3 | D12: 12 | E12: 0 | F12: 2
A13: Nini Efriza | B13: 47 | C13: 2 | D13: 12 | E13: 0 | F13: 2
... A29: Ade Sepriyanto | B29: 19 | C29: 2 | D29: 14 | E29: 1 | F29: 2
A30: Diendri Barakta | B30: 2,8 | C30: 2 | D30: 14 | E30: 1 | F30: 2
A31: Suwardi | B31: 64 | C31: 4 | D31: 14 | E31: 1 | F31: 2
A32: Emelya Nora | B32: 54 | C32: 4 | D32: 14 | E32: 0 | F32: 2
A33: Eosel Rizkia | B33: 19 | C33: 4 | D33: 14 | E33: 1 | F33: 2
A34: Warmaneti | B34: 55 | C34: 3 | D34: 14 | E34: 0 | F34: 2
A35: Yandril | B35: 40 | C35: 3 | D35: 4 | E35: 1 | F35: 1
A36: Romy Herina | B36: 27 | C36: 1 | D36: 4 | E36: 1 | F36: 1
A37: Ilham Saputra | B37: 28 | C37: 4 | D37: 4 | E37: 1 | F37: 1
A38: Berli Simanjuntak | B38: 52 | C38: 3 | D38: 4 | E38: 1 | F38: 1
A39: M. Hafiz | B39: 12 | C39: 5 | D39: 13 | E39: 1 | F39: 2
A40: Yusril | B40: 65 | C40: 3 | D40: 13 | E40: 1 | F40: 2
A41: Anggifa Fitria | B41: 8 | C41: 4 | D41: 13 | E41: 0 | F41: 2
A42: Abdul Fikri | B42: 21 | C42: 5 | D42: 13 | E42: 1 | F42: 2
... A164: Aprillia Khairunnisa | B164: 10 | C164: 6 | D164: 3 | E164: 0 | F164: 1

Sheet Pemilihan Fitur
A1: Random Sampling Data
A3: Usia | B3: =RAND() -> 0.60426065 | C3: =INDEX($A$3:$A$6,MATCH(LARGE($B$3:$B$6,ROW(Y1)),$B$3:$B$6,0)) -> Usia
A4: Lama Rawat Inap | B4: =RAND() -> 0.17187702 | C4: =INDEX($A$3:$A$6,MATCH(LARGE($B$3:$B$6,ROW(Y2)),$B$3:$B$6,0)) -> Jumlah Kasus Per Bulan
A5: Jenis Kelamin | B5: =RAND() -> 0.16804879
A6: Jumlah Kasus Per Bulan | B6: =RAND() -> 0.51980343 | D6: 9

Sheet Data Uji
A1: Usia | B1: Lama Rawat Inap | C1: Jumlah Kasus Perbulan | D1: Jenis Kelamin | E1: Tingkat Resiko
A2: 34 | B2: 3 | C2: 12 | D2: 0 | E2: 2
A3: 43 | B3: 3 | C3: 12 | D3: 1 | E3: 2
A4: 49 | B4: 4 | C4: 7 | D4: 1 | E4: 1
A5: 21 | B5: 2 | C5: 7 | D5: 0 | E5: 1
A6: 16 | B6: 2 | C6: 18 | D6: 1 | E6: 3
A7: 16 | B7: 2 | C7: 18 | D7: 1 | E7: 3
A8: 4 | B8: 2 | C8: 18 | D8: 1 | E8: 3
A9: 19 | B9: 6 | C9: 18 | D9: 0 | E9: 3
A10: 12 | B10: 3 | C10: 21 | D10: 1 | E10: 3
A11: 22 | B11: 3 | C11: 3 | D11: 1 | E11: 1

Sheet Data Latih
A1: Usia | B1: Lama Rawat Inap | C1: Jumlah Kasus Per Bulan | D1: Jenis Kelamin | E1: Tingkat Resiko
A2: 21 | B2: 5 | C2: 13 | D2: 1 | E2: Sedang
A3: 19 | B3: 2 | C3: 13 | D3: 0 | E3: Sedang
A4: 22 | B4: 4 | C4: 33 | D4: 0 | E4: Tinggi
A5: 59 | B5: 4 | C5: 15 | D5: 1 | E5: Sedang
A6: 25 | B6: 4 | C6: 33 | D6: 0 | E6: Tinggi
A7: 5 | B7: 2 | C7: 21 | D7: 0 | E7: Tinggi
A8: 35 | B8: 1 | C8: 15 | D8: 0 | E8: Sedang
A9: 16 | B9: 3 | C9: 21 | D9: 0 | E9: Tinggi
A10: 28 | B10: 3 | C10: 13 | D10: 1 | E10: Sedang
A11: 14 | B11: 4 | C11: 12 | D11: 0 | E11: Sedang
A12: 82 | B12: 5 | C12: 33 | D12: 1 | E12: Tinggi
A13: 13 | B13: 3 | C13: 33 | D13: 1 | E13: Tinggi
... A164: 24 | B164: 4 | C164: 10 | D164: 1 | E164: Sedang

Sheet Pohon 1
A1: No | B1: Usia | C1: Lama Rawat Inap | D1: Jumlah Kasus Per Bulan | E1: Jenis Kelamin | F1: Tingkat Resiko | H1: No | I1: Usia | J1: Lama Rawat Inap | K1: Jumlah Kasus Per Bulan | L1: Jenis Kelamin | M1: Tingkat Resiko | O1: Perhitungan root
A2: =RANDBETWEEN(2,164) -> 72 | B2: {=INDEX(Data_DBD!$B:$B,$A2)} -> 3 | C2: {=INDEX(Data_DBD!$C:$C,$A2)} -> 5 | D2: {=INDEX(Data_DBD!$D:$D,$A2)} -> 10 | E2: {=INDEX(Data_DBD!$E:$E,$A2)} -> 1 | F2: {=INDEX(Data_DBD!$F:$F,$A2)} -> 2 | H2: 39 | I2: 12 | J2: 5 | K2: 13 | L2: 1 | M2: 2 | O2: 1 | P2: =COUNTIF(M2:M164,"1") -> 6 | Q2: =P2/163 -> 0.036809816 | S2: Ket | T2: 1=Rendah
A3: =RANDBETWEEN(2,164) -> 73 | B3: {=INDEX(Data_DBD!$B:$B,$A3)} -> 15 | C3: {=INDEX(Data_DBD!$C:$C,$A3)} -> 3 | D3: {=INDEX(Data_DBD!$D:$D,$A3)} -> 10 | E3: {=INDEX(Data_DBD!$E:$E,$A3)} -> 1 | F3: {=INDEX(Data_DBD!$F:$F,$A3)} -> 2 | H3: 72 | I3: 3 | J3: 5 | K3: 10 | L3: 1 | M3: 2 | O3: 2 | P3: =COUNTIF(M2:M164,"2") -> 81 | Q3: =P3/163 -> 0.49693252 | T3: 2 = Sedang
A4: =RANDBETWEEN(2,164) -> 57 | B4: {=INDEX(Data_DBD!$B:$B,$A4)} -> 2 | C4: {=INDEX(Data_DBD!$C:$C,$A4)} -> 2 | D4: {=INDEX(Data_DBD!$D:$D,$A4)} -> 15 | E4: {=INDEX(Data_DBD!$E:$E,$A4)} -> 1 | F4: {=INDEX(Data_DBD!$F:$F,$A4)} -> 2 | H4: 135 | I4: 10 | J4: 2 | K4: 33 | L4: 0 | M4: 3 | O4: 3 | P4: =COUNTIF(M2:M164,"3") -> 76 | Q4: =P4/163 -> 0.46625767 | T4: 3 = Tinggi
A5: =RANDBETWEEN(2,164) -> 125 | B5: {=INDEX(Data_DBD!$B:$B,$A5)} -> 39 | C5: {=INDEX(Data_DBD!$C:$C,$A5)} -> 4 | D5: {=INDEX(Data_DBD!$D:$D,$A5)} -> 33 | E5: {=INDEX(Data_DBD!$E:$E,$A5)} -> 0 | F5: {=INDEX(Data_DBD!$F:$F,$A5)} -> 3 | H5: 74 | I5: 9 | J5: 4 | K5: 10 | L5: 0 | M5: 2 | O5: Entropy Root | P5: =-(IFERROR(Q2*LOG(Q2,2),0)+IFERROR(Q3*LOG(Q3,2),0)+IFERROR(Q4*LOG(Q4,2),0)) -> 1.1899544
A6: =RANDBETWEEN(2,164) -> 16 | B6: {=INDEX(Data_DBD!$B:$B,$A6)} -> 66 | C6: {=INDEX(Data_DBD!$C:$C,$A6)} -> 5 | D6: {=INDEX(Data_DBD!$D:$D,$A6)} -> 7 | E6: {=INDEX(Data_DBD!$E:$E,$A6)} -> 1 | F6: {=INDEX(Data_DBD!$F:$F,$A6)} -> 1 | H6: 78 | I6: 6 | J6: 3 | K6: 13 | L6: 0 | M6: 2
A7: =RANDBETWEEN(2,164) -> 49 | B7: {=INDEX(Data_DBD!$B:$B,$A7)} -> 64 | C7: {=INDEX(Data_DBD!$C:$C,$A7)} -> 5 | D7: {=INDEX(Data_DBD!$D:$D,$A7)} -> 13 | E7: {=INDEX(Data_DBD!$E:$E,$A7)} -> 0 | F7: {=INDEX(Data_DBD!$F:$F,$A7)} -> 2 | H7: 94 | I7: 12 | J7: 4 | K7: 18 | L7: 0 | M7: 3
A8: =RANDBETWEEN(2,164) -> 14 | B8: {=INDEX(Data_DBD!$B:$B,$A8)} -> 49 | C8: {=INDEX(Data_DBD!$C:$C,$A8)} -> 4 | D8: {=INDEX(Data_DBD!$D:$D,$A8)} -> 7 | E8: {=INDEX(Data_DBD!$E:$E,$A8)} -> 1 | F8: {=INDEX(Data_DBD!$F:$F,$A8)} -> 1 | H8: 124 | I8: 24 | J8: 3 | K8: 33 | L8: 1 | M8: 3
A9: =RANDBETWEEN(2,164) -> 157 | B9: {=INDEX(Data_DBD!$B:$B,$A9)} -> 15 | C9: {=INDEX(Data_DBD!$C:$C,$A9)} -> 4 | D9: {=INDEX(Data_DBD!$D:$D,$A9)} -> 21 | E9: {=INDEX(Data_DBD!$E:$E,$A9)} -> 1 | F9: {=INDEX(Data_DBD!$F:$F,$A9)} -> 3 | H9: 63 | I9: 25 | J9: 3 | K9: 15 | L9: 0 | M9: 2
A10: =RANDBETWEEN(2,164) -> 40 | B10: {=INDEX(Data_DBD!$B:$B,$A10)} -> 65 | C10: {=INDEX(Data_DBD!$C:$C,$A10)} -> 3 | D10: {=INDEX(Data_DBD!$D:$D,$A10)} -> 13 | E10: {=INDEX(Data_DBD!$E:$E,$A10)} -> 1 | F10: {=INDEX(Data_DBD!$F:$F,$A10)} -> 2 | G10: = | H10: 70 | I10: 26 | J10: 3 | K10: 10 | L10: 1 | M10: 2
A11: =RANDBETWEEN(2,164) -> 74 | B11: {=INDEX(Data_DBD!$B:$B,$A11)} -> 9 | C11: {=INDEX(Data_DBD!$C:$C,$A11)} -> 4 | D11: {=INDEX(Data_DBD!$D:$D,$A11)} -> 10 | E11: {=INDEX(Data_DBD!$E:$E,$A11)} -> 0 | F11: {=INDEX(Data_DBD!$F:$F,$A11)} -> 2 | H11: 29 | I11: 19 | J11: 2 | K11: 14 | L11: 1 | M11: 2
A12: =RANDBETWEEN(2,164) -> 163 | B12: {=INDEX(Data_DBD!$B:$B,$A12)} -> 34 | C12: {=INDEX(Data_DBD!$C:$C,$A12)} -> 4 | D12: {=INDEX(Data_DBD!$D:$D,$A12)} -> 3 | E12: {=INDEX(Data_DBD!$E:$E,$A12)} -> 1 | F12: {=INDEX(Data_DBD!$F:$F,$A12)} -> 1 | H12: 146 | I12: 34 | J12: 2 | K12: 21 | L12: 1 | M12: 3
A13: =RANDBETWEEN(2,164) -> 51 | B13: {=INDEX(Data_DBD!$B:$B,$A13)} -> 48 | C13: {=INDEX(Data_DBD!$C:$C,$A13)} -> 4 | D13: {=INDEX(Data_DBD!$D:$D,$A13)} -> 13 | E13: {=INDEX(Data_DBD!$E:$E,$A13)} -> 0 | F13: {=INDEX(Data_DBD!$F:$F,$A13)} -> 2 | H13: 4 | I13: 23 | J13: 5 | K13: 12 | L13: 0 | M13: 2
A14: =RANDBETWEEN(2,164) -> 52 | B14: {=INDEX(Data_DBD!$B:$B,$A14)} -> 59 | C14: {=INDEX(Data_DBD!$C:$C,$A14)} -> 4 | D14: {=INDEX(Data_DBD!$D:$D,$A14)} -> 15 | E14: {=INDEX(Data_DBD!$E:$E,$A14)} -> 1 | F14: {=INDEX(Data_DBD!$F:$F,$A14)} -> 2 | H14: 121 | I14: 82 | J14: 5 | K14: 33 | L14: 1 | M14: 3
A15: =RANDBETWEEN(2,164) -> 98 | B15: {=INDEX(Data_DBD!$B:$B,$A15)} -> 16 | C15: {=INDEX(Data_DBD!$C:$C,$A15)} -> 2 | D15: {=INDEX(Data_DBD!$D:$D,$A15)} -> 18 | E15: {=INDEX(Data_DBD!$E:$E,$A15)} -> 1 | F15: {=INDEX(Data_DBD!$F:$F,$A15)} -> 3 | H15: 53 | I15: 35 | J15: 4 | K15: 15 | L15: 1 | M15: 2
A16: =RANDBETWEEN(2,164) -> 119 | B16: {=INDEX(Data_DBD!$B:$B,$A16)} -> 30 | C16: {=INDEX(Data_DBD!$C:$C,$A16)} -> 7 | D16: {=INDEX(Data_DBD!$D:$D,$A16)} -> 33 | E16: {=INDEX(Data_DBD!$E:$E,$A16)} -> 0 | F16: {=INDEX(Data_DBD!$F:$F,$A16)} -> 3 | H16: 127 | I16: 21 | J16: 2 | K16: 33 | L16: 0 | M16: 3
A17: =RANDBETWEEN(2,164) -> 133 | B17: {=INDEX(Data_DBD!$B:$B,$A17)} -> 6 | C17: {=INDEX(Data_DBD!$C:$C,$A17)} -> 4 | D17: {=INDEX(Data_DBD!$D:$D,$A17)} -> 33 | E17: {=INDEX(Data_DBD!$E:$E,$A17)} -> 0 | F17: {=INDEX(Data_DBD!$F:$F,$A17)} -> 3 | H17: 52 | I17: 59 | J17: 4 | K17: 15 | L17: 1 | M17: 2
A18: =RANDBETWEEN(2,164) -> 123 | B18: {=INDEX(Data_DBD!$B:$B,$A18)} -> 22 | C18: {=INDEX(Data_DBD!$C:$C,$A18)} -> 4 | D18: {=INDEX(Data_DBD!$D:$D,$A18)} -> 33 | E18: {=INDEX(Data_DBD!$E:$E,$A18)} -> 0 | F18: {=INDEX(Data_DBD!$F:$F,$A18)} -> 3 | H18: 88 | I18: 20 | J18: 4 | K18: 13 | L18: 1 | M18: 2
A19: =RANDBETWEEN(2,164) -> 114 | B19: {=INDEX(Data_DBD!$B:$B,$A19)} -> 14 | C19: {=INDEX(Data_DBD!$C:$C,$A19)} -> 2 | D19: {=INDEX(Data_DBD!$D:$D,$A19)} -> 33 | E19: {=INDEX(Data_DBD!$E:$E,$A19)} -> 1 | F19: {=INDEX(Data_DBD!$F:$F,$A19)} -> 3 | H19: 86 | I19: 23 | J19: 3 | K19: 13 | L19: 0 | M19: 2
A20: =RANDBETWEEN(2,164) -> 12 | B20: {=INDEX(Data_DBD!$B:$B,$A20)} -> 23 | C20: {=INDEX(Data_DBD!$C:$C,$A20)} -> 3 | D20: {=INDEX(Data_DBD!$D:$D,$A20)} -> 12 | E20: {=INDEX(Data_DBD!$E:$E,$A20)} -> 0 | F20: {=INDEX(Data_DBD!$F:$F,$A20)} -> 2 | H20: 56 | I20: 4 | J20: 3 | K20: 15 | L20: 0 | M20: 2
A21: =RANDBETWEEN(2,164) -> 132 | B21: {=INDEX(Data_DBD!$B:$B,$A21)} -> 10 | C21: {=INDEX(Data_DBD!$C:$C,$A21)} -> 3 | D21: {=INDEX(Data_DBD!$D:$D,$A21)} -> 33 | E21: {=INDEX(Data_DBD!$E:$E,$A21)} -> 1 | F21: {=INDEX(Data_DBD!$F:$F,$A21)} -> 3 | H21: 114 | I21: 14 | J21: 2 | K21: 33 | L21: 1 | M21: 3
A22: =RANDBETWEEN(2,164) -> 77 | B22: {=INDEX(Data_DBD!$B:$B,$A22)} -> 16 | C22: {=INDEX(Data_DBD!$C:$C,$A22)} -> 4 | D22: {=INDEX(Data_DBD!$D:$D,$A22)} -> 13 | E22: {=INDEX(Data_DBD!$E:$E,$A22)} -> 1 | F22: {=INDEX(Data_DBD!$F:$F,$A22)} -> 2 | H22: 103 | I22: 22 | J22: 5 | K22: 18 | L22: 0 | M22: 3
... A49: =RANDBETWEEN(2,164) -> 144 | B49: {=INDEX(Data_DBD!$B:$B,$A49)} -> 61 | C49: {=INDEX(Data_DBD!$C:$C,$A49)} -> 4 | D49: {=INDEX(Data_DBD!$D:$D,$A49)} -> 21 | E49: {=INDEX(Data_DBD!$E:$E,$A49)} -> 1 | F49: {=INDEX(Data_DBD!$F:$F,$A49)} -> 3 | H49: 34 | I49: 55 | J49: 3 | K49: 14 | L49: 0 | M49: 2
A50: =RANDBETWEEN(2,164) -> 121 | B50: {=INDEX(Data_DBD!$B:$B,$A50)} -> 82 | C50: {=INDEX(Data_DBD!$C:$C,$A50)} -> 5 | D50: {=INDEX(Data_DBD!$D:$D,$A50)} -> 33 | E50: {=INDEX(Data_DBD!$E:$E,$A50)} -> 1 | F50: {=INDEX(Data_DBD!$F:$F,$A50)} -> 3 | H50: 30 | I50: 2,8 | J50: 2 | K50: 14 | L50: 1 | M50: 2
A51: =RANDBETWEEN(2,164) -> 61 | B51: {=INDEX(Data_DBD!$B:$B,$A51)} -> 29 | C51: {=INDEX(Data_DBD!$C:$C,$A51)} -> 3 | D51: {=INDEX(Data_DBD!$D:$D,$A51)} -> 15 | E51: {=INDEX(Data_DBD!$E:$E,$A51)} -> 1 | F51: {=INDEX(Data_DBD!$F:$F,$A51)} -> 2 | H51: 65 | I51: 49 | J51: 3 | K51: 15 | L51: 0 | M51: 2
A52: =RANDBETWEEN(2,164) -> 22 | B52: {=INDEX(Data_DBD!$B:$B,$A52)} -> 6 | C52: {=INDEX(Data_DBD!$C:$C,$A52)} -> 3 | D52: {=INDEX(Data_DBD!$D:$D,$A52)} -> 14 | E52: {=INDEX(Data_DBD!$E:$E,$A52)} -> 0 | F52: {=INDEX(Data_DBD!$F:$F,$A52)} -> 2 | H52: 34 | I52: 55 | J52: 3 | K52: 14 | L52: 0 | M52: 2
A53: =RANDBETWEEN(2,164) -> 75 | B53: {=INDEX(Data_DBD!$B:$B,$A53)} -> 2 | C53: {=INDEX(Data_DBD!$C:$C,$A53)} -> 2 | D53: {=INDEX(Data_DBD!$D:$D,$A53)} -> 10 | E53: {=INDEX(Data_DBD!$E:$E,$A53)} -> 1 | F53: {=INDEX(Data_DBD!$F:$F,$A53)} -> 2 | H53: 109 | I53: 40 | J53: 3 | K53: 33 | L53: 1 | M53: 3
A54: =RANDBETWEEN(2,164) -> 66 | B54: {=INDEX(Data_DBD!$B:$B,$A54)} -> 21 | C54: {=INDEX(Data_DBD!$C:$C,$A54)} -> 5 | D54: {=INDEX(Data_DBD!$D:$D,$A54)} -> 15 | E54: {=INDEX(Data_DBD!$E:$E,$A54)} -> 1 | F54: {=INDEX(Data_DBD!$F:$F,$A54)} -> 2 | H54: 101 | I54: 42 | J54: 5 | K54: 18 | L54: 0 | M54: 3
A55: =RANDBETWEEN(2,164) -> 44 | B55: {=INDEX(Data_DBD!$B:$B,$A55)} -> 28 | C55: {=INDEX(Data_DBD!$C:$C,$A55)} -> 5 | D55: {=INDEX(Data_DBD!$D:$D,$A55)} -> 13 | E55: {=INDEX(Data_DBD!$E:$E,$A55)} -> 1 | F55: {=INDEX(Data_DBD!$F:$F,$A55)} -> 2 | H55: 146 | I55: 34 | J55: 2 | K55: 21 | L55: 1 | M55: 3
A56: =RANDBETWEEN(2,164) -> 108 | B56: {=INDEX(Data_DBD!$B:$B,$A56)} -> 69 | C56: {=INDEX(Data_DBD!$C:$C,$A56)} -> 7 | D56: {=INDEX(Data_DBD!$D:$D,$A56)} -> 33 | E56: {=INDEX(Data_DBD!$E:$E,$A56)} -> 1 | F56: {=INDEX(Data_DBD!$F:$F,$A56)} -> 3 | H56: 127 | I56: 21 | J56: 2 | K56: 33 | L56: 0 | M56: 3
A57: =RANDBETWEEN(2,164) -> 37 | B57: {=INDEX(Data_DBD!$B:$B,$A57)} -> 28 | C57: {=INDEX(Data_DBD!$C:$C,$A57)} -> 4 | D57: {=INDEX(Data_DBD!$D:$D,$A57)} -> 4 | E57: {=INDEX(Data_DBD!$E:$E,$A57)} -> 1 | F57: {=INDEX(Data_DBD!$F:$F,$A57)} -> 1 | H57: 59 | I57: 28 | J57: 4 | K57: 15 | L57: 0 | M57: 2
A58: =RANDBETWEEN(2,164) -> 62 | B58: {=INDEX(Data_DBD!$B:$B,$A58)} -> 43 | C58: {=INDEX(Data_DBD!$C:$C,$A58)} -> 4 | D58: {=INDEX(Data_DBD!$D:$D,$A58)} -> 15 | E58: {=INDEX(Data_DBD!$E:$E,$A58)} -> 1 | F58: {=INDEX(Data_DBD!$F:$F,$A58)} -> 2 | H58: 13 | I58: 47 | J58: 2 | K58: 12 | L58: 0 | M58: 2
A59: =RANDBETWEEN(2,164) -> 123 | B59: {=INDEX(Data_DBD!$B:$B,$A59)} -> 22 | C59: {=INDEX(Data_DBD!$C:$C,$A59)} -> 4 | D59: {=INDEX(Data_DBD!$D:$D,$A59)} -> 33 | E59: {=INDEX(Data_DBD!$E:$E,$A59)} -> 0 | F59: {=INDEX(Data_DBD!$F:$F,$A59)} -> 3 | H59: 9 | I59: 16 | J59: 6 | K59: 12 | L59: 1 | M59: 2
A60: =RANDBETWEEN(2,164) -> 120 | B60: {=INDEX(Data_DBD!$B:$B,$A60)} -> 26 | C60: {=INDEX(Data_DBD!$C:$C,$A60)} -> 4 | D60: {=INDEX(Data_DBD!$D:$D,$A60)} -> 33 | E60: {=INDEX(Data_DBD!$E:$E,$A60)} -> 1 | F60: {=INDEX(Data_DBD!$F:$F,$A60)} -> 3 | H60: 126 | I60: 51 | J60: 3 | K60: 33 | L60: 1 | M60: 3
A61: =RANDBETWEEN(2,164) -> 62 | B61: {=INDEX(Data_DBD!$B:$B,$A61)} -> 43 | C61: {=INDEX(Data_DBD!$C:$C,$A61)} -> 4 | D61: {=INDEX(Data_DBD!$D:$D,$A61)} -> 15 | E61: {=INDEX(Data_DBD!$E:$E,$A61)} -> 1 | F61: {=INDEX(Data_DBD!$F:$F,$A61)} -> 2 | H61: 128 | I61: 38 | J61: 2 | K61: 33 | L61: 0 | M61: 3
A62: =RANDBETWEEN(2,164) -> 54 | B62: {=INDEX(Data_DBD!$B:$B,$A62)} -> 7 | C62: {=INDEX(Data_DBD!$C:$C,$A62)} -> 3 | D62: {=INDEX(Data_DBD!$D:$D,$A62)} -> 15 | E62: {=INDEX(Data_DBD!$E:$E,$A62)} -> 0 | F62: {=INDEX(Data_DBD!$F:$F,$A62)} -> 2 | H62: 103 | I62: 22 | J62: 5 | K62: 18 | L62: 0 | M62: 3
... A141: =RANDBETWEEN(2,164) -> 16 | B141: {=INDEX(Data_DBD!$B:$B,$A141)} -> 66 | C141: {=INDEX(Data_DBD!$C:$C,$A141)} -> 5 | D141: {=INDEX(Data_DBD!$D:$D,$A141)} -> 7 | E141: {=INDEX(Data_DBD!$E:$E,$A141)} -> 1 | F141: {=INDEX(Data_DBD!$F:$F,$A141)} -> 1 | H141: 5 | I141: 18 | J141: 2 | K141: 12 | L141: 1 | M141: 2
A142: =RANDBETWEEN(2,164) -> 105 | B142: {=INDEX(Data_DBD!$B:$B,$A142)} -> 61 | C142: {=INDEX(Data_DBD!$C:$C,$A142)} -> 3 | D142: {=INDEX(Data_DBD!$D:$D,$A142)} -> 18 | E142: {=INDEX(Data_DBD!$E:$E,$A142)} -> 1 | F142: {=INDEX(Data_DBD!$F:$F,$A142)} -> 3 | H142: 30 | I142: 2,8 | J142: 2 | K142: 14 | L142: 1 | M142: 2
A143: =RANDBETWEEN(2,164) -> 9 | B143: {=INDEX(Data_DBD!$B:$B,$A143)} -> 16 | C143: {=INDEX(Data_DBD!$C:$C,$A143)} -> 6 | D143: {=INDEX(Data_DBD!$D:$D,$A143)} -> 12 | E143: {=INDEX(Data_DBD!$E:$E,$A143)} -> 1 | F143: {=INDEX(Data_DBD!$F:$F,$A143)} -> 2 | H143: 72 | I143: 3 | J143: 5 | K143: 10 | L143: 1 | M143: 2
A144: =RANDBETWEEN(2,164) -> 158 | B144: {=INDEX(Data_DBD!$B:$B,$A144)} -> 5 | C144: {=INDEX(Data_DBD!$C:$C,$A144)} -> 2 | D144: {=INDEX(Data_DBD!$D:$D,$A144)} -> 21 | E144: {=INDEX(Data_DBD!$E:$E,$A144)} -> 0 | F144: {=INDEX(Data_DBD!$F:$F,$A144)} -> 3 | H144: 155 | I144: 19 | J144: 5 | K144: 21 | L144: 1 | M144: 3
...

Sheet Pohon 2
A1: No | B1: Usia | C1: Lama Rawat Inap | D1: Jumlah Kasus Per Bulan | E1: Jenis Kelamin | F1: Tingkat Resiko | H1: No | I1: Usia | J1: Lama Rawat Inap | K1: Jumlah Kasus Per Bulan | L1: Jenis Kelamin | M1: Tingkat Resiko | O1: Perhitungan root
A2: =RANDBETWEEN(2,164) -> 135 | B2: {=INDEX(Data_DBD!$B:$B,$A2)} -> 10 | C2: {=INDEX(Data_DBD!$C:$C,$A2)} -> 2 | D2: {=INDEX(Data_DBD!$D:$D,$A2)} -> 33 | E2: {=INDEX(Data_DBD!$E:$E,$A2)} -> 0 | F2: {=INDEX(Data_DBD!$F:$F,$A2)} -> 3 | H2: 57 | I2: 2 | J2: 2 | K2: 15 | L2: 1 | M2: 2 | O2: 1 | P2: =COUNTIF(M2:M164,"1") -> 10 | Q2: =P2/163 -> 0.061349693
A3: =RANDBETWEEN(2,164) -> 79 | B3: {=INDEX(Data_DBD!$B:$B,$A3)} -> 29 | C3: {=INDEX(Data_DBD!$C:$C,$A3)} -> 3 | D3: {=INDEX(Data_DBD!$D:$D,$A3)} -> 13 | E3: {=INDEX(Data_DBD!$E:$E,$A3)} -> 0 | F3: {=INDEX(Data_DBD!$F:$F,$A3)} -> 2 | H3: 52 | I3: 59 | J3: 4 | K3: 15 | L3: 1 | M3: 2 | O3: 2 | P3: =COUNTIF(M2:M164,"2") -> 80 | Q3: =P3/163 -> 0.49079755
A4: =RANDBETWEEN(2,164) -> 27 | B4: {=INDEX(Data_DBD!$B:$B,$A4)} -> 37 | C4: {=INDEX(Data_DBD!$C:$C,$A4)} -> 4 | D4: {=INDEX(Data_DBD!$D:$D,$A4)} -> 14 | E4: {=INDEX(Data_DBD!$E:$E,$A4)} -> 1 | F4: {=INDEX(Data_DBD!$F:$F,$A4)} -> 2 | H4: 91 | I4: 35 | J4: 1 | K4: 18 | L4: 1 | M4: 3 | O4: 3 | P4: =COUNTIF(M2:M164,"3") -> 73 | Q4: =P4/163 -> 0.44785276
A5: =RANDBETWEEN(2,164) -> 96 | B5: {=INDEX(Data_DBD!$B:$B,$A5)} -> 56 | C5: {=INDEX(Data_DBD!$C:$C,$A5)} -> 4 | D5: {=INDEX(Data_DBD!$D:$D,$A5)} -> 18 | E5: {=INDEX(Data_DBD!$E:$E,$A5)} -> 0 | F5: {=INDEX(Data_DBD!$F:$F,$A5)} -> 3 | H5: 45 | I5: 75 | J5: 3 | K5: 13 | L5: 1 | M5: 2 | O5: Entropy Root | P5: =-(IFERROR(Q2*LOG(Q2,2),0)+IFERROR(Q3*LOG(Q3,2),0)+IFERROR(Q4*LOG(Q4,2),0)) -> 1.2700121
A6: =RANDBETWEEN(2,164) -> 56 | B6: {=INDEX(Data_DBD!$B:$B,$A6)} -> 4 | C6: {=INDEX(Data_DBD!$C:$C,$A6)} -> 3 | D6: {=INDEX(Data_DBD!$D:$D,$A6)} -> 15 | E6: {=INDEX(Data_DBD!$E:$E,$A6)} -> 0 | F6: {=INDEX(Data_DBD!$F:$F,$A6)} -> 2 | H6: 76 | I6: 70 | J6: 2 | K6: 10 | L6: 0 | M6: 2
A7: =RANDBETWEEN(2,164) -> 83 | B7: {=INDEX(Data_DBD!$B:$B,$A7)} -> 50 | C7: {=INDEX(Data_DBD!$C:$C,$A7)} -> 3 | D7: {=INDEX(Data_DBD!$D:$D,$A7)} -> 13 | E7: {=INDEX(Data_DBD!$E:$E,$A7)} -> 0 | F7: {=INDEX(Data_DBD!$F:$F,$A7)} -> 2 | H7: 131 | I7: 10 | J7: 2 | K7: 33 | L7: 0 | M7: 3
A8: =RANDBETWEEN(2,164) -> 15 | B8: {=INDEX(Data_DBD!$B:$B,$A8)} -> 21 | C8: {=INDEX(Data_DBD!$C:$C,$A8)} -> 2 | D8: {=INDEX(Data_DBD!$D:$D,$A8)} -> 7 | E8: {=INDEX(Data_DBD!$E:$E,$A8)} -> 0 | F8: {=INDEX(Data_DBD!$F:$F,$A8)} -> 1 | H8: 133 | I8: 6 | J8: 4 | K8: 33 | L8: 0 | M8: 3
A9: =RANDBETWEEN(2,164) -> 85 | B9: {=INDEX(Data_DBD!$B:$B,$A9)} -> 27 | C9: {=INDEX(Data_DBD!$C:$C,$A9)} -> 9 | D9: {=INDEX(Data_DBD!$D:$D,$A9)} -> 13 | E9: {=INDEX(Data_DBD!$E:$E,$A9)} -> 0 | F9: {=INDEX(Data_DBD!$F:$F,$A9)} -> 2 | H9: 114 | I9: 14 | J9: 2 | K9: 33 | L9: 1 | M9: 3
A10: =RANDBETWEEN(2,164) -> 13 | B10: {=INDEX(Data_DBD!$B:$B,$A10)} -> 47 | C10: {=INDEX(Data_DBD!$C:$C,$A10)} -> 2 | D10: {=INDEX(Data_DBD!$D:$D,$A10)} -> 12 | E10: {=INDEX(Data_DBD!$E:$E,$A10)} -> 0 | F10: {=INDEX(Data_DBD!$F:$F,$A10)} -> 2 | H10: 50 | I10: 19 | J10: 5 | K10: 13 | L10: 0 | M10: 2
A11: =RANDBETWEEN(2,164) -> 74 | B11: {=INDEX(Data_DBD!$B:$B,$A11)} -> 9 | C11: {=INDEX(Data_DBD!$C:$C,$A11)} -> 4 | D11: {=INDEX(Data_DBD!$D:$D,$A11)} -> 10 | E11: {=INDEX(Data_DBD!$E:$E,$A11)} -> 0 | F11: {=INDEX(Data_DBD!$F:$F,$A11)} -> 2 | H11: 124 | I11: 24 | J11: 3 | K11: 33 | L11: 1 | M11: 3
A12: =RANDBETWEEN(2,164) -> 12 | B12: {=INDEX(Data_DBD!$B:$B,$A12)} -> 23 | C12: {=INDEX(Data_DBD!$C:$C,$A12)} -> 3 | D12: {=INDEX(Data_DBD!$D:$D,$A12)} -> 12 | E12: {=INDEX(Data_DBD!$E:$E,$A12)} -> 0 | F12: {=INDEX(Data_DBD!$F:$F,$A12)} -> 2 | H12: 89 | I12: 32 | J12: 4 | K12: 13 | L12: 0 | M12: 2
A13: =RANDBETWEEN(2,164) -> 59 | B13: {=INDEX(Data_DBD!$B:$B,$A13)} -> 28 | C13: {=INDEX(Data_DBD!$C:$C,$A13)} -> 4 | D13: {=INDEX(Data_DBD!$D:$D,$A13)} -> 15 | E13: {=INDEX(Data_DBD!$E:$E,$A13)} -> 0 | F13: {=INDEX(Data_DBD!$F:$F,$A13)} -> 2 | H13: 89 | I13: 32 | J13: 4 | K13: 13 | L13: 0 | M13: 2
A14: =RANDBETWEEN(2,164) -> 52 | B14: {=INDEX(Data_DBD!$B:$B,$A14)} -> 59 | C14: {=INDEX(Data_DBD!$C:$C,$A14)} -> 4 | D14: {=INDEX(Data_DBD!$D:$D,$A14)} -> 15 | E14: {=INDEX(Data_DBD!$E:$E,$A14)} -> 1 | F14: {=INDEX(Data_DBD!$F:$F,$A14)} -> 2 | H14: 119 | I14: 30 | J14: 7 | K14: 33 | L14: 0 | M14: 3
A15: =RANDBETWEEN(2,164) -> 89 | B15: {=INDEX(Data_DBD!$B:$B,$A15)} -> 32 | C15: {=INDEX(Data_DBD!$C:$C,$A15)} -> 4 | D15: {=INDEX(Data_DBD!$D:$D,$A15)} -> 13 | E15: {=INDEX(Data_DBD!$E:$E,$A15)} -> 0 | F15: {=INDEX(Data_DBD!$F:$F,$A15)} -> 2 | H15: 112 | I15: 61 | J15: 3 | K15: 33 | L15: 1 | M15: 3
A16: =RANDBETWEEN(2,164) -> 6 | B16: {=INDEX(Data_DBD!$B:$B,$A16)} -> 14 | C16: {=INDEX(Data_DBD!$C:$C,$A16)} -> 4 | D16: {=INDEX(Data_DBD!$D:$D,$A16)} -> 12 | E16: {=INDEX(Data_DBD!$E:$E,$A16)} -> 0 | F16: {=INDEX(Data_DBD!$F:$F,$A16)} -> 2 | H16: 39 | I16: 12 | J16: 5 | K16: 13 | L16: 1 | M16: 2
A17: =RANDBETWEEN(2,164) -> 148 | B17: {=INDEX(Data_DBD!$B:$B,$A17)} -> 55 | C17: {=INDEX(Data_DBD!$C:$C,$A17)} -> 3 | D17: {=INDEX(Data_DBD!$D:$D,$A17)} -> 21 | E17: {=INDEX(Data_DBD!$E:$E,$A17)} -> 1 | F17: {=INDEX(Data_DBD!$F:$F,$A17)} -> 3 | H17: 5 | I17: 18 | J17: 2 | K17: 12 | L17: 1 | M17: 2
... A31: =RANDBETWEEN(2,164) -> 77 | B31: {=INDEX(Data_DBD!$B:$B,$A31)} -> 16 | C31: {=INDEX(Data_DBD!$C:$C,$A31)} -> 4 | D31: {=INDEX(Data_DBD!$D:$D,$A31)} -> 13 | E31: {=INDEX(Data_DBD!$E:$E,$A31)} -> 1 | F31: {=INDEX(Data_DBD!$F:$F,$A31)} -> 2 | H31: 50 | I31: 19 | J31: 5 | K31: 13 | L31: 0 | M31: 2
A32: =RANDBETWEEN(2,164) -> 33 | B32: {=INDEX(Data_DBD!$B:$B,$A32)} -> 19 | C32: {=INDEX(Data_DBD!$C:$C,$A32)} -> 4 | D32: {=INDEX(Data_DBD!$D:$D,$A32)} -> 14 | E32: {=INDEX(Data_DBD!$E:$E,$A32)} -> 1 | F32: {=INDEX(Data_DBD!$F:$F,$A32)} -> 2 | H32: 30 | I32: 2,8 | J32: 2 | K32: 14 | L32: 1 | M32: 2
A33: =RANDBETWEEN(2,164) -> 20 | B33: {=INDEX(Data_DBD!$B:$B,$A33)} -> 15 | C33: {=INDEX(Data_DBD!$C:$C,$A33)} -> 5 | D33: {=INDEX(Data_DBD!$D:$D,$A33)} -> 7 | E33: {=INDEX(Data_DBD!$E:$E,$A33)} -> 0 | F33: {=INDEX(Data_DBD!$F:$F,$A33)} -> 1 | H33: 96 | I33: 56 | J33: 4 | K33: 18 | L33: 0 | M33: 3
A34: =RANDBETWEEN(2,164) -> 115 | B34: {=INDEX(Data_DBD!$B:$B,$A34)} -> 52 | C34: {=INDEX(Data_DBD!$C:$C,$A34)} -> 3 | D34: {=INDEX(Data_DBD!$D:$D,$A34)} -> 33 | E34: {=INDEX(Data_DBD!$E:$E,$A34)} -> 1 | F34: {=INDEX(Data_DBD!$F:$F,$A34)} -> 3 | H34: 118 | I34: 67 | J34: 4 | K34: 33 | L34: 1 | M34: 3
A35: =RANDBETWEEN(2,164) -> 74 | B35: {=INDEX(Data_DBD!$B:$B,$A35)} -> 9 | C35: {=INDEX(Data_DBD!$C:$C,$A35)} -> 4 | D35: {=INDEX(Data_DBD!$D:$D,$A35)} -> 10 | E35: {=INDEX(Data_DBD!$E:$E,$A35)} -> 0 | F35: {=INDEX(Data_DBD!$F:$F,$A35)} -> 2 | H35: 19 | I35: 8 | J35: 4 | K35: 7 | L35: 0 | M35: 1
A36: =RANDBETWEEN(2,164) -> 6 | B36: {=INDEX(Data_DBD!$B:$B,$A36)} -> 14 | C36: {=INDEX(Data_DBD!$C:$C,$A36)} -> 4 | D36: {=INDEX(Data_DBD!$D:$D,$A36)} -> 12 | E36: {=INDEX(Data_DBD!$E:$E,$A36)} -> 0 | F36: {=INDEX(Data_DBD!$F:$F,$A36)} -> 2 | H36: 51 | I36: 48 | J36: 4 | K36: 13 | L36: 0 | M36: 2
A37: =RANDBETWEEN(2,164) -> 111 | B37: {=INDEX(Data_DBD!$B:$B,$A37)} -> 25 | C37: {=INDEX(Data_DBD!$C:$C,$A37)} -> 4 | D37: {=INDEX(Data_DBD!$D:$D,$A37)} -> 33 | E37: {=INDEX(Data_DBD!$E:$E,$A37)} -> 0 | F37: {=INDEX(Data_DBD!$F:$F,$A37)} -> 3 | H37: 136 | I37: 6 | J37: 2 | K37: 33 | L37: 0 | M37: 3
A38: =RANDBETWEEN(2,164) -> 157 | B38: {=INDEX(Data_DBD!$B:$B,$A38)} -> 15 | C38: {=INDEX(Data_DBD!$C:$C,$A38)} -> 4 | D38: {=INDEX(Data_DBD!$D:$D,$A38)} -> 21 | E38: {=INDEX(Data_DBD!$E:$E,$A38)} -> 1 | F38: {=INDEX(Data_DBD!$F:$F,$A38)} -> 3 | H38: 164 | I38: 10 | J38: 6 | K38: 3 | L38: 0 | M38: 1
A39: =RANDBETWEEN(2,164) -> 41 | B39: {=INDEX(Data_DBD!$B:$B,$A39)} -> 8 | C39: {=INDEX(Data_DBD!$C:$C,$A39)} -> 4 | D39: {=INDEX(Data_DBD!$D:$D,$A39)} -> 13 | E39: {=INDEX(Data_DBD!$E:$E,$A39)} -> 0 | F39: {=INDEX(Data_DBD!$F:$F,$A39)} -> 2 | H39: 82 | I39: 28 | J39: 3 | K39: 13 | L39: 1 | M39: 2
A40: =RANDBETWEEN(2,164) -> 102 | B40: {=INDEX(Data_DBD!$B:$B,$A40)} -> 41 | C40: {=INDEX(Data_DBD!$C:$C,$A40)} -> 4 | D40: {=INDEX(Data_DBD!$D:$D,$A40)} -> 18 | E40: {=INDEX(Data_DBD!$E:$E,$A40)} -> 0 | F40: {=INDEX(Data_DBD!$F:$F,$A40)} -> 3 | H40: 56 | I40: 4 | J40: 3 | K40: 15 | L40: 0 | M40: 2
A41: =RANDBETWEEN(2,164) -> 91 | B41: {=INDEX(Data_DBD!$B:$B,$A41)} -> 35 | C41: {=INDEX(Data_DBD!$C:$C,$A41)} -> 1 | D41: {=INDEX(Data_DBD!$D:$D,$A41)} -> 18 | E41: {=INDEX(Data_DBD!$E:$E,$A41)} -> 1 | F41: {=INDEX(Data_DBD!$F:$F,$A41)} -> 3 | H41: 131 | I41: 10 | J41: 2 | K41: 33 | L41: 0 | M41: 3
A42: =RANDBETWEEN(2,164) -> 87 | B42: {=INDEX(Data_DBD!$B:$B,$A42)} -> 21 | C42: {=INDEX(Data_DBD!$C:$C,$A42)} -> 3 | D42: {=INDEX(Data_DBD!$D:$D,$A42)} -> 13 | E42: {=INDEX(Data_DBD!$E:$E,$A42)} -> 0 | F42: {=INDEX(Data_DBD!$F:$F,$A42)} -> 2 | H42: 33 | I42: 19 | J42: 4 | K42: 14 | L42: 1 | M42: 2
A43: =RANDBETWEEN(2,164) -> 130 | B43: {=INDEX(Data_DBD!$B:$B,$A43)} -> 12 | C43: {=INDEX(Data_DBD!$C:$C,$A43)} -> 4 | D43: {=INDEX(Data_DBD!$D:$D,$A43)} -> 33 | E43: {=INDEX(Data_DBD!$E:$E,$A43)} -> 0 | F43: {=INDEX(Data_DBD!$F:$F,$A43)} -> 3 | H43: 43 | I43: 15 | J43: 4 | K43: 13 | L43: 0 | M43: 2
A44: =RANDBETWEEN(2,164) -> 6 | B44: {=INDEX(Data_DBD!$B:$B,$A44)} -> 14 | C44: {=INDEX(Data_DBD!$C:$C,$A44)} -> 4 | D44: {=INDEX(Data_DBD!$D:$D,$A44)} -> 12 | E44: {=INDEX(Data_DBD!$E:$E,$A44)} -> 0 | F44: {=INDEX(Data_DBD!$F:$F,$A44)} -> 2 | H44: 18 | I44: 49 | J44: 4 | K44: 7 | L44: 1 | M44: 1
... A129: =RANDBETWEEN(2,164) -> 91 | B129: {=INDEX(Data_DBD!$B:$B,$A129)} -> 35 | C129: {=INDEX(Data_DBD!$C:$C,$A129)} -> 1 | D129: {=INDEX(Data_DBD!$D:$D,$A129)} -> 18 | E129: {=INDEX(Data_DBD!$E:$E,$A129)} -> 1 | F129: {=INDEX(Data_DBD!$F:$F,$A129)} -> 3 | H129: 45 | I129: 75 | J129: 3 | K129: 13 | L129: 1 | M129: 2
A130: =RANDBETWEEN(2,164) -> 56 | B130: {=INDEX(Data_DBD!$B:$B,$A130)} -> 4 | C130: {=INDEX(Data_DBD!$C:$C,$A130)} -> 3 | D130: {=INDEX(Data_DBD!$D:$D,$A130)} -> 15 | E130: {=INDEX(Data_DBD!$E:$E,$A130)} -> 0 | F130: {=INDEX(Data_DBD!$F:$F,$A130)} -> 2 | H130: 30 | I130: 2,8 | J130: 2 | K130: 14 | L130: 1 | M130: 2
A131: =RANDBETWEEN(2,164) -> 150 | B131: {=INDEX(Data_DBD!$B:$B,$A131)} -> 61 | C131: {=INDEX(Data_DBD!$C:$C,$A131)} -> 5 | D131: {=INDEX(Data_DBD!$D:$D,$A131)} -> 21 | E131: {=INDEX(Data_DBD!$E:$E,$A131)} -> 1 | F131: {=INDEX(Data_DBD!$F:$F,$A131)} -> 3 | H131: 126 | I131: 51 | J131: 3 | K131: 33 | L131: 1 | M131: 3
A132: =RANDBETWEEN(2,164) -> 52 | B132: {=INDEX(Data_DBD!$B:$B,$A132)} -> 59 | C132: {=INDEX(Data_DBD!$C:$C,$A132)} -> 4 | D132: {=INDEX(Data_DBD!$D:$D,$A132)} -> 15 | E132: {=INDEX(Data_DBD!$E:$E,$A132)} -> 1 | F132: {=INDEX(Data_DBD!$F:$F,$A132)} -> 2 | H132: 76 | I132: 70 | J132: 2 | K132: 10 | L132: 0 | M132: 2
A133: =RANDBETWEEN(2,164) -> 119 | B133: {=INDEX(Data_DBD!$B:$B,$A133)} -> 30 | C133: {=INDEX(Data_DBD!$C:$C,$A133)} -> 7 | D133: {=INDEX(Data_DBD!$D:$D,$A133)} -> 33 | E133: {=INDEX(Data_DBD!$E:$E,$A133)} -> 0 | F133: {=INDEX(Data_DBD!$F:$F,$A133)} -> 3 | H133: 146 | I133: 34 | J133: 2 | K133: 21 | L133: 1 | M133: 3
A134: =RANDBETWEEN(2,164) -> 18 | B134: {=INDEX(Data_DBD!$B:$B,$A134)} -> 49 | C134: {=INDEX(Data_DBD!$C:$C,$A134)} -> 4 | D134: {=INDEX(Data_DBD!$D:$D,$A134)} -> 7 | E134: {=INDEX(Data_DBD!$E:$E,$A134)} -> 1 | F134: {=INDEX(Data_DBD!$F:$F,$A134)} -> 1 | H134: 71 | I134: 84 | J134: 3 | K134: 10 | L134: 0 | M134: 2
A135: =RANDBETWEEN(2,164) -> 134 | B135: {=INDEX(Data_DBD!$B:$B,$A135)} -> 4 | C135: {=INDEX(Data_DBD!$C:$C,$A135)} -> 2 | D135: {=INDEX(Data_DBD!$D:$D,$A135)} -> 33 | E135: {=INDEX(Data_DBD!$E:$E,$A135)} -> 1 | F135: {=INDEX(Data_DBD!$F:$F,$A135)} -> 3 | H135: 80 | I135: 27 | J135: 3 | K135: 13 | L135: 1 | M135: 2
A136: =RANDBETWEEN(2,164) -> 95 | B136: {=INDEX(Data_DBD!$B:$B,$A136)} -> 11 | C136: {=INDEX(Data_DBD!$C:$C,$A136)} -> 3 | D136: {=INDEX(Data_DBD!$D:$D,$A136)} -> 18 | E136: {=INDEX(Data_DBD!$E:$E,$A136)} -> 1 | F136: {=INDEX(Data_DBD!$F:$F,$A136)} -> 3 | H136: 116 | I136: 32 | J136: 4 | K136: 33 | L136: 1 | M136: 3
A137: =RANDBETWEEN(2,164) -> 98 | B137: {=INDEX(Data_DBD!$B:$B,$A137)} -> 16 | C137: {=INDEX(Data_DBD!$C:$C,$A137)} -> 2 | D137: {=INDEX(Data_DBD!$D:$D,$A137)} -> 18 | E137: {=INDEX(Data_DBD!$E:$E,$A137)} -> 1 | F137: {=INDEX(Data_DBD!$F:$F,$A137)} -> 3 | H137: 73 | I137: 15 | J137: 3 | K137: 10 | L137: 1 | M137: 2
...

Sheet Pohon 3
A1: No | B1: Usia | C1: Lama Rawat Inap | D1: Jumlah Kasus Per Bulan | E1: Jenis Kelamin | F1: Tingkat Resiko | H1: No | I1: Usia | J1: Lama Rawat Inap | K1: Jumlah Kasus Per Bulan | L1: Jenis Kelamin | M1: Tingkat Resiko | O1: Perhitungan root
A2: =RANDBETWEEN(2,164) -> 30 | B2: {=INDEX(Data_DBD!$B:$B,$A2)} -> 2,8 | C2: {=INDEX(Data_DBD!$C:$C,$A2)} -> 2 | D2: {=INDEX(Data_DBD!$D:$D,$A2)} -> 14 | E2: {=INDEX(Data_DBD!$E:$E,$A2)} -> 1 | F2: {=INDEX(Data_DBD!$F:$F,$A2)} -> 2 | H2: 84 | I2: 42 | J2: 4 | K2: 13 | L2: 1 | M2: 2 | O2: 1 | P2: =COUNTIF(M2:M164,"1") -> 16 | Q2: =P2/163 -> 0.098159509
A3: =RANDBETWEEN(2,164) -> 73 | B3: {=INDEX(Data_DBD!$B:$B,$A3)} -> 15 | C3: {=INDEX(Data_DBD!$C:$C,$A3)} -> 3 | D3: {=INDEX(Data_DBD!$D:$D,$A3)} -> 10 | E3: {=INDEX(Data_DBD!$E:$E,$A3)} -> 1 | F3: {=INDEX(Data_DBD!$F:$F,$A3)} -> 2 | H3: 87 | I3: 21 | J3: 3 | K3: 13 | L3: 0 | M3: 2 | O3: 2 | P3: =COUNTIF(M2:M164,"2") -> 78 | Q3: =P3/163 -> 0.47852761
A4: =RANDBETWEEN(2,164) -> 58 | B4: {=INDEX(Data_DBD!$B:$B,$A4)} -> 17 | C4: {=INDEX(Data_DBD!$C:$C,$A4)} -> 3 | D4: {=INDEX(Data_DBD!$D:$D,$A4)} -> 15 | E4: {=INDEX(Data_DBD!$E:$E,$A4)} -> 0 | F4: {=INDEX(Data_DBD!$F:$F,$A4)} -> 2 | H4: 116 | I4: 32 | J4: 4 | K4: 33 | L4: 1 | M4: 3 | O4: 3 | P4: =COUNTIF(M2:M164,"3") -> 69 | Q4: =P4/163 -> 0.42331288
A5: =RANDBETWEEN(2,164) -> 144 | B5: {=INDEX(Data_DBD!$B:$B,$A5)} -> 61 | C5: {=INDEX(Data_DBD!$C:$C,$A5)} -> 4 | D5: {=INDEX(Data_DBD!$D:$D,$A5)} -> 21 | E5: {=INDEX(Data_DBD!$E:$E,$A5)} -> 1 | F5: {=INDEX(Data_DBD!$F:$F,$A5)} -> 3 | H5: 101 | I5: 42 | J5: 5 | K5: 18 | L5: 0 | M5: 3 | O5: Entropy Root | P5: =-(IFERROR(Q2*LOG(Q2,2),0)+IFERROR(Q3*LOG(Q3,2),0)+IFERROR(Q4*LOG(Q4,2),0)) -> 1.3625345
A6: =RANDBETWEEN(2,164) -> 121 | B6: {=INDEX(Data_DBD!$B:$B,$A6)} -> 82 | C6: {=INDEX(Data_DBD!$C:$C,$A6)} -> 5 | D6: {=INDEX(Data_DBD!$D:$D,$A6)} -> 33 | E6: {=INDEX(Data_DBD!$E:$E,$A6)} -> 1 | F6: {=INDEX(Data_DBD!$F:$F,$A6)} -> 3 | H6: 95 | I6: 11 | J6: 3 | K6: 18 | L6: 1 | M6: 3
A7: =RANDBETWEEN(2,164) -> 115 | B7: {=INDEX(Data_DBD!$B:$B,$A7)} -> 52 | C7: {=INDEX(Data_DBD!$C:$C,$A7)} -> 3 | D7: {=INDEX(Data_DBD!$D:$D,$A7)} -> 33 | E7: {=INDEX(Data_DBD!$E:$E,$A7)} -> 1 | F7: {=INDEX(Data_DBD!$F:$F,$A7)} -> 3 | H7: 31 | I7: 64 | J7: 4 | K7: 14 | L7: 1 | M7: 2
A8: =RANDBETWEEN(2,164) -> 161 | B8: {=INDEX(Data_DBD!$B:$B,$A8)} -> 12 | C8: {=INDEX(Data_DBD!$C:$C,$A8)} -> 3 | D8: {=INDEX(Data_DBD!$D:$D,$A8)} -> 21 | E8: {=INDEX(Data_DBD!$E:$E,$A8)} -> 1 | F8: {=INDEX(Data_DBD!$F:$F,$A8)} -> 3 | H8: 119 | I8: 30 | J8: 7 | K8: 33 | L8: 0 | M8: 3
A9: =RANDBETWEEN(2,164) -> 55 | B9: {=INDEX(Data_DBD!$B:$B,$A9)} -> 7 | C9: {=INDEX(Data_DBD!$C:$C,$A9)} -> 4 | D9: {=INDEX(Data_DBD!$D:$D,$A9)} -> 15 | E9: {=INDEX(Data_DBD!$E:$E,$A9)} -> 1 | F9: {=INDEX(Data_DBD!$F:$F,$A9)} -> 2 | H9: 137 | I9: 3.5 | J9: 1 | K9: 33 | L9: 1 | M9: 3
A10: =RANDBETWEEN(2,164) -> 3 | B10: {=INDEX(Data_DBD!$B:$B,$A10)} -> 43 | C10: {=INDEX(Data_DBD!$C:$C,$A10)} -> 3 | D10: {=INDEX(Data_DBD!$D:$D,$A10)} -> 12 | E10: {=INDEX(Data_DBD!$E:$E,$A10)} -> 1 | F10: {=INDEX(Data_DBD!$F:$F,$A10)} -> 2 | H10: 7 | I10: 12 | J10: 1 | K10: 12 | L10: 1 | M10: 2
A11: =RANDBETWEEN(2,164) -> 37 | B11: {=INDEX(Data_DBD!$B:$B,$A11)} -> 28 | C11: {=INDEX(Data_DBD!$C:$C,$A11)} -> 4 | D11: {=INDEX(Data_DBD!$D:$D,$A11)} -> 4 | E11: {=INDEX(Data_DBD!$E:$E,$A11)} -> 1 | F11: {=INDEX(Data_DBD!$F:$F,$A11)} -> 1 | H11: 95 | I11: 11 | J11: 3 | K11: 18 | L11: 1 | M11: 3
A12: =RANDBETWEEN(2,164) -> 128 | B12: {=INDEX(Data_DBD!$B:$B,$A12)} -> 38 | C12: {=INDEX(Data_DBD!$C:$C,$A12)} -> 2 | D12: {=INDEX(Data_DBD!$D:$D,$A12)} -> 33 | E12: {=INDEX(Data_DBD!$E:$E,$A12)} -> 0 | F12: {=INDEX(Data_DBD!$F:$F,$A12)} -> 3 | H12: 86 | I12: 23 | J12: 3 | K12: 13 | L12: 0 | M12: 2
A13: =RANDBETWEEN(2,164) -> 100 | B13: {=INDEX(Data_DBD!$B:$B,$A13)} -> 19 | C13: {=INDEX(Data_DBD!$C:$C,$A13)} -> 6 | D13: {=INDEX(Data_DBD!$D:$D,$A13)} -> 18 | E13: {=INDEX(Data_DBD!$E:$E,$A13)} -> 0 | F13: {=INDEX(Data_DBD!$F:$F,$A13)} -> 3 | H13: 27 | I13: 37 | J13: 4 | K13: 14 | L13: 1 | M13: 2
A14: =RANDBETWEEN(2,164) -> 60 | B14: {=INDEX(Data_DBD!$B:$B,$A14)} -> 68 | C14: {=INDEX(Data_DBD!$C:$C,$A14)} -> 4 | D14: {=INDEX(Data_DBD!$D:$D,$A14)} -> 15 | E14: {=INDEX(Data_DBD!$E:$E,$A14)} -> 0 | F14: {=INDEX(Data_DBD!$F:$F,$A14)} -> 2 | H14: 11 | I14: 24 | J14: 5 | K14: 12 | L14: 1 | M14: 2
A15: =RANDBETWEEN(2,164) -> 11 | B15: {=INDEX(Data_DBD!$B:$B,$A15)} -> 24 | C15: {=INDEX(Data_DBD!$C:$C,$A15)} -> 5 | D15: {=INDEX(Data_DBD!$D:$D,$A15)} -> 12 | E15: {=INDEX(Data_DBD!$E:$E,$A15)} -> 1 | F15: {=INDEX(Data_DBD!$F:$F,$A15)} -> 2 | H15: 68 | I15: 44 | J15: 5 | K15: 10 | L15: 0 | M15: 2
A16: =RANDBETWEEN(2,164) -> 141 | B16: {=INDEX(Data_DBD!$B:$B,$A16)} -> 36 | C16: {=INDEX(Data_DBD!$C:$C,$A16)} -> 2 | D16: {=INDEX(Data_DBD!$D:$D,$A16)} -> 21 | E16: {=INDEX(Data_DBD!$E:$E,$A16)} -> 0 | F16: {=INDEX(Data_DBD!$F:$F,$A16)} -> 3 | H16: 150 | I16: 61 | J16: 5 | K16: 21 | L16: 1 | M16: 3
A17: =RANDBETWEEN(2,164) -> 9 | B17: {=INDEX(Data_DBD!$B:$B,$A17)} -> 16 | C17: {=INDEX(Data_DBD!$C:$C,$A17)} -> 6 | D17: {=INDEX(Data_DBD!$D:$D,$A17)} -> 12 | E17: {=INDEX(Data_DBD!$E:$E,$A17)} -> 1 | F17: {=INDEX(Data_DBD!$F:$F,$A17)} -> 2 | H17: 160 | I17: 16 | J17: 3 | K17: 21 | L17: 0 | M17: 3
... A164: =RANDBETWEEN(2,164) -> 38 | B164: {=INDEX(Data_DBD!$B:$B,$A164)} -> 52 | C164: {=INDEX(Data_DBD!$C:$C,$A164)} -> 3 | D164: {=INDEX(Data_DBD!$D:$D,$A164)} -> 4 | E164: {=INDEX(Data_DBD!$E:$E,$A164)} -> 1 | F164: {=INDEX(Data_DBD!$F:$F,$A164)} -> 1 | H164: 157 | I164: 15 | J164: 4 | K164: 21 | L164: 1 | M164: 3
I165: =AVERAGE(I2:I164) -> 32.199387 | J165: =AVERAGE(J2:J164) -> 3.6134969 | K165: =AVERAGE(K2:K164) -> 17.791411 | L165: =AVERAGE(L2:L164) -> 0.53374233
B167: 6
E168: USIA | J168: LAMA RAWAT INAP | O168: JUMLAH KASUS PER BULAN | T168: JENIS KELAMIN
E169: Usia | F169: =AVERAGEIF($I$2:$I$164,"<="&$I$165) -> 17.35 | G169: =AVERAGEIF($I$2:$I$164,">"&$I$165) -> 50.506849 | J169: Lama rawat inap | K169: =AVERAGEIF($J$2:$J$164,"<="&$J$165) -> 2.5135135 | L169: =AVERAGEIF($J$2:$J$164,">"&$J$165) -> 4.5280899 | O169: Jumlah kasus perbulan | P169: =AVERAGEIF($K$2:$K$164,"<="&$K$165) -> 11.989362 | Q169: =AVERAGEIF($K$2:$K$164,">"&$K$165) -> 25.695652 | T169: Jenis kelamin | U169: =AVERAGEIF($L$2:$L$164,"<="&$L$165) -> 0 | V169: =AVERAGEIF($L$2:$L$164,">"&$L$165) -> 1
E170: {=IF($I$2:$I$164<$F$169,"kiri",IF($I$2:$I$164<$G$169,"tengah","kanan"))} -> tengah | F170: Kanan > 50 | J170: {=IF($J$2:$J$164<$K$169,"kiri",IF($J$2:$J$164<$L$169,"tengah","kanan"))} -> tengah | K170: Kanan > 4.52 | O170: {=IF($K$2:$K$164<$P$169,"kiri",IF($K$2:$K$164<$Q$169,"tengah","kanan"))} -> tengah | P170: Kanan > 25.6 | T170: {=IF($L$2:$L$164<$U$169,"kiri",IF($L$2:$L$164<$V$169,"tengah","kanan"))} -> kanan | U170: Kanan > 1
E171: tengah | F171: =COUNTIFS($E$170:$E$332,"Kanan",$M$2:$M$164,"1") -> 5 | G171: =F171/32 -> 0.15625 | J171: tengah | K171: {=SUMPRODUCT((J170:J332="Kanan")*(M2:M164=1))} -> 6 | L171: =K171/37 -> 0.16216216 | O171: tengah | P171: =COUNTIFS($O$170:$O$332,"Kanan",$M$2:$M$164,"1") -> 0 | Q171: =P171/41 -> 0 | T171: tengah | U171: =COUNTIFS($T$170:$T$332,"Kanan",$M$2:$M$164,"1") -> 9 | V171: =U171/85 -> 0.10588235
E172: tengah | F172: =COUNTIFS($E$170:$E$332,"Kanan",$M$2:$M$164,"2") -> 12 | G172: =F172/32 -> 0.375 | J172: tengah | K172: =COUNTIFS($J$170:$J$332,"Kanan",$M$2:$M$164,"2") -> 17 | L172: =K172/37 -> 0.45945946 | O172: kanan | P172: =COUNTIFS($O$170:$O$332,"Kanan",$M$2:$M$164,"2") -> 0 | Q172: =P172/41 -> 0 | T172: kanan | U172: =COUNTIFS($T$170:$T$332,"Kanan",$M$2:$M$164,"2") -> 35 | V172: =U172/85 -> 0.41176471
E173: tengah | F173: {=SUMPRODUCT((E170:E332="KANAN")*(M2:M164=3))} -> 15 | G173: =F173/32 -> 0.46875 | J173: kanan | K173: =COUNTIFS($J$170:$J$332,"Kanan",$M$2:$M$164,"3") -> 14 | L173: =K173/37 -> 0.37837838 | O173: tengah | P173: =COUNTIFS($O$170:$O$332,"Kanan",$M$2:$M$164,"3") -> 31 | Q173: =P173/31 -> 1 | T173: tengah | U173: =COUNTIFS($T$170:$T$332,"Kanan",$M$2:$M$164,"3") -> 43 | V173: =U173/85 -> 0.50588235
E174: kiri | F174: Entropy | G174: =-(IFERROR(G171*LOG(G171,2),0)+IFERROR(G172*LOG(G172,2),0)+IFERROR(G173*LOG(G173,2),0)) -> 1.4614828 | J174: tengah | K174: Entropy | L174: =-(IFERROR(L171*LOG(L171,2),0)+IFERROR(L172*LOG(L172,2),0)+IFERROR(L173*LOG(L173,2),0)) -> 1.471626 | O174: tengah | P174: Entropy | Q174: =-(IFERROR(Q171*LOG(Q171,2),0)+IFERROR(Q172*LOG(Q172,2),0)+IFERROR(Q173*LOG(Q173,2),0)) -> 0 | T174: kanan | U174: Entropy | V174: =-(IFERROR(V171*LOG(V171,2),0)+IFERROR(V172*LOG(V172,2),0)+IFERROR(V173*LOG(V173,2),0)) -> 1.3674517
E175: kanan | G175: =SUM(F171:F173)/163 -> 0.19631902 | J175: tengah | L175: =SUM(K171:K173)/163 -> 0.22699387 | O175: tengah | Q175: =SUM(P171:P173)/163 -> 0.19018405 | T175: kanan | V175: =SUM(U171:U173)/163 -> 0.53374233
E176: tengah | G176: =G174*G175 -> 0.28691687 | J176: kanan | L176: =L174*L175 -> 0.33405008 | O176: kanan | Q176: =Q174*Q175 -> 0 | T176: tengah | V176: =V174*V175 -> 0.72986687
E177: kiri | J177: kiri | O177: kanan | T177: kanan
E178: kiri | J178: kiri | O178: tengah | T178: kanan
E179: kiri | F179: Kiri<17.3 | J179: tengah | K179: Kiri<2.51 | O179: tengah | P179: Kiri<11.9 | T179: kanan | U179: Kiri<0
E180: tengah | F180: {=SUMPRODUCT((E170:E332="kiri")*(M2:M164=1))} -> 6 | G180: =F180/42 -> 0.14285714 | J180: tengah | K180: =COUNTIFS($J$170:$J$332,"Kiri",$M$2:$M$164,"1") -> 2 | L180: =K180/29 -> 0.068965517 | O180: tengah | P180: =COUNTIFS($O$170:$O$332,"Kiri",$M$2:$M$164,"1") -> 16 | Q180: =P180/33 -> 0.48484848 | T180: tengah | U180: =COUNTIFS($T$170:$T$332,"Kiri",$M$2:$M$164,"1") -> 0 | V180: =U180/57 -> 0
E181: tengah | F181: {=SUMPRODUCT((E170:E332="kiri")*(M2:M164=2))} -> 11 | G181: =F181/42 -> 0.26190476 | J181: tengah | K181: =COUNTIFS($J$170:$J$332,"Kiri",$M$2:$M$164,"2") -> 7 | L181: =K181/29 -> 0.24137931 | O181: tengah | P181: =COUNTIFS($O$170:$O$332,"Kiri",$M$2:$M$164,"2") -> 7 | Q181: =P181/33 -> 0.21212121 | T181: kanan | U181: =COUNTIFS($T$170:$T$332,"Kiri",$M$2:$M$164,"2") -> 0 | V181: =U181/57 -> 0
E182: tengah | F182: {=SUMPRODUCT((E170:E332="kiri")*(M2:M164=3))} -> 25 | G182: =F182/42 -> 0.5952381 | J182: kanan | K182: =COUNTIFS($J$170:$J$332,"Kiri",$M$2:$M$164,"3") -> 20 | L182: =K182/29 -> 0.68965517 | O182: tengah | P182: =COUNTIFS($O$170:$O$332,"Kiri",$M$2:$M$164,"3") -> 0 | Q182: =P182/65 -> 0 | T182: kanan | U182: =COUNTIFS($T$170:$T$332,"Kiri",$M$2:$M$164,"3") -> 0 | V182: =U182/57 -> 0
E183: tengah | F183: Entropy | G183: =-(IFERROR(G180*LOG(G180,2),0)+IFERROR(G181*LOG(G181,2),0)+IFERROR(G182*LOG(G182,2),0)) -> 1.3527953 | J183: kanan | K183: Entropy | L183: =-(IFERROR(L180*LOG(L180,2),0)+IFERROR(L181*LOG(L181,2),0)+IFERROR(L182*LOG(L182,2),0)) -> 1.130738 | O183: kiri | P183: Entropy | Q183: =-(IFERROR(Q180*LOG(Q180,2),0)+IFERROR(Q181*LOG(Q181,2),0)+IFERROR(Q182*LOG(Q182,2),0)) -> 0.98089637 | T183: tengah | U183: Entropy | V183: =-(IFERROR(V180*LOG(V180,2),0)+IFERROR(V181*LOG(V181,2),0)+IFERROR(V182*LOG(V182,2),0)) -> 0
E184: kanan | G184: =SUM(F180:F182)/163 -> 0.25766871 | J184: kanan | L184: =SUM(K180:K182)/163 -> 0.17791411 | O184: tengah | Q184: =SUM(P180:P182)/163 -> 0.14110429 | T184: kanan | V184: =SUM(U180:U182)/163 -> 0
E185: kiri | G185: =G183*G184 -> 0.34857303 | J185: tengah | L185: =L183*L184 -> 0.20117425 | O185: tengah | Q185: =Q183*Q184 -> 0.13840869 | T185: tengah | V185: =V183*V184 -> 0
E186: tengah | J186: tengah | O186: tengah | T186: tengah
E187: tengah | J187: kiri | O187: kanan | T187: kanan
...

Sheet Pohon 4
A1: No | B1: Usia | C1: Lama Rawat Inap | D1: Jumlah Kasus Per Bulan | E1: Jenis Kelamin | F1: Tingkat Resiko | H1: No | I1: Usia | J1: Lama Rawat Inap | K1: Jumlah Kasus Per Bulan | L1: Jenis Kelamin | M1: Tingkat Resiko | O1: Perhitungan root
A2: =RANDBETWEEN(2,164) -> 33 | B2: {=INDEX(Data_DBD!$B:$B,$A2)} -> 19 | C2: {=INDEX(Data_DBD!$C:$C,$A2)} -> 4 | D2: {=INDEX(Data_DBD!$D:$D,$A2)} -> 14 | E2: {=INDEX(Data_DBD!$E:$E,$A2)} -> 1 | F2: {=INDEX(Data_DBD!$F:$F,$A2)} -> 2 | H2: 47 | I2: 19 | J2: 2 | K2: 13 | L2: 0 | M2: 2 | O2: 1 | P2: =COUNTIF(M2:M164,"1") -> 7 | Q2: =P2/163 -> 0.042944785
A3: =RANDBETWEEN(2,164) -> 98 | B3: {=INDEX(Data_DBD!$B:$B,$A3)} -> 16 | C3: {=INDEX(Data_DBD!$C:$C,$A3)} -> 2 | D3: {=INDEX(Data_DBD!$D:$D,$A3)} -> 18 | E3: {=INDEX(Data_DBD!$E:$E,$A3)} -> 1 | F3: {=INDEX(Data_DBD!$F:$F,$A3)} -> 3 | H3: 81 | I3: 23 | J3: 5 | K3: 13 | L3: 1 | M3: 2 | O3: 2 | P3: =COUNTIF(M2:M164,"2") -> 84 | Q3: =P3/163 -> 0.51533742
A4: =RANDBETWEEN(2,164) -> 79 | B4: {=INDEX(Data_DBD!$B:$B,$A4)} -> 29 | C4: {=INDEX(Data_DBD!$C:$C,$A4)} -> 3 | D4: {=INDEX(Data_DBD!$D:$D,$A4)} -> 13 | E4: {=INDEX(Data_DBD!$E:$E,$A4)} -> 0 | F4: {=INDEX(Data_DBD!$F:$F,$A4)} -> 2 | H4: 124 | I4: 24 | J4: 3 | K4: 33 | L4: 1 | M4: 3 | O4: 3 | P4: =COUNTIF(M2:M164,"3") -> 72 | Q4: =P4/163 -> 0.44171779
A5: =RANDBETWEEN(2,164) -> 145 | B5: {=INDEX(Data_DBD!$B:$B,$A5)} -> 28 | C5: {=INDEX(Data_DBD!$C:$C,$A5)} -> 4 | D5: {=INDEX(Data_DBD!$D:$D,$A5)} -> 21 | E5: {=INDEX(Data_DBD!$E:$E,$A5)} -> 1 | F5: {=INDEX(Data_DBD!$F:$F,$A5)} -> 3 | H5: 26 | I5: 75 | J5: 4 | K5: 14 | L5: 1 | M5: 2 | O5: Entropy Root | P5: =-(IFERROR(Q2*LOG(Q2,2),0)+IFERROR(Q3*LOG(Q3,2),0)+IFERROR(Q4*LOG(Q4,2),0)) -> 1.2086009
A6: =RANDBETWEEN(2,164) -> 94 | B6: {=INDEX(Data_DBD!$B:$B,$A6)} -> 12 | C6: {=INDEX(Data_DBD!$C:$C,$A6)} -> 4 | D6: {=INDEX(Data_DBD!$D:$D,$A6)} -> 18 | E6: {=INDEX(Data_DBD!$E:$E,$A6)} -> 0 | F6: {=INDEX(Data_DBD!$F:$F,$A6)} -> 3 | H6: 122 | I6: 28 | J6: 3 | K6: 33 | L6: 1 | M6: 3
A7: =RANDBETWEEN(2,164) -> 76 | B7: {=INDEX(Data_DBD!$B:$B,$A7)} -> 70 | C7: {=INDEX(Data_DBD!$C:$C,$A7)} -> 2 | D7: {=INDEX(Data_DBD!$D:$D,$A7)} -> 10 | E7: {=INDEX(Data_DBD!$E:$E,$A7)} -> 0 | F7: {=INDEX(Data_DBD!$F:$F,$A7)} -> 2 | H7: 147 | I7: 66 | J7: 10 | K7: 21 | L7: 1 | M7: 3
A8: =RANDBETWEEN(2,164) -> 125 | B8: {=INDEX(Data_DBD!$B:$B,$A8)} -> 39 | C8: {=INDEX(Data_DBD!$C:$C,$A8)} -> 4 | D8: {=INDEX(Data_DBD!$D:$D,$A8)} -> 33 | E8: {=INDEX(Data_DBD!$E:$E,$A8)} -> 0 | F8: {=INDEX(Data_DBD!$F:$F,$A8)} -> 3 | H8: 54 | I8: 7 | J8: 3 | K8: 15 | L8: 0 | M8: 2
A9: =RANDBETWEEN(2,164) -> 36 | B9: {=INDEX(Data_DBD!$B:$B,$A9)} -> 27 | C9: {=INDEX(Data_DBD!$C:$C,$A9)} -> 1 | D9: {=INDEX(Data_DBD!$D:$D,$A9)} -> 4 | E9: {=INDEX(Data_DBD!$E:$E,$A9)} -> 1 | F9: {=INDEX(Data_DBD!$F:$F,$A9)} -> 1 | H9: 90 | I9: 47 | J9: 3 | K9: 18 | L9: 0 | M9: 3
A10: =RANDBETWEEN(2,164) -> 117 | B10: {=INDEX(Data_DBD!$B:$B,$A10)} -> 49 | C10: {=INDEX(Data_DBD!$C:$C,$A10)} -> 4 | D10: {=INDEX(Data_DBD!$D:$D,$A10)} -> 33 | E10: {=INDEX(Data_DBD!$E:$E,$A10)} -> 1 | F10: {=INDEX(Data_DBD!$F:$F,$A10)} -> 3 | H10: 66 | I10: 21 | J10: 5 | K10: 15 | L10: 1 | M10: 2
A11: =RANDBETWEEN(2,164) -> 52 | B11: {=INDEX(Data_DBD!$B:$B,$A11)} -> 59 | C11: {=INDEX(Data_DBD!$C:$C,$A11)} -> 4 | D11: {=INDEX(Data_DBD!$D:$D,$A11)} -> 15 | E11: {=INDEX(Data_DBD!$E:$E,$A11)} -> 1 | F11: {=INDEX(Data_DBD!$F:$F,$A11)} -> 2 | H11: 72 | I11: 3 | J11: 5 | K11: 10 | L11: 1 | M11: 2
A12: =RANDBETWEEN(2,164) -> 96 | B12: {=INDEX(Data_DBD!$B:$B,$A12)} -> 56 | C12: {=INDEX(Data_DBD!$C:$C,$A12)} -> 4 | D12: {=INDEX(Data_DBD!$D:$D,$A12)} -> 18 | E12: {=INDEX(Data_DBD!$E:$E,$A12)} -> 0 | F12: {=INDEX(Data_DBD!$F:$F,$A12)} -> 3 | H12: 57 | I12: 2 | J12: 2 | K12: 15 | L12: 1 | M12: 2
A13: =RANDBETWEEN(2,164) -> 156 | B13: {=INDEX(Data_DBD!$B:$B,$A13)} -> 5 | C13: {=INDEX(Data_DBD!$C:$C,$A13)} -> 2 | D13: {=INDEX(Data_DBD!$D:$D,$A13)} -> 21 | E13: {=INDEX(Data_DBD!$E:$E,$A13)} -> 0 | F13: {=INDEX(Data_DBD!$F:$F,$A13)} -> 3 | H13: 67 | I13: 21 | J13: 3 | K13: 10 | L13: 1 | M13: 2
A14: =RANDBETWEEN(2,164) -> 91 | B14: {=INDEX(Data_DBD!$B:$B,$A14)} -> 35 | C14: {=INDEX(Data_DBD!$C:$C,$A14)} -> 1 | D14: {=INDEX(Data_DBD!$D:$D,$A14)} -> 18 | E14: {=INDEX(Data_DBD!$E:$E,$A14)} -> 1 | F14: {=INDEX(Data_DBD!$F:$F,$A14)} -> 3 | H14: 91 | I14: 35 | J14: 1 | K14: 18 | L14: 1 | M14: 3
A15: =RANDBETWEEN(2,164) -> 84 | B15: {=INDEX(Data_DBD!$B:$B,$A15)} -> 42 | C15: {=INDEX(Data_DBD!$C:$C,$A15)} -> 4 | D15: {=INDEX(Data_DBD!$D:$D,$A15)} -> 13 | E15: {=INDEX(Data_DBD!$E:$E,$A15)} -> 1 | F15: {=INDEX(Data_DBD!$F:$F,$A15)} -> 2 | H15: 22 | I15: 6 | J15: 3 | K15: 14 | L15: 0 | M15: 2
A16: =RANDBETWEEN(2,164) -> 160 | B16: {=INDEX(Data_DBD!$B:$B,$A16)} -> 16 | C16: {=INDEX(Data_DBD!$C:$C,$A16)} -> 3 | D16: {=INDEX(Data_DBD!$D:$D,$A16)} -> 21 | E16: {=INDEX(Data_DBD!$E:$E,$A16)} -> 0 | F16: {=INDEX(Data_DBD!$F:$F,$A16)} -> 3 | H16: 145 | I16: 28 | J16: 4 | K16: 21 | L16: 1 | M16: 3
A17: =RANDBETWEEN(2,164) -> 83 | B17: {=INDEX(Data_DBD!$B:$B,$A17)} -> 50 | C17: {=INDEX(Data_DBD!$C:$C,$A17)} -> 3 | D17: {=INDEX(Data_DBD!$D:$D,$A17)} -> 13 | E17: {=INDEX(Data_DBD!$E:$E,$A17)} -> 0 | F17: {=INDEX(Data_DBD!$F:$F,$A17)} -> 2 | H17: 50 | I17: 19 | J17: 5 | K17: 13 | L17: 0 | M17: 2
... A57: =RANDBETWEEN(2,164) -> 150 | B57: {=INDEX(Data_DBD!$B:$B,$A57)} -> 61 | C57: {=INDEX(Data_DBD!$C:$C,$A57)} -> 5 | D57: {=INDEX(Data_DBD!$D:$D,$A57)} -> 21 | E57: {=INDEX(Data_DBD!$E:$E,$A57)} -> 1 | F57: {=INDEX(Data_DBD!$F:$F,$A57)} -> 3 | H57: 39 | I57: 12 | J57: 5 | K57: 13 | L57: 1 | M57: 2
A58: =RANDBETWEEN(2,164) -> 110 | B58: {=INDEX(Data_DBD!$B:$B,$A58)} -> 42 | C58: {=INDEX(Data_DBD!$C:$C,$A58)} -> 2 | D58: {=INDEX(Data_DBD!$D:$D,$A58)} -> 33 | E58: {=INDEX(Data_DBD!$E:$E,$A58)} -> 1 | F58: {=INDEX(Data_DBD!$F:$F,$A58)} -> 3 | H58: 30 | I58: 2,8 | J58: 2 | K58: 14 | L58: 1 | M58: 2
A59: =RANDBETWEEN(2,164) -> 138 | B59: {=INDEX(Data_DBD!$B:$B,$A59)} -> 13 | C59: {=INDEX(Data_DBD!$C:$C,$A59)} -> 3 | D59: {=INDEX(Data_DBD!$D:$D,$A59)} -> 33 | E59: {=INDEX(Data_DBD!$E:$E,$A59)} -> 1 | F59: {=INDEX(Data_DBD!$F:$F,$A59)} -> 3 | H59: 25 | I59: 81 | J59: 5 | K59: 14 | L59: 0 | M59: 2
A60: =RANDBETWEEN(2,164) -> 76 | B60: {=INDEX(Data_DBD!$B:$B,$A60)} -> 70 | C60: {=INDEX(Data_DBD!$C:$C,$A60)} -> 2 | D60: {=INDEX(Data_DBD!$D:$D,$A60)} -> 10 | E60: {=INDEX(Data_DBD!$E:$E,$A60)} -> 0 | F60: {=INDEX(Data_DBD!$F:$F,$A60)} -> 2 | H60: 73 | I60: 15 | J60: 3 | K60: 10 | L60: 1 | M60: 2
A61: =RANDBETWEEN(2,164) -> 156 | B61: {=INDEX(Data_DBD!$B:$B,$A61)} -> 5 | C61: {=INDEX(Data_DBD!$C:$C,$A61)} -> 2 | D61: {=INDEX(Data_DBD!$D:$D,$A61)} -> 21 | E61: {=INDEX(Data_DBD!$E:$E,$A61)} -> 0 | F61: {=INDEX(Data_DBD!$F:$F,$A61)} -> 3 | H61: 64 | I61: 35 | J61: 1 | K61: 15 | L61: 0 | M61: 2
A62: =RANDBETWEEN(2,164) -> 44 | B62: {=INDEX(Data_DBD!$B:$B,$A62)} -> 28 | C62: {=INDEX(Data_DBD!$C:$C,$A62)} -> 5 | D62: {=INDEX(Data_DBD!$D:$D,$A62)} -> 13 | E62: {=INDEX(Data_DBD!$E:$E,$A62)} -> 1 | F62: {=INDEX(Data_DBD!$F:$F,$A62)} -> 2 | H62: 68 | I62: 44 | J62: 5 | K62: 10 | L62: 0 | M62: 2
A63: =RANDBETWEEN(2,164) -> 38 | B63: {=INDEX(Data_DBD!$B:$B,$A63)} -> 52 | C63: {=INDEX(Data_DBD!$C:$C,$A63)} -> 3 | D63: {=INDEX(Data_DBD!$D:$D,$A63)} -> 4 | E63: {=INDEX(Data_DBD!$E:$E,$A63)} -> 1 | F63: {=INDEX(Data_DBD!$F:$F,$A63)} -> 1 | H63: 60 | I63: 68 | J63: 4 | K63: 15 | L63: 0 | M63: 2
A64: =RANDBETWEEN(2,164) -> 107 | B64: {=INDEX(Data_DBD!$B:$B,$A64)} -> 48 | C64: {=INDEX(Data_DBD!$C:$C,$A64)} -> 5 | D64: {=INDEX(Data_DBD!$D:$D,$A64)} -> 18 | E64: {=INDEX(Data_DBD!$E:$E,$A64)} -> 0 | F64: {=INDEX(Data_DBD!$F:$F,$A64)} -> 3 | H64: 66 | I64: 21 | J64: 5 | K64: 15 | L64: 1 | M64: 2
A65: =RANDBETWEEN(2,164) -> 142 | B65: {=INDEX(Data_DBD!$B:$B,$A65)} -> 39 | C65: {=INDEX(Data_DBD!$C:$C,$A65)} -> 2 | D65: {=INDEX(Data_DBD!$D:$D,$A65)} -> 21 | E65: {=INDEX(Data_DBD!$E:$E,$A65)} -> 1 | F65: {=INDEX(Data_DBD!$F:$F,$A65)} -> 3 | H65: 19 | I65: 8 | J65: 4 | K65: 7 | L65: 0 | M65: 1
A66: =RANDBETWEEN(2,164) -> 136 | B66: {=INDEX(Data_DBD!$B:$B,$A66)} -> 6 | C66: {=INDEX(Data_DBD!$C:$C,$A66)} -> 2 | D66: {=INDEX(Data_DBD!$D:$D,$A66)} -> 33 | E66: {=INDEX(Data_DBD!$E:$E,$A66)} -> 0 | F66: {=INDEX(Data_DBD!$F:$F,$A66)} -> 3 | H66: 88 | I66: 20 | J66: 4 | K66: 13 | L66: 1 | M66: 2
A67: =RANDBETWEEN(2,164) -> 125 | B67: {=INDEX(Data_DBD!$B:$B,$A67)} -> 39 | C67: {=INDEX(Data_DBD!$C:$C,$A67)} -> 4 | D67: {=INDEX(Data_DBD!$D:$D,$A67)} -> 33 | E67: {=INDEX(Data_DBD!$E:$E,$A67)} -> 0 | F67: {=INDEX(Data_DBD!$F:$F,$A67)} -> 3 | H67: 28 | I67: 22 | J67: 2 | K67: 14 | L67: 1 | M67: 2
A68: =RANDBETWEEN(2,164) -> 108 | B68: {=INDEX(Data_DBD!$B:$B,$A68)} -> 69 | C68: {=INDEX(Data_DBD!$C:$C,$A68)} -> 7 | D68: {=INDEX(Data_DBD!$D:$D,$A68)} -> 33 | E68: {=INDEX(Data_DBD!$E:$E,$A68)} -> 1 | F68: {=INDEX(Data_DBD!$F:$F,$A68)} -> 3 | H68: 50 | I68: 19 | J68: 5 | K68: 13 | L68: 0 | M68: 2
A69: =RANDBETWEEN(2,164) -> 104 | B69: {=INDEX(Data_DBD!$B:$B,$A69)} -> 37 | C69: {=INDEX(Data_DBD!$C:$C,$A69)} -> 4 | D69: {=INDEX(Data_DBD!$D:$D,$A69)} -> 18 | E69: {=INDEX(Data_DBD!$E:$E,$A69)} -> 1 | F69: {=INDEX(Data_DBD!$F:$F,$A69)} -> 3 | H69: 118 | I69: 67 | J69: 4 | K69: 33 | L69: 1 | M69: 3
A70: =RANDBETWEEN(2,164) -> 97 | B70: {=INDEX(Data_DBD!$B:$B,$A70)} -> 16 | C70: {=INDEX(Data_DBD!$C:$C,$A70)} -> 2 | D70: {=INDEX(Data_DBD!$D:$D,$A70)} -> 18 | E70: {=INDEX(Data_DBD!$E:$E,$A70)} -> 1 | F70: {=INDEX(Data_DBD!$F:$F,$A70)} -> 3 | H70: 5 | I70: 18 | J70: 2 | K70: 12 | L70: 1 | M70: 2
... A164: =RANDBETWEEN(2,164) -> 136 | B164: {=INDEX(Data_DBD!$B:$B,$A164)} -> 6 | C164: {=INDEX(Data_DBD!$C:$C,$A164)} -> 2 | D164: {=INDEX(Data_DBD!$D:$D,$A164)} -> 33 | E164: {=INDEX(Data_DBD!$E:$E,$A164)} -> 0 | F164: {=INDEX(Data_DBD!$F:$F,$A164)} -> 3 | H164: 42 | I164: 21 | J164: 5 | K164: 13 | L164: 1 | M164: 2
I165: =AVERAGE(I2:I164) -> 31.506173 | J165: =AVERAGE(J2:J164) -> 3.7546012 | K165: =AVERAGE(K2:K164) -> 18.453988 | L165: =AVERAGE(L2:L164) -> 0.55214724
B166: 10
E168: USIA | J168: LAMA RAWAT INAP | O168: JUMLAH KASUS PER BULAN | T168: JENIS KELAMIN
E169: Usia | F169: =AVERAGEIF($I$2:$I$164,"<="&$I$165) -> 17.95 | G169: =AVERAGEIF($I$2:$I$164,">"&$I$165) -> 53.370968 | J169: Lama rawat inap | K169: =AVERAGEIF($J$2:$J$164,"<="&$J$165) -> 2.5616438 | L169: =AVERAGEIF($J$2:$J$164,">"&$J$165) -> 4.7222222 | O169: Jumlah kasus perbulan | P169: =AVERAGEIF($K$2:$K$164,"<="&$K$165) -> 13.047619 | Q169: =AVERAGEIF($K$2:$K$164,">"&$K$165) -> 28.241379 | T169: Jenis kelamin | U169: =AVERAGEIF($L$2:$L$164,"<="&$L$165) -> 0 | V169: =AVERAGEIF($L$2:$L$164,">"&$L$165) -> 1
E170: {=IF($I$2:$I$164<$F$169,"kiri",IF($I$2:$I$164<$G$169,"tengah","kanan"))} -> tengah | F170: Kanan > 50 | J170: {=IF($J$2:$J$164<$K$169,"kiri",IF($J$2:$J$164<$L$169,"tengah","kanan"))} -> kiri | K170: Kanan > 4.52 | O170: {=IF($K$2:$K$164<$P$169,"kiri",IF($K$2:$K$164<$Q$169,"tengah","kanan"))} -> kiri | P170: Kanan > 28.2 | T170: {=IF($L$2:$L$164<$U$169,"kiri",IF($L$2:$L$164<$V$169,"tengah","kanan"))} -> tengah | U170: Kanan > 1
E171: tengah | F171: =COUNTIFS($E$170:$E$332,"Kanan",$M$2:$M$164,"1") -> 0 | G171: =F171/32 -> 0 | J171: kanan | K171: {=SUMPRODUCT((J170:J332="Kanan")*(M2:M164=1))} -> 1 | L171: =K171/42 -> 0.023809524 | O171: kiri | P171: =COUNTIFS($O$170:$O$332,"Kanan",$M$2:$M$164,"1") -> 0 | Q171: =P171/35 -> 0 | T171: kanan | U171: =COUNTIFS($T$170:$T$332,"Kanan",$M$2:$M$164,"1") -> 5 | V171: =U171/85 -> 0.058823529
E172: tengah | F172: =COUNTIFS($E$170:$E$332,"Kanan",$M$2:$M$164,"2") -> 10 | G172: =F172/32 -> 0.3125 | J172: tengah | K172: =COUNTIFS($J$170:$J$332,"Kanan",$M$2:$M$164,"2") -> 28 | L172: =K172/42 -> 0.66666667 | O172: kanan | P172: =COUNTIFS($O$170:$O$332,"Kanan",$M$2:$M$164,"2") -> 0 | Q172: =P172/35 -> 0 | T172: kanan | U172: =COUNTIFS($T$170:$T$332,"Kanan",$M$2:$M$164,"2") -> 43 | V172: =U172/85 -> 0.50588235
E173: kanan | F173: {=SUMPRODUCT((E170:E332="KANAN")*(M2:M164=3))} -> 22 | G173: =F173/32 -> 0.6875 | J173: tengah | K173: =COUNTIFS($J$170:$J$332,"Kanan",$M$2:$M$164,"3") -> 13 | L173: =K173/42 -> 0.30952381 | O173: tengah | P173: =COUNTIFS($O$170:$O$332,"Kanan",$M$2:$M$164,"3") -> 35 | Q173: =P173/35 -> 1 | T173: kanan | U173: =COUNTIFS($T$170:$T$332,"Kanan",$M$2:$M$164,"3") -> 42 | V173: =U173/85 -> 0.49411765
...

Sheet Pohon 5
A1: No | B1: Usia | C1: Lama Rawat Inap | D1: Jumlah Kasus Per Bulan | E1: Jenis Kelamin | F1: Tingkat Resiko | H1: No | I1: Usia | J1: Lama Rawat Inap | K1: Jumlah Kasus Per Bulan | L1: Jenis Kelamin | M1: Tingkat Resiko | O1: Perhitungan root
A2: =RANDBETWEEN(2,164) -> 109 | B2: {=INDEX(Data_DBD!$B:$B,$A2)} -> 40 | C2: {=INDEX(Data_DBD!$C:$C,$A2)} -> 3 | D2: {=INDEX(Data_DBD!$D:$D,$A2)} -> 33 | E2: {=INDEX(Data_DBD!$E:$E,$A2)} -> 1 | F2: {=INDEX(Data_DBD!$F:$F,$A2)} -> 3 | H2: 30 | I2: 2,8 | J2: 2 | K2: 14 | L2: 1 | M2: 2 | O2: 1 | P2: =COUNTIF(M2:M164,"1") -> 14 | Q2: =P2/163 -> 0.085889571
A3: =RANDBETWEEN(2,164) -> 153 | B3: {=INDEX(Data_DBD!$B:$B,$A3)} -> 73 | C3: {=INDEX(Data_DBD!$C:$C,$A3)} -> 7 | D3: {=INDEX(Data_DBD!$D:$D,$A3)} -> 21 | E3: {=INDEX(Data_DBD!$E:$E,$A3)} -> 1 | F3: {=INDEX(Data_DBD!$F:$F,$A3)} -> 3 | H3: 150 | I3: 61 | J3: 5 | K3: 21 | L3: 1 | M3: 3 | O3: 2 | P3: =COUNTIF(M2:M164,"2") -> 84 | Q3: =P3/163 -> 0.51533742
A4: =RANDBETWEEN(2,164) -> 82 | B4: {=INDEX(Data_DBD!$B:$B,$A4)} -> 28 | C4: {=INDEX(Data_DBD!$C:$C,$A4)} -> 3 | D4: {=INDEX(Data_DBD!$D:$D,$A4)} -> 13 | E4: {=INDEX(Data_DBD!$E:$E,$A4)} -> 1 | F4: {=INDEX(Data_DBD!$F:$F,$A4)} -> 2 | H4: 61 | I4: 29 | J4: 3 | K4: 15 | L4: 1 | M4: 2 | O4: 3 | P4: =COUNTIF(M2:M164,"3") -> 65 | Q4: =P4/163 -> 0.39877301
A5: =RANDBETWEEN(2,164) -> 132 | B5: {=INDEX(Data_DBD!$B:$B,$A5)} -> 10 | C5: {=INDEX(Data_DBD!$C:$C,$A5)} -> 3 | D5: {=INDEX(Data_DBD!$D:$D,$A5)} -> 33 | E5: {=INDEX(Data_DBD!$E:$E,$A5)} -> 1 | F5: {=INDEX(Data_DBD!$F:$F,$A5)} -> 3 | H5: 80 | I5: 27 | J5: 3 | K5: 13 | L5: 1 | M5: 2 | O5: Entropy Root | P5: =-(IFERROR(Q2*LOG(Q2,2),0)+IFERROR(Q3*LOG(Q3,2),0)+IFERROR(Q4*LOG(Q4,2),0)) -> 1.325958
A6: =RANDBETWEEN(2,164) -> 59 | B6: {=INDEX(Data_DBD!$B:$B,$A6)} -> 28 | C6: {=INDEX(Data_DBD!$C:$C,$A6)} -> 4 | D6: {=INDEX(Data_DBD!$D:$D,$A6)} -> 15 | E6: {=INDEX(Data_DBD!$E:$E,$A6)} -> 0 | F6: {=INDEX(Data_DBD!$F:$F,$A6)} -> 2 | H6: 128 | I6: 38 | J6: 2 | K6: 33 | L6: 0 | M6: 3
A7: =RANDBETWEEN(2,164) -> 78 | B7: {=INDEX(Data_DBD!$B:$B,$A7)} -> 6 | C7: {=INDEX(Data_DBD!$C:$C,$A7)} -> 3 | D7: {=INDEX(Data_DBD!$D:$D,$A7)} -> 13 | E7: {=INDEX(Data_DBD!$E:$E,$A7)} -> 0 | F7: {=INDEX(Data_DBD!$F:$F,$A7)} -> 2 | H7: 109 | I7: 40 | J7: 3 | K7: 33 | L7: 1 | M7: 3
A8: =RANDBETWEEN(2,164) -> 140 | B8: {=INDEX(Data_DBD!$B:$B,$A8)} -> 74 | C8: {=INDEX(Data_DBD!$C:$C,$A8)} -> 5 | D8: {=INDEX(Data_DBD!$D:$D,$A8)} -> 21 | E8: {=INDEX(Data_DBD!$E:$E,$A8)} -> 1 | F8: {=INDEX(Data_DBD!$F:$F,$A8)} -> 3 | H8: 128 | I8: 38 | J8: 2 | K8: 33 | L8: 0 | M8: 3
A9: =RANDBETWEEN(2,164) -> 44 | B9: {=INDEX(Data_DBD!$B:$B,$A9)} -> 28 | C9: {=INDEX(Data_DBD!$C:$C,$A9)} -> 5 | D9: {=INDEX(Data_DBD!$D:$D,$A9)} -> 13 | E9: {=INDEX(Data_DBD!$E:$E,$A9)} -> 1 | F9: {=INDEX(Data_DBD!$F:$F,$A9)} -> 2 | H9: 57 | I9: 2 | J9: 2 | K9: 15 | L9: 1 | M9: 2
A10: =RANDBETWEEN(2,164) -> 127 | B10: {=INDEX(Data_DBD!$B:$B,$A10)} -> 21 | C10: {=INDEX(Data_DBD!$C:$C,$A10)} -> 2 | D10: {=INDEX(Data_DBD!$D:$D,$A10)} -> 33 | E10: {=INDEX(Data_DBD!$E:$E,$A10)} -> 0 | F10: {=INDEX(Data_DBD!$F:$F,$A10)} -> 3 | H10: 16 | I10: 66 | J10: 5 | K10: 7 | L10: 1 | M10: 1
A11: =RANDBETWEEN(2,164) -> 59 | B11: {=INDEX(Data_DBD!$B:$B,$A11)} -> 28 | C11: {=INDEX(Data_DBD!$C:$C,$A11)} -> 4 | D11: {=INDEX(Data_DBD!$D:$D,$A11)} -> 15 | E11: {=INDEX(Data_DBD!$E:$E,$A11)} -> 0 | F11: {=INDEX(Data_DBD!$F:$F,$A11)} -> 2 | H11: 136 | I11: 6 | J11: 2 | K11: 33 | L11: 0 | M11: 3
A12: =RANDBETWEEN(2,164) -> 11 | B12: {=INDEX(Data_DBD!$B:$B,$A12)} -> 24 | C12: {=INDEX(Data_DBD!$C:$C,$A12)} -> 5 | D12: {=INDEX(Data_DBD!$D:$D,$A12)} -> 12 | E12: {=INDEX(Data_DBD!$E:$E,$A12)} -> 1 | F12: {=INDEX(Data_DBD!$F:$F,$A12)} -> 2 | H12: 8 | I12: 4 | J12: 2 | K12: 12 | L12: 0 | M12: 2
A13: =RANDBETWEEN(2,164) -> 112 | B13: {=INDEX(Data_DBD!$B:$B,$A13)} -> 61 | C13: {=INDEX(Data_DBD!$C:$C,$A13)} -> 3 | D13: {=INDEX(Data_DBD!$D:$D,$A13)} -> 33 | E13: {=INDEX(Data_DBD!$E:$E,$A13)} -> 1 | F13: {=INDEX(Data_DBD!$F:$F,$A13)} -> 3 | H13: 50 | I13: 19 | J13: 5 | K13: 13 | L13: 0 | M13: 2
A14: =RANDBETWEEN(2,164) -> 57 | B14: {=INDEX(Data_DBD!$B:$B,$A14)} -> 2 | C14: {=INDEX(Data_DBD!$C:$C,$A14)} -> 2 | D14: {=INDEX(Data_DBD!$D:$D,$A14)} -> 15 | E14: {=INDEX(Data_DBD!$E:$E,$A14)} -> 1 | F14: {=INDEX(Data_DBD!$F:$F,$A14)} -> 2 | H14: 73 | I14: 15 | J14: 3 | K14: 10 | L14: 1 | M14: 2
A15: =RANDBETWEEN(2,164) -> 62 | B15: {=INDEX(Data_DBD!$B:$B,$A15)} -> 43 | C15: {=INDEX(Data_DBD!$C:$C,$A15)} -> 4 | D15: {=INDEX(Data_DBD!$D:$D,$A15)} -> 15 | E15: {=INDEX(Data_DBD!$E:$E,$A15)} -> 1 | F15: {=INDEX(Data_DBD!$F:$F,$A15)} -> 2 | H15: 63 | I15: 25 | J15: 3 | K15: 15 | L15: 0 | M15: 2
A16: =RANDBETWEEN(2,164) -> 79 | B16: {=INDEX(Data_DBD!$B:$B,$A16)} -> 29 | C16: {=INDEX(Data_DBD!$C:$C,$A16)} -> 3 | D16: {=INDEX(Data_DBD!$D:$D,$A16)} -> 13 | E16: {=INDEX(Data_DBD!$E:$E,$A16)} -> 0 | F16: {=INDEX(Data_DBD!$F:$F,$A16)} -> 2 | H16: 138 | I16: 13 | J16: 3 | K16: 33 | L16: 1 | M16: 3
A17: =RANDBETWEEN(2,164) -> 113 | B17: {=INDEX(Data_DBD!$B:$B,$A17)} -> 69 | C17: {=INDEX(Data_DBD!$C:$C,$A17)} -> 1 | D17: {=INDEX(Data_DBD!$D:$D,$A17)} -> 33 | E17: {=INDEX(Data_DBD!$E:$E,$A17)} -> 1 | F17: {=INDEX(Data_DBD!$F:$F,$A17)} -> 3 | H17: 21 | I17: 10 | J17: 5 | K17: 14 | L17: 1 | M17: 2
... A164: =RANDBETWEEN(2,164) -> 14 | B164: {=INDEX(Data_DBD!$B:$B,$A164)} -> 49 | C164: {=INDEX(Data_DBD!$C:$C,$A164)} -> 4 | D164: {=INDEX(Data_DBD!$D:$D,$A164)} -> 7 | E164: {=INDEX(Data_DBD!$E:$E,$A164)} -> 1 | F164: {=INDEX(Data_DBD!$F:$F,$A164)} -> 1 | H164: 22 | I164: 6 | J164: 3 | K164: 14 | L164: 0 | M164: 2
I165: =AVERAGE(I2:I164) -> 31.503086 | J165: =AVERAGE(J2:J164) -> 3.6809816 | K165: =AVERAGE(K2:K164) -> 17.717791 | L165: =AVERAGE(L2:L164) -> 0.5398773
B166: 9
E168: USIA | J168: LAMA RAWAT INAP | O168: JUMLAH KASUS PER BULAN | T168: JENIS KELAMIN
E169: Usia | F169: =AVERAGEIF($I$2:$I$164,"<="&$I$165) -> 15.713542 | G169: =AVERAGEIF($I$2:$I$164,">"&$I$165) -> 54.469697 | J169: Lama rawat inap | K169: =AVERAGEIF($J$2:$J$164,"<="&$J$165) -> 2.5324675 | L169: =AVERAGEIF($J$2:$J$164,">"&$J$165) -> 4.7093023 | O169: Jumlah kasus perbulan | P169: =AVERAGEIF($K$2:$K$164,"<="&$K$165) -> 12.112245 | Q169: =AVERAGEIF($K$2:$K$164,">"&$K$165) -> 26.169231 | T169: Jenis kelamin | U169: =AVERAGEIF($L$2:$L$164,"<="&$L$165) -> 0 | V169: =AVERAGEIF($L$2:$L$164,">"&$L$165) -> 1
E170: {=IF($I$2:$I$164<$F$169,"kiri",IF($I$2:$I$164<$G$169,"tengah","kanan"))} -> kanan | F170: Kanan > 50 | J170: {=IF($J$2:$J$164<$K$169,"kiri",IF($J$2:$J$164<$L$169,"tengah","kanan"))} -> kiri | K170: Kanan > 4.52 | O170: {=IF($K$2:$K$164<$P$169,"kiri",IF($K$2:$K$164<$Q$169,"tengah","kanan"))} -> tengah | P170: Kanan > 28.2 | T170: {=IF($L$2:$L$164<$U$169,"kiri",IF($L$2:$L$164<$V$169,"tengah","kanan"))} -> kanan | U170: Kanan > 1
E171: kanan | F171: =COUNTIFS($E$170:$E$332,"Kanan",$M$2:$M$164,"1") -> 1 | G171: =F171/32 -> 0.03125 | J171: kanan | K171: {=SUMPRODUCT((J170:J332="Kanan")*(M2:M164=1))} -> 5 | L171: =K171/35 -> 0.14285714 | O171: tengah | P171: =COUNTIFS($O$170:$O$332,"Kanan",$M$2:$M$164,"1") -> 0 | Q171: =P171/31 -> 0 | T171: kanan | U171: =COUNTIFS($T$170:$T$332,"Kanan",$M$2:$M$164,"1") -> 8 | V171: =U171/88 -> 0.090909091
E172: tengah | F172: =COUNTIFS($E$170:$E$332,"Kanan",$M$2:$M$164,"2") -> 18 | G172: =F172/32 -> 0.5625 | J172: tengah | K172: =COUNTIFS($J$170:$J$332,"Kanan",$M$2:$M$164,"2") -> 13 | L172: =K172/35 -> 0.37142857 | O172: tengah | P172: =COUNTIFS($O$170:$O$332,"Kanan",$M$2:$M$164,"2") -> 0 | Q172: =P172/31 -> 0 | T172: kanan | U172: =COUNTIFS($T$170:$T$332,"Kanan",$M$2:$M$164,"2") -> 41 | V172: =U172/88 -> 0.46590909
E173: tengah | F173: {=SUMPRODUCT((E170:E332="KANAN")*(M2:M164=3))} -> 13 | G173: =F173/32 -> 0.40625 | J173: tengah | K173: =COUNTIFS($J$170:$J$332,"Kanan",$M$2:$M$164,"3") -> 17 | L173: =K173/35 -> 0.48571429 | O173: tengah | P173: =COUNTIFS($O$170:$O$332,"Kanan",$M$2:$M$164,"3") -> 31 | Q173: =P173/31 -> 1 | T173: kanan | U173: =COUNTIFS($T$170:$T$332,"Kanan",$M$2:$M$164,"3") -> 39 | V173: =U173/88 -> 0.44318182
