Workbook

Sheet Data_DBD
A1: Nama | B1: Usia | C1: Lama Rawat Inap | D1: Jumlah Kasus Perbulan | E1: Jenis Kelamin | F1: Tingkat Resiko
A2: Neni Sumetria | B2: 34 | C2: 3 | D2: 12 | E2: 0 | F2: Sedang
A3: Malki Amron | B3: 43 | C3: 3 | D3: 12 | E3: 1 | F3: Sedang
A4: Arifa Qyaratul | B4: 23 | C4: 5 | D4: 12 | E4: 0 | F4: Sedang
A5: Rezki Mhd | B5: 18 | C5: 2 | D5: 12 | E5: 1 | F5: Sedang
A6: Selfiolla | B6: 14 | C6: 4 | D6: 12 | E6: 0 | F6: Sedang
A7: M.Albiruni | B7: 12 | C7: 1 | D7: 12 | E7: 1 | F7: Sedang
A8: Yurika Azarine | B8: 4 | C8: 2 | D8: 12 | E8: 0 | F8: Sedang
A9: Rahmad Ihtiar | B9: 16 | C9: 6 | D9: 12 | E9: 1 | F9: Sedang
A10: Tiara Endiwa | B10: 18 | C10: 5 | D10: 12 | E10: 0 | F10: Sedang
A11: Boby | B11: 24 | C11: 5 | D11: 12 | E11: 1 | F11: Sedang
A12: Defi Putri | B12: 23 | C12: 3 | D12: 12 | E12: 0 | F12: Sedang
A13: Nini Efriza | B13: 47 | C13: 2 | D13: 12 | E13: 0 | F13: Sedang
... A164: Aprillia Khairunnisa | B164: 10 | C164: 6 | D164: 3 | E164: 0 | F164: Rendah

Sheet Random_Sampling
A1: Random Sampling Data
A3: Usia | B3: =RAND() -> 0.57234716
A4: Lama Rawat Inap | B4: =RAND() -> 0.88611739
A5: Jenis Kelamin | B5: =RAND() -> 0.55737233
A6: Jumlah Kasus Per Bulan | B6: =RAND() -> 0.63169925 | D6: 9

Sheet Pohon 1
A1: No | B1: Usia | C1: Lama Rawat Inap | D1: Jumlah Kasus Per Bulan | E1: Jenis Kelamin | F1: Tingkat Resiko | H1: No | I1: Usia | J1: Lama Rawat Inap | K1: Jumlah Kasus Per Bulan | L1: Jenis Kelamin | M1: Tingkat Resiko | O1: Perhitungan root
A2: =RANDBETWEEN(2,164) -> 112 | B2: {=INDEX(Data_DBD!$B:$B,$A2)} -> 61 | C2: {=INDEX(Data_DBD!$C:$C,$A2)} -> 3 | D2: {=INDEX(Data_DBD!$D:$D,$A2)} -> 33 | E2: {=INDEX(Data_DBD!$E:$E,$A2)} -> 1 | F2: {=INDEX(Data_DBD!$F:$F,$A2)} -> Tinggi | H2: 42 | I2: 21 | J2: 5 | K2: 13 | L2: 1 | M2: Sedang | O2: Tinggi | P2: =COUNTIF(M2:M164,"Tinggi") -> 53 | Q2: =P2/163 -> 0.32515337
A3: =RANDBETWEEN(2,164) -> 153 | B3: {=INDEX(Data_DBD!$B:$B,$A3)} -> 73 | C3: {=INDEX(Data_DBD!$C:$C,$A3)} -> 7 | D3: {=INDEX(Data_DBD!$D:$D,$A3)} -> 21 | E3: {=INDEX(Data_DBD!$E:$E,$A3)} -> 1 | F3: {=INDEX(Data_DBD!$F:$F,$A3)} -> Tinggi | H3: 47 | I3: 19 | J3: 2 | K3: 13 | L3: 0 | M3: Sedang | O3: Sedang | P3: =COUNTIF(M2:M164,"Sedang") -> 93 | Q3: =P3/163 -> 0.57055215
A4: =RANDBETWEEN(2,164) -> 79 | B4: {=INDEX(Data_DBD!$B:$B,$A4)} -> 29 | C4: {=INDEX(Data_DBD!$C:$C,$A4)} -> 3 | D4: {=INDEX(Data_DBD!$D:$D,$A4)} -> 13 | E4: {=INDEX(Data_DBD!$E:$E,$A4)} -> 0 | F4: {=INDEX(Data_DBD!$F:$F,$A4)} -> Sedang | H4: 123 | I4: 22 | J4: 4 | K4: 33 | L4: 0 | M4: Tinggi | O4: Rendah | P4: =COUNTIF(M2:M164,"Rendah") -> 17 | Q4: =P4/163 -> 0.10429448
A5: =RANDBETWEEN(2,164) -> 147 | B5: {=INDEX(Data_DBD!$B:$B,$A5)} -> 66 | C5: {=INDEX(Data_DBD!$C:$C,$A5)} -> 10 | D5: {=INDEX(Data_DBD!$D:$D,$A5)} -> 21 | E5: {=INDEX(Data_DBD!$E:$E,$A5)} -> 1 | F5: {=INDEX(Data_DBD!$F:$F,$A5)} -> Tinggi | H5: 52 | I5: 59 | J5: 4 | K5: 15 | L5: 1 | M5: Sedang | O5: Entropy Root | P5: =-(IFERROR(Q2*LOG(Q2,2),0)+IFERROR(Q3*LOG(Q3,2),0)+IFERROR(Q4*LOG(Q4,2),0)) -> 1.3290446
A6: =RANDBETWEEN(2,164) -> 90 | B6: {=INDEX(Data_DBD!$B:$B,$A6)} -> 47 | C6: {=INDEX(Data_DBD!$C:$C,$A6)} -> 3 | D6: {=INDEX(Data_DBD!$D:$D,$A6)} -> 18 | E6: {=INDEX(Data_DBD!$E:$E,$A6)} -> 0 | F6: {=INDEX(Data_DBD!$F:$F,$A6)} -> Sedang | H6: 111 | I6: 25 | J6: 4 | K6: 33 | L6: 0 | M6: Tinggi
A7: =RANDBETWEEN(2,164) -> 59 | B7: {=INDEX(Data_DBD!$B:$B,$A7)} -> 28 | C7: {=INDEX(Data_DBD!$C:$C,$A7)} -> 4 | D7: {=INDEX(Data_DBD!$D:$D,$A7)} -> 15 | E7: {=INDEX(Data_DBD!$E:$E,$A7)} -> 0 | F7: {=INDEX(Data_DBD!$F:$F,$A7)} -> Sedang | H7: 156 | I7: 5 | J7: 2 | K7: 21 | L7: 0 | M7: Tinggi
A8: =RANDBETWEEN(2,164) -> 86 | B8: {=INDEX(Data_DBD!$B:$B,$A8)} -> 23 | C8: {=INDEX(Data_DBD!$C:$C,$A8)} -> 3 | D8: {=INDEX(Data_DBD!$D:$D,$A8)} -> 13 | E8: {=INDEX(Data_DBD!$E:$E,$A8)} -> 0 | F8: {=INDEX(Data_DBD!$F:$F,$A8)} -> Sedang | H8: 64 | I8: 35 | J8: 1 | K8: 15 | L8: 0 | M8: Sedang
A9: =RANDBETWEEN(2,164) -> 22 | B9: {=INDEX(Data_DBD!$B:$B,$A9)} -> 6 | C9: {=INDEX(Data_DBD!$C:$C,$A9)} -> 3 | D9: {=INDEX(Data_DBD!$D:$D,$A9)} -> 14 | E9: {=INDEX(Data_DBD!$E:$E,$A9)} -> 0 | F9: {=INDEX(Data_DBD!$F:$F,$A9)} -> Sedang | H9: 160 | I9: 16 | J9: 3 | K9: 21 | L9: 0 | M9: Tinggi
A10: =RANDBETWEEN(2,164) -> 75 | B10: {=INDEX(Data_DBD!$B:$B,$A10)} -> 2 | C10: {=INDEX(Data_DBD!$C:$C,$A10)} -> 2 | D10: {=INDEX(Data_DBD!$D:$D,$A10)} -> 10 | E10: {=INDEX(Data_DBD!$E:$E,$A10)} -> 1 | F10: {=INDEX(Data_DBD!$F:$F,$A10)} -> Rendah | H10: 82 | I10: 28 | J10: 3 | K10: 13 | L10: 1 | M10: Sedang
A11: =RANDBETWEEN(2,164) -> 74 | B11: {=INDEX(Data_DBD!$B:$B,$A11)} -> 9 | C11: {=INDEX(Data_DBD!$C:$C,$A11)} -> 4 | D11: {=INDEX(Data_DBD!$D:$D,$A11)} -> 10 | E11: {=INDEX(Data_DBD!$E:$E,$A11)} -> 0 | F11: {=INDEX(Data_DBD!$F:$F,$A11)} -> Rendah | H11: 6 | I11: 14 | J11: 4 | K11: 12 | L11: 0 | M11: Sedang
A12: =RANDBETWEEN(2,164) -> 152 | B12: {=INDEX(Data_DBD!$B:$B,$A12)} -> 47 | C12: {=INDEX(Data_DBD!$C:$C,$A12)} -> 3 | D12: {=INDEX(Data_DBD!$D:$D,$A12)} -> 21 | E12: {=INDEX(Data_DBD!$E:$E,$A12)} -> 1 | F12: {=INDEX(Data_DBD!$F:$F,$A12)} -> Tinggi | H12: 121 | I12: 82 | J12: 5 | K12: 33 | L12: 1 | M12: Tinggi
A13: =RANDBETWEEN(2,164) -> 121 | B13: {=INDEX(Data_DBD!$B:$B,$A13)} -> 82 | C13: {=INDEX(Data_DBD!$C:$C,$A13)} -> 5 | D13: {=INDEX(Data_DBD!$D:$D,$A13)} -> 33 | E13: {=INDEX(Data_DBD!$E:$E,$A13)} -> 1 | F13: {=INDEX(Data_DBD!$F:$F,$A13)} -> Tinggi | H13: 138 | I13: 13 | J13: 3 | K13: 33 | L13: 1 | M13: Tinggi
A14: =RANDBETWEEN(2,164) -> 106 | B14: {=INDEX(Data_DBD!$B:$B,$A14)} -> 23 | C14: {=INDEX(Data_DBD!$C:$C,$A14)} -> 3 | D14: {=INDEX(Data_DBD!$D:$D,$A14)} -> 18 | E14: {=INDEX(Data_DBD!$E:$E,$A14)} -> 1 | F14: {=INDEX(Data_DBD!$F:$F,$A14)} -> Sedang | H14: 122 | I14: 28 | J14: 3 | K14: 33 | L14: 1 | M14: Tinggi
A15: =RANDBETWEEN(2,164) -> 93 | B15: {=INDEX(Data_DBD!$B:$B,$A15)} -> 65 | C15: {=INDEX(Data_DBD!$C:$C,$A15)} -> 4 | D15: {=INDEX(Data_DBD!$D:$D,$A15)} -> 18 | E15: {=INDEX(Data_DBD!$E:$E,$A15)} -> 0 | F15: {=INDEX(Data_DBD!$F:$F,$A15)} -> Sedang | H15: 10 | I15: 18 | J15: 5 | K15: 12 | L15: 0 | M15: Sedang
A16: =RANDBETWEEN(2,164) -> 24 | B16: {=INDEX(Data_DBD!$B:$B,$A16)} -> 60 | C16: {=INDEX(Data_DBD!$C:$C,$A16)} -> 4 | D16: {=INDEX(Data_DBD!$D:$D,$A16)} -> 14 | E16: {=INDEX(Data_DBD!$E:$E,$A16)} -> 0 | F16: {=INDEX(Data_DBD!$F:$F,$A16)} -> Sedang | H16: 71 | I16: 84 | J16: 3 | K16: 10 | L16: 0 | M16: Rendah
A17: =RANDBETWEEN(2,164) -> 83 | B17: {=INDEX(Data_DBD!$B:$B,$A17)} -> 50 | C17: {=INDEX(Data_DBD!$C:$C,$A17)} -> 3 | D17: {=INDEX(Data_DBD!$D:$D,$A17)} -> 13 | E17: {=INDEX(Data_DBD!$E:$E,$A17)} -> 0 | F17: {=INDEX(Data_DBD!$F:$F,$A17)} -> Sedang | H17: 128 | I17: 38 | J17: 2 | K17: 33 | L17: 0 | M17: Tinggi
... A65: =RANDBETWEEN(2,164) -> 49 | B65: {=INDEX(Data_DBD!$B:$B,$A65)} -> 64 | C65: {=INDEX(Data_DBD!$C:$C,$A65)} -> 5 | D65: {=INDEX(Data_DBD!$D:$D,$A65)} -> 13 | E65: {=INDEX(Data_DBD!$E:$E,$A65)} -> 0 | F65: {=INDEX(Data_DBD!$F:$F,$A65)} -> Sedang | H65: 141 | I65: 36 | J65: 2 | K65: 21 | L65: 0 | M65: Tinggi
A66: =RANDBETWEEN(2,164) -> 113 | B66: {=INDEX(Data_DBD!$B:$B,$A66)} -> 69 | C66: {=INDEX(Data_DBD!$C:$C,$A66)} -> 1 | D66: {=INDEX(Data_DBD!$D:$D,$A66)} -> 33 | E66: {=INDEX(Data_DBD!$E:$E,$A66)} -> 1 | F66: {=INDEX(Data_DBD!$F:$F,$A66)} -> Tinggi | H66: 128 | I66: 38 | J66: 2 | K66: 33 | L66: 0 | M66: Tinggi | U66: Pohon 1:
A67: =RANDBETWEEN(2,164) -> 109 | B67: {=INDEX(Data_DBD!$B:$B,$A67)} -> 40 | C67: {=INDEX(Data_DBD!$C:$C,$A67)} -> 3 | D67: {=INDEX(Data_DBD!$D:$D,$A67)} -> 33 | E67: {=INDEX(Data_DBD!$E:$E,$A67)} -> 1 | F67: {=INDEX(Data_DBD!$F:$F,$A67)} -> Tinggi | H67: 89 | I67: 32 | J67: 4 | K67: 13 | L67: 0 | M67: Sedang | U67: Rule 1.1
A68: =RANDBETWEEN(2,164) -> 35 | B68: {=INDEX(Data_DBD!$B:$B,$A68)} -> 40 | C68: {=INDEX(Data_DBD!$C:$C,$A68)} -> 3 | D68: {=INDEX(Data_DBD!$D:$D,$A68)} -> 4 | E68: {=INDEX(Data_DBD!$E:$E,$A68)} -> 1 | F68: {=INDEX(Data_DBD!$F:$F,$A68)} -> Rendah | H68: 11 | I68: 24 | J68: 5 | K68: 12 | L68: 1 | M68: Sedang | U68: IF Jumlah Kasus Per Bulan < 13,35
A69: =RANDBETWEEN(2,164) -> 116 | B69: {=INDEX(Data_DBD!$B:$B,$A69)} -> 32 | C69: {=INDEX(Data_DBD!$C:$C,$A69)} -> 4 | D69: {=INDEX(Data_DBD!$D:$D,$A69)} -> 33 | E69: {=INDEX(Data_DBD!$E:$E,$A69)} -> 1 | F69: {=INDEX(Data_DBD!$F:$F,$A69)} -> Tinggi | H69: 79 | I69: 29 | J69: 3 | K69: 13 | L69: 0 | M69: Sedang | U69: THEN Risiko = Sedang
A70: =RANDBETWEEN(2,164) -> 142 | B70: {=INDEX(Data_DBD!$B:$B,$A70)} -> 39 | C70: {=INDEX(Data_DBD!$C:$C,$A70)} -> 2 | D70: {=INDEX(Data_DBD!$D:$D,$A70)} -> 21 | E70: {=INDEX(Data_DBD!$E:$E,$A70)} -> 1 | F70: {=INDEX(Data_DBD!$F:$F,$A70)} -> Tinggi | H70: 133 | I70: 6 | J70: 4 | K70: 33 | L70: 0 | M70: Tinggi | U70: Rule 1.2
A71: =RANDBETWEEN(2,164) -> 64 | B71: {=INDEX(Data_DBD!$B:$B,$A71)} -> 35 | C71: {=INDEX(Data_DBD!$C:$C,$A71)} -> 1 | D71: {=INDEX(Data_DBD!$D:$D,$A71)} -> 15 | E71: {=INDEX(Data_DBD!$E:$E,$A71)} -> 0 | F71: {=INDEX(Data_DBD!$F:$F,$A71)} -> Sedang | H71: 133 | I71: 6 | J71: 4 | K71: 33 | L71: 0 | M71: Tinggi | U71: IF Jumlah Kasus Per Bulan ≤ 13,35 AND Jumlah Kasus Per Bulan > 27,46
A72: =RANDBETWEEN(2,164) -> 49 | B72: {=INDEX(Data_DBD!$B:$B,$A72)} -> 64 | C72: {=INDEX(Data_DBD!$C:$C,$A72)} -> 5 | D72: {=INDEX(Data_DBD!$D:$D,$A72)} -> 13 | E72: {=INDEX(Data_DBD!$E:$E,$A72)} -> 0 | F72: {=INDEX(Data_DBD!$F:$F,$A72)} -> Sedang | H72: 94 | I72: 12 | J72: 4 | K72: 18 | L72: 0 | M72: Sedang | U72: THEN Risiko = Tinggi
A73: =RANDBETWEEN(2,164) -> 101 | B73: {=INDEX(Data_DBD!$B:$B,$A73)} -> 42 | C73: {=INDEX(Data_DBD!$C:$C,$A73)} -> 5 | D73: {=INDEX(Data_DBD!$D:$D,$A73)} -> 18 | E73: {=INDEX(Data_DBD!$E:$E,$A73)} -> 0 | F73: {=INDEX(Data_DBD!$F:$F,$A73)} -> Sedang | H73: 84 | I73: 42 | J73: 4 | K73: 13 | L73: 1 | M73: Sedang | U73: Rule 1.3
A74: =RANDBETWEEN(2,164) -> 115 | B74: {=INDEX(Data_DBD!$B:$B,$A74)} -> 52 | C74: {=INDEX(Data_DBD!$C:$C,$A74)} -> 3 | D74: {=INDEX(Data_DBD!$D:$D,$A74)} -> 33 | E74: {=INDEX(Data_DBD!$E:$E,$A74)} -> 1 | F74: {=INDEX(Data_DBD!$F:$F,$A74)} -> Tinggi | H74: 33 | I74: 19 | J74: 4 | K74: 14 | L74: 1 | M74: Sedang | U74: IF Jumlah Kasus Per Bulan > 28,4 THEN Risiko = Tinggi
A75: =RANDBETWEEN(2,164) -> 128 | B75: {=INDEX(Data_DBD!$B:$B,$A75)} -> 38 | C75: {=INDEX(Data_DBD!$C:$C,$A75)} -> 2 | D75: {=INDEX(Data_DBD!$D:$D,$A75)} -> 33 | E75: {=INDEX(Data_DBD!$E:$E,$A75)} -> 0 | F75: {=INDEX(Data_DBD!$F:$F,$A75)} -> Tinggi | H75: 114 | I75: 14 | J75: 2 | K75: 33 | L75: 1 | M75: Tinggi
A76: =RANDBETWEEN(2,164) -> 42 | B76: {=INDEX(Data_DBD!$B:$B,$A76)} -> 21 | C76: {=INDEX(Data_DBD!$C:$C,$A76)} -> 5 | D76: {=INDEX(Data_DBD!$D:$D,$A76)} -> 13 | E76: {=INDEX(Data_DBD!$E:$E,$A76)} -> 1 | F76: {=INDEX(Data_DBD!$F:$F,$A76)} -> Sedang | H76: 77 | I76: 16 | J76: 4 | K76: 13 | L76: 1 | M76: Sedang
A77: =RANDBETWEEN(2,164) -> 77 | B77: {=INDEX(Data_DBD!$B:$B,$A77)} -> 16 | C77: {=INDEX(Data_DBD!$C:$C,$A77)} -> 4 | D77: {=INDEX(Data_DBD!$D:$D,$A77)} -> 13 | E77: {=INDEX(Data_DBD!$E:$E,$A77)} -> 1 | F77: {=INDEX(Data_DBD!$F:$F,$A77)} -> Sedang | H77: 114 | I77: 14 | J77: 2 | K77: 33 | L77: 1 | M77: Tinggi
A78: =RANDBETWEEN(2,164) -> 109 | B78: {=INDEX(Data_DBD!$B:$B,$A78)} -> 40 | C78: {=INDEX(Data_DBD!$C:$C,$A78)} -> 3 | D78: {=INDEX(Data_DBD!$D:$D,$A78)} -> 33 | E78: {=INDEX(Data_DBD!$E:$E,$A78)} -> 1 | F78: {=INDEX(Data_DBD!$F:$F,$A78)} -> Tinggi | H78: 102 | I78: 41 | J78: 4 | K78: 18 | L78: 0 | M78: Sedang
A79: =RANDBETWEEN(2,164) -> 79 | B79: {=INDEX(Data_DBD!$B:$B,$A79)} -> 29 | C79: {=INDEX(Data_DBD!$C:$C,$A79)} -> 3 | D79: {=INDEX(Data_DBD!$D:$D,$A79)} -> 13 | E79: {=INDEX(Data_DBD!$E:$E,$A79)} -> 0 | F79: {=INDEX(Data_DBD!$F:$F,$A79)} -> Sedang | H79: 3 | I79: 43 | J79: 3 | K79: 12 | L79: 1 | M79: Sedang
A80: =RANDBETWEEN(2,164) -> 10 | B80: {=INDEX(Data_DBD!$B:$B,$A80)} -> 18 | C80: {=INDEX(Data_DBD!$C:$C,$A80)} -> 5 | D80: {=INDEX(Data_DBD!$D:$D,$A80)} -> 12 | E80: {=INDEX(Data_DBD!$E:$E,$A80)} -> 0 | F80: {=INDEX(Data_DBD!$F:$F,$A80)} -> Sedang | H80: 72 | I80: 3 | J80: 5 | K80: 10 | L80: 1 | M80: Rendah
A81: =RANDBETWEEN(2,164) -> 23 | B81: {=INDEX(Data_DBD!$B:$B,$A81)} -> 28 | C81: {=INDEX(Data_DBD!$C:$C,$A81)} -> 4 | D81: {=INDEX(Data_DBD!$D:$D,$A81)} -> 14 | E81: {=INDEX(Data_DBD!$E:$E,$A81)} -> 1 | F81: {=INDEX(Data_DBD!$F:$F,$A81)} -> Sedang | H81: 92 | I81: 55 | J81: 7 | K81: 18 | L81: 0 | M81: Sedang
A82: =RANDBETWEEN(2,164) -> 54 | B82: {=INDEX(Data_DBD!$B:$B,$A82)} -> 7 | C82: {=INDEX(Data_DBD!$C:$C,$A82)} -> 3 | D82: {=INDEX(Data_DBD!$D:$D,$A82)} -> 15 | E82: {=INDEX(Data_DBD!$E:$E,$A82)} -> 0 | F82: {=INDEX(Data_DBD!$F:$F,$A82)} -> Sedang | H82: 65 | I82: 49 | J82: 3 | K82: 15 | L82: 0 | M82: Sedang
A83: =RANDBETWEEN(2,164) -> 124 | B83: {=INDEX(Data_DBD!$B:$B,$A83)} -> 24 | C83: {=INDEX(Data_DBD!$C:$C,$A83)} -> 3 | D83: {=INDEX(Data_DBD!$D:$D,$A83)} -> 33 | E83: {=INDEX(Data_DBD!$E:$E,$A83)} -> 1 | F83: {=INDEX(Data_DBD!$F:$F,$A83)} -> Tinggi | H83: 90 | I83: 47 | J83: 3 | K83: 18 | L83: 0 | M83: Sedang
A84: =RANDBETWEEN(2,164) -> 100 | B84: {=INDEX(Data_DBD!$B:$B,$A84)} -> 19 | C84: {=INDEX(Data_DBD!$C:$C,$A84)} -> 6 | D84: {=INDEX(Data_DBD!$D:$D,$A84)} -> 18 | E84: {=INDEX(Data_DBD!$E:$E,$A84)} -> 0 | F84: {=INDEX(Data_DBD!$F:$F,$A84)} -> Sedang | H84: 93 | I84: 65 | J84: 4 | K84: 18 | L84: 0 | M84: Sedang
A85: =RANDBETWEEN(2,164) -> 48 | B85: {=INDEX(Data_DBD!$B:$B,$A85)} -> 50 | C85: {=INDEX(Data_DBD!$C:$C,$A85)} -> 5 | D85: {=INDEX(Data_DBD!$D:$D,$A85)} -> 13 | E85: {=INDEX(Data_DBD!$E:$E,$A85)} -> 1 | F85: {=INDEX(Data_DBD!$F:$F,$A85)} -> Sedang | H85: 16 | I85: 66 | J85: 5 | K85: 7 | L85: 1 | M85: Rendah
A86: =RANDBETWEEN(2,164) -> 16 | B86: {=INDEX(Data_DBD!$B:$B,$A86)} -> 66 | C86: {=INDEX(Data_DBD!$C:$C,$A86)} -> 5 | D86: {=INDEX(Data_DBD!$D:$D,$A86)} -> 7 | E86: {=INDEX(Data_DBD!$E:$E,$A86)} -> 1 | F86: {=INDEX(Data_DBD!$F:$F,$A86)} -> Rendah | H86: 146 | I86: 34 | J86: 2 | K86: 21 | L86: 1 | M86: Tinggi
... A164: =RANDBETWEEN(2,164) -> 55 | B164: {=INDEX(Data_DBD!$B:$B,$A164)} -> 7 | C164: {=INDEX(Data_DBD!$C:$C,$A164)} -> 4 | D164: {=INDEX(Data_DBD!$D:$D,$A164)} -> 15 | E164: {=INDEX(Data_DBD!$E:$E,$A164)} -> 1 | F164: {=INDEX(Data_DBD!$F:$F,$A164)} -> Sedang | H164: 69 | I164: 24 | J164: 4 | K164: 10 | L164: 1 | M164: Rendah
...

Sheet Pohon 2
A1: No | B1: Usia | C1: Lama Rawat Inap | D1: Jenis Kelamin | E1: Tingkat Resiko | H1: No | I1: Usia | J1: Lama Rawat Inap | K1: Jenis Kelamin | L1: Tingkat Resiko | O1: Perhitungan root
A2: =RANDBETWEEN(2,164) -> 160 | B2: {=INDEX(Data_DBD!$B:$B,$A2)} -> 16 | C2: {=INDEX(Data_DBD!$C:$C,$A2)} -> 3 | D2: {=INDEX(Data_DBD!$E:$E,$A2)} -> 0 | E2: {=INDEX(Data_DBD!$F:$F,$A2)} -> Tinggi | H2: 95 | I2: 11 | J2: 3 | K2: 1 | L2: Tinggi | O2: Tinggi | P2: =COUNTIF(L2:L164,"Tinggi") -> 65 | Q2: =P2/163 -> 0.39877301
A3: =RANDBETWEEN(2,164) -> 119 | B3: {=INDEX(Data_DBD!$B:$B,$A3)} -> 30 | C3: {=INDEX(Data_DBD!$C:$C,$A3)} -> 7 | D3: {=INDEX(Data_DBD!$E:$E,$A3)} -> 0 | E3: {=INDEX(Data_DBD!$F:$F,$A3)} -> Tinggi | H3: 12 | I3: 23 | J3: 3 | K3: 0 | L3: Sedang | O3: Sedang | P3: =COUNTIF(L2:L164,"Sedang") -> 83 | Q3: =P3/163 -> 0.50920245
A4: =RANDBETWEEN(2,164) -> 144 | B4: {=INDEX(Data_DBD!$B:$B,$A4)} -> 61 | C4: {=INDEX(Data_DBD!$C:$C,$A4)} -> 4 | D4: {=INDEX(Data_DBD!$E:$E,$A4)} -> 1 | E4: {=INDEX(Data_DBD!$F:$F,$A4)} -> Tinggi | H4: 30 | I4: 3 | J4: 2 | K4: 1 | L4: Sedang | O4: Rendah | P4: =COUNTIF(L2:L164,"Rendah") -> 15 | Q4: =P4/163 -> 0.09202454
A5: =RANDBETWEEN(2,164) -> 57 | B5: {=INDEX(Data_DBD!$B:$B,$A5)} -> 2 | C5: {=INDEX(Data_DBD!$C:$C,$A5)} -> 2 | D5: {=INDEX(Data_DBD!$E:$E,$A5)} -> 1 | E5: {=INDEX(Data_DBD!$F:$F,$A5)} -> Sedang | H5: 76 | I5: 70 | J5: 2 | K5: 0 | L5: Sedang | O5: Entropy Root | P5: =-(IFERROR(Q2*LOG(Q2,2),0)+IFERROR(Q3*LOG(Q3,2),0)+IFERROR(Q4*LOG(Q4,2),0)) -> 1.3414549
A6: =RANDBETWEEN(2,164) -> 114 | B6: {=INDEX(Data_DBD!$B:$B,$A6)} -> 14 | C6: {=INDEX(Data_DBD!$C:$C,$A6)} -> 2 | D6: {=INDEX(Data_DBD!$E:$E,$A6)} -> 1 | E6: {=INDEX(Data_DBD!$F:$F,$A6)} -> Tinggi | H6: 85 | I6: 27 | J6: 9 | K6: 0 | L6: Sedang
A7: =RANDBETWEEN(2,164) -> 137 | B7: {=INDEX(Data_DBD!$B:$B,$A7)} -> 3 | C7: {=INDEX(Data_DBD!$C:$C,$A7)} -> 1 | D7: {=INDEX(Data_DBD!$E:$E,$A7)} -> 1 | E7: {=INDEX(Data_DBD!$F:$F,$A7)} -> Tinggi | H7: 55 | I7: 7 | J7: 4 | K7: 1 | L7: Sedang
A8: =RANDBETWEEN(2,164) -> 55 | B8: {=INDEX(Data_DBD!$B:$B,$A8)} -> 7 | C8: {=INDEX(Data_DBD!$C:$C,$A8)} -> 4 | D8: {=INDEX(Data_DBD!$E:$E,$A8)} -> 1 | E8: {=INDEX(Data_DBD!$F:$F,$A8)} -> Sedang | H8: 51 | I8: 48 | J8: 4 | K8: 0 | L8: Sedang
A9: =RANDBETWEEN(2,164) -> 115 | B9: {=INDEX(Data_DBD!$B:$B,$A9)} -> 52 | C9: {=INDEX(Data_DBD!$C:$C,$A9)} -> 3 | D9: {=INDEX(Data_DBD!$E:$E,$A9)} -> 1 | E9: {=INDEX(Data_DBD!$F:$F,$A9)} -> Tinggi | H9: 108 | I9: 69 | J9: 7 | K9: 1 | L9: Tinggi
A10: =RANDBETWEEN(2,164) -> 58 | B10: {=INDEX(Data_DBD!$B:$B,$A10)} -> 17 | C10: {=INDEX(Data_DBD!$C:$C,$A10)} -> 3 | D10: {=INDEX(Data_DBD!$E:$E,$A10)} -> 0 | E10: {=INDEX(Data_DBD!$F:$F,$A10)} -> Sedang | H10: 72 | I10: 3 | J10: 5 | K10: 1 | L10: Sedang
A11: =RANDBETWEEN(2,164) -> 68 | B11: {=INDEX(Data_DBD!$B:$B,$A11)} -> 44 | C11: {=INDEX(Data_DBD!$C:$C,$A11)} -> 5 | D11: {=INDEX(Data_DBD!$E:$E,$A11)} -> 0 | E11: {=INDEX(Data_DBD!$F:$F,$A11)} -> Rendah | H11: 147 | I11: 66 | J11: 10 | K11: 1 | L11: Tinggi
A12: =RANDBETWEEN(2,164) -> 149 | B12: {=INDEX(Data_DBD!$B:$B,$A12)} -> 19 | C12: {=INDEX(Data_DBD!$C:$C,$A12)} -> 5 | D12: {=INDEX(Data_DBD!$E:$E,$A12)} -> 0 | E12: {=INDEX(Data_DBD!$F:$F,$A12)} -> Tinggi | H12: 69 | I12: 24 | J12: 4 | K12: 1 | L12: Sedang
A13: =RANDBETWEEN(2,164) -> 148 | B13: {=INDEX(Data_DBD!$B:$B,$A13)} -> 55 | C13: {=INDEX(Data_DBD!$C:$C,$A13)} -> 3 | D13: {=INDEX(Data_DBD!$E:$E,$A13)} -> 1 | E13: {=INDEX(Data_DBD!$F:$F,$A13)} -> Tinggi | H13: 4 | I13: 23 | J13: 5 | K13: 0 | L13: Sedang
A14: =RANDBETWEEN(2,164) -> 150 | B14: {=INDEX(Data_DBD!$B:$B,$A14)} -> 61 | C14: {=INDEX(Data_DBD!$C:$C,$A14)} -> 5 | D14: {=INDEX(Data_DBD!$E:$E,$A14)} -> 1 | E14: {=INDEX(Data_DBD!$F:$F,$A14)} -> Tinggi | H14: 6 | I14: 14 | J14: 4 | K14: 0 | L14: Sedang
A15: =RANDBETWEEN(2,164) -> 51 | B15: {=INDEX(Data_DBD!$B:$B,$A15)} -> 48 | C15: {=INDEX(Data_DBD!$C:$C,$A15)} -> 4 | D15: {=INDEX(Data_DBD!$E:$E,$A15)} -> 0 | E15: {=INDEX(Data_DBD!$F:$F,$A15)} -> Sedang | H15: 13 | I15: 47 | J15: 2 | K15: 0 | L15: Sedang
A16: =RANDBETWEEN(2,164) -> 88 | B16: {=INDEX(Data_DBD!$B:$B,$A16)} -> 20 | C16: {=INDEX(Data_DBD!$C:$C,$A16)} -> 4 | D16: {=INDEX(Data_DBD!$E:$E,$A16)} -> 1 | E16: {=INDEX(Data_DBD!$F:$F,$A16)} -> Sedang | H16: 142 | I16: 39 | J16: 2 | K16: 1 | L16: Tinggi
A17: =RANDBETWEEN(2,164) -> 16 | B17: {=INDEX(Data_DBD!$B:$B,$A17)} -> 66 | C17: {=INDEX(Data_DBD!$C:$C,$A17)} -> 5 | D17: {=INDEX(Data_DBD!$E:$E,$A17)} -> 1 | E17: {=INDEX(Data_DBD!$F:$F,$A17)} -> Rendah | H17: 159 | I17: 17 | J17: 2 | K17: 0 | L17: Tinggi
... A153: =RANDBETWEEN(2,164) -> 147 | B153: {=INDEX(Data_DBD!$B:$B,$A153)} -> 66 | C153: {=INDEX(Data_DBD!$C:$C,$A153)} -> 10 | D153: {=INDEX(Data_DBD!$E:$E,$A153)} -> 1 | E153: {=INDEX(Data_DBD!$F:$F,$A153)} -> Tinggi | H153: 35 | I153: 40 | J153: 3 | K153: 1 | L153: Rendah
A154: =RANDBETWEEN(2,164) -> 118 | B154: {=INDEX(Data_DBD!$B:$B,$A154)} -> 67 | C154: {=INDEX(Data_DBD!$C:$C,$A154)} -> 4 | D154: {=INDEX(Data_DBD!$E:$E,$A154)} -> 1 | E154: {=INDEX(Data_DBD!$F:$F,$A154)} -> Tinggi | H154: 161 | I154: 12 | J154: 3 | K154: 1 | L154: Tinggi | V154: Pohon 2:
A155: =RANDBETWEEN(2,164) -> 117 | B155: {=INDEX(Data_DBD!$B:$B,$A155)} -> 49 | C155: {=INDEX(Data_DBD!$C:$C,$A155)} -> 4 | D155: {=INDEX(Data_DBD!$E:$E,$A155)} -> 1 | E155: {=INDEX(Data_DBD!$F:$F,$A155)} -> Tinggi | H155: 31 | I155: 64 | J155: 4 | K155: 1 | L155: Sedang | V155: Rule 1.1
A156: =RANDBETWEEN(2,164) -> 136 | B156: {=INDEX(Data_DBD!$B:$B,$A156)} -> 6 | C156: {=INDEX(Data_DBD!$C:$C,$A156)} -> 2 | D156: {=INDEX(Data_DBD!$E:$E,$A156)} -> 0 | E156: {=INDEX(Data_DBD!$F:$F,$A156)} -> Tinggi | H156: 144 | I156: 61 | J156: 4 | K156: 1 | L156: Tinggi | V156: IF Usia < 16,61
A157: =RANDBETWEEN(2,164) -> 154 | B157: {=INDEX(Data_DBD!$B:$B,$A157)} -> 18 | C157: {=INDEX(Data_DBD!$C:$C,$A157)} -> 5 | D157: {=INDEX(Data_DBD!$E:$E,$A157)} -> 1 | E157: {=INDEX(Data_DBD!$F:$F,$A157)} -> Tinggi | H157: 77 | I157: 16 | J157: 4 | K157: 1 | L157: Sedang | V157: THEN Kategori Usia = Anak-anak
A158: =RANDBETWEEN(2,164) -> 104 | B158: {=INDEX(Data_DBD!$B:$B,$A158)} -> 37 | C158: {=INDEX(Data_DBD!$C:$C,$A158)} -> 4 | D158: {=INDEX(Data_DBD!$E:$E,$A158)} -> 1 | E158: {=INDEX(Data_DBD!$F:$F,$A158)} -> Sedang | H158: 79 | I158: 29 | J158: 3 | K158: 0 | L158: Sedang | V158: Rule 1.2
A159: =RANDBETWEEN(2,164) -> 22 | B159: {=INDEX(Data_DBD!$B:$B,$A159)} -> 6 | C159: {=INDEX(Data_DBD!$C:$C,$A159)} -> 3 | D159: {=INDEX(Data_DBD!$E:$E,$A159)} -> 0 | E159: {=INDEX(Data_DBD!$F:$F,$A159)} -> Sedang | H159: 103 | I159: 22 | J159: 5 | K159: 0 | L159: Tinggi | V159: IF Usia ≤ 16,61 AND Usia > 54,4
A160: =RANDBETWEEN(2,164) -> 111 | B160: {=INDEX(Data_DBD!$B:$B,$A160)} -> 25 | C160: {=INDEX(Data_DBD!$C:$C,$A160)} -> 4 | D160: {=INDEX(Data_DBD!$E:$E,$A160)} -> 0 | E160: {=INDEX(Data_DBD!$F:$F,$A160)} -> Tinggi | H160: 94 | I160: 12 | J160: 4 | K160: 0 | L160: Tinggi | V160: THEN Kategori Usia = Anak-anak
A161: =RANDBETWEEN(2,164) -> 84 | B161: {=INDEX(Data_DBD!$B:$B,$A161)} -> 42 | C161: {=INDEX(Data_DBD!$C:$C,$A161)} -> 4 | D161: {=INDEX(Data_DBD!$E:$E,$A161)} -> 1 | E161: {=INDEX(Data_DBD!$F:$F,$A161)} -> Sedang | H161: 81 | I161: 23 | J161: 5 | K161: 1 | L161: Sedang | V161: Rule 1.3
A162: =RANDBETWEEN(2,164) -> 155 | B162: {=INDEX(Data_DBD!$B:$B,$A162)} -> 19 | C162: {=INDEX(Data_DBD!$C:$C,$A162)} -> 5 | D162: {=INDEX(Data_DBD!$E:$E,$A162)} -> 1 | E162: {=INDEX(Data_DBD!$F:$F,$A162)} -> Tinggi | H162: 17 | I162: 2 | J162: 3 | K162: 0 | L162: Rendah | V162: IF Usia > 54,4 THEN Kategori Usia = Anak-anak
A163: =RANDBETWEEN(2,164) -> 51 | B163: {=INDEX(Data_DBD!$B:$B,$A163)} -> 48 | C163: {=INDEX(Data_DBD!$C:$C,$A163)} -> 4 | D163: {=INDEX(Data_DBD!$E:$E,$A163)} -> 0 | E163: {=INDEX(Data_DBD!$F:$F,$A163)} -> Sedang | H163: 2 | I163: 34 | J163: 3 | K163: 0 | L163: Sedang
A164: =RANDBETWEEN(2,164) -> 117 | B164: {=INDEX(Data_DBD!$B:$B,$A164)} -> 49 | C164: {=INDEX(Data_DBD!$C:$C,$A164)} -> 4 | D164: {=INDEX(Data_DBD!$E:$E,$A164)} -> 1 | E164: {=INDEX(Data_DBD!$F:$F,$A164)} -> Tinggi | H164: 138 | I164: 13 | J164: 3 | K164: 1 | L164: Tinggi
I165: =AVERAGE(I2:I164) -> 31.484663 | J165: =AVERAGE(J2:J164) -> 3.595092 | K165: =AVERAGE(K2:K164) -> 0.52147239
B167: 2
E168: USIA | J168: LAMA RAWAT INAP | T168: JENIS KELAMIN
E169: Usia | F169: =AVERAGEIF($I$2:$I$164,"<="&$I$165) -> 16.616162 | G169: =AVERAGEIF($I$2:$I$164,">"&$I$165) -> 54.484375 | J169: Lama rawat inap | K169: =AVERAGEIF($J$2:$J$164,"<="&$J$165) -> 2.6136364 | L169: =AVERAGEIF($J$2:$J$164,">"&$J$165) -> 4.7466667 | T169: Jenis kelamin | U169: =AVERAGEIF($K$2:$K$164,"<="&$K$165) -> 0 | V169: =AVERAGEIF($K$2:$K$164,">"&$K$165) -> 1
E170: {=IF($I$2:$I$164<$F$169,"kiri",IF($I$2:$I$164<$G$169,"tengah","kanan"))} -> kiri | F170: Kanan > 54.4 | J170: {=IF($J$2:$J$164<$K$169,"kiri",IF($J$2:$J$164<$L$169,"tengah","kanan"))} -> tengah | K170: Kanan > 4.74 | T170: {=IF($K$2:$K$164<$U$169,"kiri",IF($K$2:$K$164<$V$169,"tengah","kanan"))} -> kanan | U170: Kanan > 1
E171: tengah | F171: =COUNTIFS($E$170:$E$332,"Kanan",$L$2:$L$164,"Tinggi") -> 14 | G171: =F171/30 -> 0.46666667 | J171: tengah | K171: =COUNTIFS($J$170:$J$332,"Kanan",$L$2:$L$164,"Tinggi") -> 12 | L171: =K171/27 -> 0.44444444 | T171: tengah | U171: =COUNTIFS($T$170:$T$332,"Kanan",$L$2:$L$164,"Tinggi") -> 40 | V171: =U171/85 -> 0.47058824
E172: kiri | F172: =COUNTIFS($E$170:$E$332,"Kanan",$L$2:$L$164,"Sedang") -> 16 | G172: =F172/30 -> 0.53333333 | J172: kiri | K172: =COUNTIFS($J$170:$J$332,"Kanan",$L$2:$L$164,"Sedang") -> 14 | L172: =K172/27 -> 0.51851852 | T172: kanan | U172: =COUNTIFS($T$170:$T$332,"Kanan",$L$2:$L$164,"Sedang") -> 36 | V172: =U172/85 -> 0.42352941
E173: kanan | F173: =COUNTIFS($E$170:$E$332,"Kanan",$L$2:$L$164,"Rendah") -> 0 | G173: =F173/30 -> 0 | J173: kiri | K173: =COUNTIFS($J$170:$J$332,"Kanan",$L$2:$L$164,"Rendah") -> 1 | L173: =K173/27 -> 0.037037037 | T173: tengah | U173: =COUNTIFS($T$170:$T$332,"Kanan",$L$2:$L$164,"Rendah") -> 9 | V173: =U173/85 -> 0.10588235
E174: tengah | F174: Entropy | G174: =-(IFERROR(G171*LOG(G171,2),0)+IFERROR(G172*LOG(G172,2),0)+IFERROR(G173*LOG(G173,2),0)) -> 0.99679163 | J174: kanan | K174: Entropy | L174: =-(IFERROR(L171*LOG(L171,2),0)+IFERROR(L172*LOG(L172,2),0)+IFERROR(L173*LOG(L173,2),0)) -> 1.1873868 | T174: tengah | U174: Entropy | V174: =-(IFERROR(V171*LOG(V171,2),0)+IFERROR(V172*LOG(V172,2),0)+IFERROR(V173*LOG(V173,2),0)) -> 1.3796998
E175: kiri | G175: =SUM(F171:F173)/163 -> 0.18404908 | J175: tengah | L175: =SUM(K171:K173)/163 -> 0.16564417 | T175: kanan | V175: =SUM(U171:U173)/163 -> 0.52147239
E176: tengah | G176: =G174*G175 -> 0.18345858 | J176: tengah | L176: =L174*L175 -> 0.1966837 | T176: tengah | V176: =V174*V175 -> 0.71947534
...

Sheet Pohon 3
A1: No | B1: Lama Rawat Inap | C1: Jenis Kelamin | D1: Tingkat Resiko | H1: No | I1: Lama Rawat Inap | J1: Jenis Kelamin | K1: Tingkat Resiko | O1: Perhitungan root
A2: =RANDBETWEEN(2,164) -> 53 | B2: {=INDEX(Data_DBD!$C:$C,$A2)} -> 4 | C2: {=INDEX(Data_DBD!$E:$E,$A2)} -> 1 | D2: {=INDEX(Data_DBD!$F:$F,$A2)} -> Sedang | H2: 98 | I2: 2 | J2: 1 | K2: Tinggi | O2: Tinggi | P2: =COUNTIF(K2:K164,"Tinggi") -> 70 | Q2: =P2/163 -> 0.42944785
A3: =RANDBETWEEN(2,164) -> 108 | B3: {=INDEX(Data_DBD!$C:$C,$A3)} -> 7 | C3: {=INDEX(Data_DBD!$E:$E,$A3)} -> 1 | D3: {=INDEX(Data_DBD!$F:$F,$A3)} -> Tinggi | H3: 126 | I3: 3 | J3: 1 | K3: Tinggi | O3: Sedang | P3: =COUNTIF(K2:K164,"Sedang") -> 81 | Q3: =P3/163 -> 0.49693252
A4: =RANDBETWEEN(2,164) -> 55 | B4: {=INDEX(Data_DBD!$C:$C,$A4)} -> 4 | C4: {=INDEX(Data_DBD!$E:$E,$A4)} -> 1 | D4: {=INDEX(Data_DBD!$F:$F,$A4)} -> Sedang | H4: 49 | I4: 5 | J4: 0 | K4: Sedang | O4: Rendah | P4: =COUNTIF(K2:K164,"Rendah") -> 12 | Q4: =P4/163 -> 0.073619632
A5: =RANDBETWEEN(2,164) -> 95 | B5: {=INDEX(Data_DBD!$C:$C,$A5)} -> 3 | C5: {=INDEX(Data_DBD!$E:$E,$A5)} -> 1 | D5: {=INDEX(Data_DBD!$F:$F,$A5)} -> Sedang | H5: 14 | I5: 4 | J5: 1 | K5: Rendah | O5: Entropy Root | P5: =-(IFERROR(Q2*LOG(Q2,2),0)+IFERROR(Q3*LOG(Q3,2),0)+IFERROR(Q4*LOG(Q4,2),0)) -> 1.3021195
A6: =RANDBETWEEN(2,164) -> 70 | B6: {=INDEX(Data_DBD!$C:$C,$A6)} -> 3 | C6: {=INDEX(Data_DBD!$E:$E,$A6)} -> 1 | D6: {=INDEX(Data_DBD!$F:$F,$A6)} -> Rendah | H6: 54 | I6: 3 | J6: 0 | K6: Sedang
A7: =RANDBETWEEN(2,164) -> 38 | B7: {=INDEX(Data_DBD!$C:$C,$A7)} -> 3 | C7: {=INDEX(Data_DBD!$E:$E,$A7)} -> 1 | D7: {=INDEX(Data_DBD!$F:$F,$A7)} -> Rendah | H7: 80 | I7: 3 | J7: 1 | K7: Sedang
A8: =RANDBETWEEN(2,164) -> 127 | B8: {=INDEX(Data_DBD!$C:$C,$A8)} -> 2 | C8: {=INDEX(Data_DBD!$E:$E,$A8)} -> 0 | D8: {=INDEX(Data_DBD!$F:$F,$A8)} -> Tinggi | H8: 36 | I8: 1 | J8: 1 | K8: Rendah
A9: =RANDBETWEEN(2,164) -> 143 | B9: {=INDEX(Data_DBD!$C:$C,$A9)} -> 4 | C9: {=INDEX(Data_DBD!$E:$E,$A9)} -> 1 | D9: {=INDEX(Data_DBD!$F:$F,$A9)} -> Tinggi | H9: 105 | I9: 3 | J9: 1 | K9: Tinggi
A10: =RANDBETWEEN(2,164) -> 141 | B10: {=INDEX(Data_DBD!$C:$C,$A10)} -> 2 | C10: {=INDEX(Data_DBD!$E:$E,$A10)} -> 0 | D10: {=INDEX(Data_DBD!$F:$F,$A10)} -> Tinggi | H10: 26 | I10: 4 | J10: 1 | K10: Sedang
A11: =RANDBETWEEN(2,164) -> 108 | B11: {=INDEX(Data_DBD!$C:$C,$A11)} -> 7 | C11: {=INDEX(Data_DBD!$E:$E,$A11)} -> 1 | D11: {=INDEX(Data_DBD!$F:$F,$A11)} -> Tinggi | H11: 63 | I11: 3 | J11: 0 | K11: Sedang
A12: =RANDBETWEEN(2,164) -> 17 | B12: {=INDEX(Data_DBD!$C:$C,$A12)} -> 3 | C12: {=INDEX(Data_DBD!$E:$E,$A12)} -> 0 | D12: {=INDEX(Data_DBD!$F:$F,$A12)} -> Rendah | H12: 107 | I12: 5 | J12: 0 | K12: Tinggi
A13: =RANDBETWEEN(2,164) -> 126 | B13: {=INDEX(Data_DBD!$C:$C,$A13)} -> 3 | C13: {=INDEX(Data_DBD!$E:$E,$A13)} -> 1 | D13: {=INDEX(Data_DBD!$F:$F,$A13)} -> Tinggi | H13: 50 | I13: 5 | J13: 0 | K13: Sedang
A14: =RANDBETWEEN(2,164) -> 106 | B14: {=INDEX(Data_DBD!$C:$C,$A14)} -> 3 | C14: {=INDEX(Data_DBD!$E:$E,$A14)} -> 1 | D14: {=INDEX(Data_DBD!$F:$F,$A14)} -> Sedang | H14: 99 | I14: 2 | J14: 1 | K14: Tinggi
A15: =RANDBETWEEN(2,164) -> 130 | B15: {=INDEX(Data_DBD!$C:$C,$A15)} -> 4 | C15: {=INDEX(Data_DBD!$E:$E,$A15)} -> 0 | D15: {=INDEX(Data_DBD!$F:$F,$A15)} -> Tinggi | H15: 149 | I15: 5 | J15: 0 | K15: Tinggi
A16: =RANDBETWEEN(2,164) -> 43 | B16: {=INDEX(Data_DBD!$C:$C,$A16)} -> 4 | C16: {=INDEX(Data_DBD!$E:$E,$A16)} -> 0 | D16: {=INDEX(Data_DBD!$F:$F,$A16)} -> Sedang | H16: 72 | I16: 5 | J16: 1 | K16: Sedang
A17: =RANDBETWEEN(2,164) -> 139 | B17: {=INDEX(Data_DBD!$C:$C,$A17)} -> 7 | C17: {=INDEX(Data_DBD!$E:$E,$A17)} -> 0 | D17: {=INDEX(Data_DBD!$F:$F,$A17)} -> Tinggi | H17: 109 | I17: 3 | J17: 1 | K17: Tinggi
... A153: =RANDBETWEEN(2,164) -> 121 | B153: {=INDEX(Data_DBD!$C:$C,$A153)} -> 5 | C153: {=INDEX(Data_DBD!$E:$E,$A153)} -> 1 | D153: {=INDEX(Data_DBD!$F:$F,$A153)} -> Tinggi | H153: 76 | I153: 2 | J153: 0 | K153: Sedang
A154: =RANDBETWEEN(2,164) -> 75 | B154: {=INDEX(Data_DBD!$C:$C,$A154)} -> 2 | C154: {=INDEX(Data_DBD!$E:$E,$A154)} -> 1 | D154: {=INDEX(Data_DBD!$F:$F,$A154)} -> Rendah | H154: 91 | I154: 1 | J154: 1 | K154: Tinggi | U154: Pohon 3:
A155: =RANDBETWEEN(2,164) -> 29 | B155: {=INDEX(Data_DBD!$C:$C,$A155)} -> 2 | C155: {=INDEX(Data_DBD!$E:$E,$A155)} -> 1 | D155: {=INDEX(Data_DBD!$F:$F,$A155)} -> Sedang | H155: 150 | I155: 5 | J155: 1 | K155: Tinggi | U155: Rule 1.1
A156: =RANDBETWEEN(2,164) -> 54 | B156: {=INDEX(Data_DBD!$C:$C,$A156)} -> 3 | C156: {=INDEX(Data_DBD!$E:$E,$A156)} -> 0 | D156: {=INDEX(Data_DBD!$F:$F,$A156)} -> Sedang | H156: 74 | I156: 4 | J156: 0 | K156: Sedang | U156: IF Lama Rawat Inap < 2,44
A157: =RANDBETWEEN(2,164) -> 114 | B157: {=INDEX(Data_DBD!$C:$C,$A157)} -> 2 | C157: {=INDEX(Data_DBD!$E:$E,$A157)} -> 1 | D157: {=INDEX(Data_DBD!$F:$F,$A157)} -> Tinggi | H157: 41 | I157: 4 | J157: 0 | K157: Sedang | U157: THEN Kelas = Sedang
A158: =RANDBETWEEN(2,164) -> 141 | B158: {=INDEX(Data_DBD!$C:$C,$A158)} -> 2 | C158: {=INDEX(Data_DBD!$E:$E,$A158)} -> 0 | D158: {=INDEX(Data_DBD!$F:$F,$A158)} -> Tinggi | H158: 142 | I158: 2 | J158: 1 | K158: Tinggi | U158: Rule 1.2
A159: =RANDBETWEEN(2,164) -> 87 | B159: {=INDEX(Data_DBD!$C:$C,$A159)} -> 3 | C159: {=INDEX(Data_DBD!$E:$E,$A159)} -> 0 | D159: {=INDEX(Data_DBD!$F:$F,$A159)} -> Sedang | H159: 155 | I159: 5 | J159: 1 | K159: Tinggi | U159: IF Lama Rawat Inap ≤ 2,44 AND Lama Rawat Inap > 4,68
A160: =RANDBETWEEN(2,164) -> 44 | B160: {=INDEX(Data_DBD!$C:$C,$A160)} -> 5 | C160: {=INDEX(Data_DBD!$E:$E,$A160)} -> 1 | D160: {=INDEX(Data_DBD!$F:$F,$A160)} -> Sedang | H160: 98 | I160: 2 | J160: 1 | K160: Tinggi | U160: THEN Kelas = Lama
A161: =RANDBETWEEN(2,164) -> 161 | B161: {=INDEX(Data_DBD!$C:$C,$A161)} -> 3 | C161: {=INDEX(Data_DBD!$E:$E,$A161)} -> 1 | D161: {=INDEX(Data_DBD!$F:$F,$A161)} -> Tinggi | H161: 28 | I161: 2 | J161: 1 | K161: Sedang | U161: Rule 1.3
A162: =RANDBETWEEN(2,164) -> 38 | B162: {=INDEX(Data_DBD!$C:$C,$A162)} -> 3 | C162: {=INDEX(Data_DBD!$E:$E,$A162)} -> 1 | D162: {=INDEX(Data_DBD!$F:$F,$A162)} -> Rendah | H162: 87 | I162: 3 | J162: 0 | K162: Sedang | U162: IF Lama Rawat Inap > 4,68 THEN Kelas = Sedang
A163: =RANDBETWEEN(2,164) -> 148 | B163: {=INDEX(Data_DBD!$C:$C,$A163)} -> 3 | C163: {=INDEX(Data_DBD!$E:$E,$A163)} -> 1 | D163: {=INDEX(Data_DBD!$F:$F,$A163)} -> Tinggi | H163: 120 | I163: 4 | J163: 1 | K163: Tinggi
A164: =RANDBETWEEN(2,164) -> 28 | B164: {=INDEX(Data_DBD!$C:$C,$A164)} -> 2 | C164: {=INDEX(Data_DBD!$E:$E,$A164)} -> 1 | D164: {=INDEX(Data_DBD!$F:$F,$A164)} -> Sedang | H164: 137 | I164: 1 | J164: 1 | K164: Tinggi
I165: =AVERAGE(I2:I164) -> 3.5460123 | J165: =AVERAGE(J2:J164) -> 0.56441718
B167: 6
I168: LAMA RAWAT INAP | N168: JENIS KELAMIN
I169: Lama rawat inap | J169: =AVERAGEIF($I$2:$I$164,"<="&$I$165) -> 2.4457831 | K169: =AVERAGEIF($I$2:$I$164,">"&$I$165) -> 4.6875 | N169: Jenis kelamin | O169: =AVERAGEIF($J$2:$J$164,"<="&$J$165) -> 0 | P169: =AVERAGEIF($J$2:$J$164,">"&$J$165) -> 1
I170: {=IF($I$2:$I$164<$J$169,"kiri",IF($I$2:$I$164<$K$169,"tengah","kanan"))} -> kiri | J170: Kanan > 4.68 | N170: {=IF($J$2:$J$164<$O$169,"kiri",IF($J$2:$J$164<$P$169,"tengah","kanan"))} -> kanan | O170: Kanan > 1
I171: tengah | J171: =COUNTIFS($I$170:$I$332,"Kanan",$K$2:$K$164,"Tinggi") -> 19 | K171: =J171/40 -> 0.475 | N171: kanan | O171: =COUNTIFS($N$170:$N$332,"Kanan",$K$2:$K$164,"Tinggi") -> 45 | P171: =O171/92 -> 0.48913043
I172: kanan | J172: =COUNTIFS($I$170:$I$332,"Kanan",$K$2:$K$164,"Sedang") -> 18 | K172: =J172/40 -> 0.45 | N172: tengah | O172: =COUNTIFS($N$170:$N$332,"Kanan",$K$2:$K$164,"Sedang") -> 40 | P172: =O172/92 -> 0.43478261
I173: tengah | J173: =COUNTIFS($I$170:$I$332,"Kanan",$K$2:$K$164,"Rendah") -> 3 | K173: =J173/40 -> 0.075 | N173: kanan | O173: =COUNTIFS($N$170:$N$332,"Kanan",$K$2:$K$164,"Rendah") -> 7 | P173: =O173/92 -> 0.076086957
I174: tengah | J174: Entropy | K174: =-(IFERROR(K171*LOG(K171,2),0)+IFERROR(K172*LOG(K172,2),0)+IFERROR(K173*LOG(K173,2),0)) -> 1.3088241 | N174: tengah | O174: Entropy | P174: =-(IFERROR(P171*LOG(P171,2),0)+IFERROR(P172*LOG(P172,2),0)+IFERROR(P173*LOG(P173,2),0)) -> 1.3098446
I175: tengah | K175: =SUM(J171:J173)/163 -> 0.24539877 | N175: kanan | P175: =SUM(O171:O173)/163 -> 0.56441718
I176: kiri | K176: =K174*K175 -> 0.32118383 | N176: kanan | P176: =P174*P175 -> 0.73929879
...

Sheet Pohon 4
A1: No | B1: Jenis Kelamin | C1: Tingkat Resiko | H1: No | I1: Jenis Kelamin | J1: Tingkat Resiko | O1: Perhitungan root
A2: =RANDBETWEEN(2,164) -> 154 | B2: {=INDEX(Data_DBD!$E:$E,$A2)} -> 1 | C2: {=INDEX(Data_DBD!$F:$F,$A2)} -> Tinggi | H2: 150 | I2: 1 | J2: Tinggi | O2: Tinggi | P2: =COUNTIF(J2:J164,"Tinggi") -> 83 | Q2: =P2/163 -> 0.50920245
A3: =RANDBETWEEN(2,164) -> 86 | B3: {=INDEX(Data_DBD!$E:$E,$A3)} -> 0 | C3: {=INDEX(Data_DBD!$F:$F,$A3)} -> Sedang | H3: 88 | I3: 1 | J3: Sedang | O3: Sedang | P3: =COUNTIF(J2:J164,"Sedang") -> 69 | Q3: =P3/163 -> 0.42331288
A4: =RANDBETWEEN(2,164) -> 14 | B4: {=INDEX(Data_DBD!$E:$E,$A4)} -> 1 | C4: {=INDEX(Data_DBD!$F:$F,$A4)} -> Rendah | H4: 120 | I4: 1 | J4: Tinggi | O4: Rendah | P4: =COUNTIF(J2:J164,"Rendah") -> 11 | Q4: =P4/163 -> 0.067484663
A5: =RANDBETWEEN(2,164) -> 77 | B5: {=INDEX(Data_DBD!$E:$E,$A5)} -> 1 | C5: {=INDEX(Data_DBD!$F:$F,$A5)} -> Sedang | H5: 62 | I5: 1 | J5: Sedang | O5: Entropy Root | P5: =-(IFERROR(Q2*LOG(Q2,2),0)+IFERROR(Q3*LOG(Q3,2),0)+IFERROR(Q4*LOG(Q4,2),0)) -> 1.2832668
A6: =RANDBETWEEN(2,164) -> 92 | B6: {=INDEX(Data_DBD!$E:$E,$A6)} -> 0 | C6: {=INDEX(Data_DBD!$F:$F,$A6)} -> Sedang | H6: 153 | I6: 1 | J6: Tinggi
A7: =RANDBETWEEN(2,164) -> 31 | B7: {=INDEX(Data_DBD!$E:$E,$A7)} -> 1 | C7: {=INDEX(Data_DBD!$F:$F,$A7)} -> Sedang | H7: 6 | I7: 0 | J7: Sedang
A8: =RANDBETWEEN(2,164) -> 99 | B8: {=INDEX(Data_DBD!$E:$E,$A8)} -> 1 | C8: {=INDEX(Data_DBD!$F:$F,$A8)} -> Sedang | H8: 95 | I8: 1 | J8: Tinggi
A9: =RANDBETWEEN(2,164) -> 110 | B9: {=INDEX(Data_DBD!$E:$E,$A9)} -> 1 | C9: {=INDEX(Data_DBD!$F:$F,$A9)} -> Tinggi | H9: 69 | I9: 1 | J9: Sedang
A10: =RANDBETWEEN(2,164) -> 134 | B10: {=INDEX(Data_DBD!$E:$E,$A10)} -> 1 | C10: {=INDEX(Data_DBD!$F:$F,$A10)} -> Tinggi | H10: 138 | I10: 1 | J10: Tinggi
A11: =RANDBETWEEN(2,164) -> 55 | B11: {=INDEX(Data_DBD!$E:$E,$A11)} -> 1 | C11: {=INDEX(Data_DBD!$F:$F,$A11)} -> Sedang | H11: 81 | I11: 1 | J11: Sedang
A12: =RANDBETWEEN(2,164) -> 15 | B12: {=INDEX(Data_DBD!$E:$E,$A12)} -> 0 | C12: {=INDEX(Data_DBD!$F:$F,$A12)} -> Rendah | H12: 88 | I12: 1 | J12: Sedang
A13: =RANDBETWEEN(2,164) -> 98 | B13: {=INDEX(Data_DBD!$E:$E,$A13)} -> 1 | C13: {=INDEX(Data_DBD!$F:$F,$A13)} -> Sedang | H13: 56 | I13: 0 | J13: Sedang
A14: =RANDBETWEEN(2,164) -> 110 | B14: {=INDEX(Data_DBD!$E:$E,$A14)} -> 1 | C14: {=INDEX(Data_DBD!$F:$F,$A14)} -> Tinggi | H14: 58 | I14: 0 | J14: Sedang
A15: =RANDBETWEEN(2,164) -> 113 | B15: {=INDEX(Data_DBD!$E:$E,$A15)} -> 1 | C15: {=INDEX(Data_DBD!$F:$F,$A15)} -> Tinggi | H15: 138 | I15: 1 | J15: Tinggi
A16: =RANDBETWEEN(2,164) -> 68 | B16: {=INDEX(Data_DBD!$E:$E,$A16)} -> 0 | C16: {=INDEX(Data_DBD!$F:$F,$A16)} -> Rendah | H16: 25 | I16: 0 | J16: Sedang
A17: =RANDBETWEEN(2,164) -> 118 | B17: {=INDEX(Data_DBD!$E:$E,$A17)} -> 1 | C17: {=INDEX(Data_DBD!$F:$F,$A17)} -> Tinggi | H17: 9 | I17: 1 | J17: Sedang
... A157: =RANDBETWEEN(2,164) -> 8 | B157: {=INDEX(Data_DBD!$E:$E,$A157)} -> 0 | C157: {=INDEX(Data_DBD!$F:$F,$A157)} -> Sedang | H157: 10 | I157: 0 | J157: Sedang
A158: =RANDBETWEEN(2,164) -> 128 | B158: {=INDEX(Data_DBD!$E:$E,$A158)} -> 0 | C158: {=INDEX(Data_DBD!$F:$F,$A158)} -> Tinggi | H158: 98 | I158: 1 | J158: Tinggi | R158: Pohon 4:
A159: =RANDBETWEEN(2,164) -> 53 | B159: {=INDEX(Data_DBD!$E:$E,$A159)} -> 1 | C159: {=INDEX(Data_DBD!$F:$F,$A159)} -> Sedang | H159: 129 | I159: 0 | J159: Tinggi | R159: Rule 1.1
A160: =RANDBETWEEN(2,164) -> 64 | B160: {=INDEX(Data_DBD!$E:$E,$A160)} -> 0 | C160: {=INDEX(Data_DBD!$F:$F,$A160)} -> Sedang | H160: 127 | I160: 0 | J160: Tinggi | R160: IF Jenis Kelamin ≤ 0 AND Jenis Kelamin > 1
A161: =RANDBETWEEN(2,164) -> 146 | B161: {=INDEX(Data_DBD!$E:$E,$A161)} -> 1 | C161: {=INDEX(Data_DBD!$F:$F,$A161)} -> Tinggi | H161: 80 | I161: 1 | J161: Sedang | R161: THEN Kelas = Tinggi
A162: =RANDBETWEEN(2,164) -> 49 | B162: {=INDEX(Data_DBD!$E:$E,$A162)} -> 0 | C162: {=INDEX(Data_DBD!$F:$F,$A162)} -> Sedang | H162: 164 | I162: 0 | J162: Rendah | R162: Rule 1.2
A163: =RANDBETWEEN(2,164) -> 123 | B163: {=INDEX(Data_DBD!$E:$E,$A163)} -> 0 | C163: {=INDEX(Data_DBD!$F:$F,$A163)} -> Tinggi | H163: 61 | I163: 1 | J163: Sedang | R163: IF Jenis Kelamin > 1 THEN Kelas = Tinggi
A164: =RANDBETWEEN(2,164) -> 42 | B164: {=INDEX(Data_DBD!$E:$E,$A164)} -> 1 | C164: {=INDEX(Data_DBD!$F:$F,$A164)} -> Sedang | H164: 56 | I164: 0 | J164: Sedang
I165: =AVERAGE(I2:I164) -> 0.49079755
B166: 10
H168: JENIS KELAMIN
H169: Jenis kelamin | I169: =AVERAGEIF($I$2:$I$164,"<="&$I$165) -> 0 | J169: =AVERAGEIF($I$2:$I$164,">"&$I$165) -> 1
H170: {=IF($I$2:$I$164<$I$169,"kiri",IF($I$2:$I$164<$J$169,"tengah","kanan"))} -> kanan | I170: Kanan > 1
H171: kanan | I171: =COUNTIFS($H$170:$H$332,"Kanan",$J$2:$J$164,"Tinggi") -> 41 | J171: =I171/80 -> 0.5125
H172: kanan | I172: =COUNTIFS($H$170:$H$332,"Kanan",$J$2:$J$164,"Sedang") -> 33 | J172: =I172/80 -> 0.4125
H173: kanan | I173: =COUNTIFS($H$170:$H$332,"Kanan",$J$2:$J$164,"Rendah") -> 6 | J173: =I173/80 -> 0.075
H174: kanan | I174: Entropy | J174: =-(IFERROR(J171*LOG(J171,2),0)+IFERROR(J172*LOG(J172,2),0)+IFERROR(J173*LOG(J173,2),0)) -> 1.3014979
H175: tengah | J175: =SUM(I171:I173)/163 -> 0.49079755
H176: kanan | J176: =J174*J175 -> 0.63877199
H177: kanan
H178: kanan
H179: kanan | I179: Kiri<0
H180: kanan | I180: =COUNTIFS($H$170:$H$332,"Kiri",$J$2:$J$164,"Tinggi") -> 0 | J180: =I180/57 -> 0
...

Sheet Pohon 5
A1: No | B1: Usia | C1: Lama Rawat Inap | D1: Jumlah Kasus Per Bulan | E1: Jenis Kelamin | F1: Tingkat Resiko | H1: No | I1: Usia | J1: Lama Rawat Inap | K1: Jumlah Kasus Per Bulan | L1: Jenis Kelamin | M1: Tingkat Resiko | O1: Perhitungan root
A2: =RANDBETWEEN(2,164) -> 18 | B2: {=INDEX(Data_DBD!$B:$B,$A2)} -> 49 | C2: {=INDEX(Data_DBD!$C:$C,$A2)} -> 4 | D2: {=INDEX(Data_DBD!$D:$D,$A2)} -> 7 | E2: {=INDEX(Data_DBD!$E:$E,$A2)} -> 1 | F2: {=INDEX(Data_DBD!$F:$F,$A2)} -> Rendah | H2: 14 | I2: 49 | J2: 4 | K2: 7 | L2: 1 | M2: Rendah | O2: Tinggi | P2: =COUNTIF(M2:M164,"Tinggi") -> 57 | Q2: =P2/163 -> 0.34969325
A3: =RANDBETWEEN(2,164) -> 17 | B3: {=INDEX(Data_DBD!$B:$B,$A3)} -> 2 | C3: {=INDEX(Data_DBD!$C:$C,$A3)} -> 3 | D3: {=INDEX(Data_DBD!$D:$D,$A3)} -> 7 | E3: {=INDEX(Data_DBD!$E:$E,$A3)} -> 0 | F3: {=INDEX(Data_DBD!$F:$F,$A3)} -> Rendah | H3: 127 | I3: 21 | J3: 2 | K3: 33 | L3: 0 | M3: Tinggi | O3: Sedang | P3: =COUNTIF(M2:M164,"Sedang") -> 82 | Q3: =P3/163 -> 0.50306748
A4: =RANDBETWEEN(2,164) -> 159 | B4: {=INDEX(Data_DBD!$B:$B,$A4)} -> 17 | C4: {=INDEX(Data_DBD!$C:$C,$A4)} -> 2 | D4: {=INDEX(Data_DBD!$D:$D,$A4)} -> 21 | E4: {=INDEX(Data_DBD!$E:$E,$A4)} -> 0 | F4: {=INDEX(Data_DBD!$F:$F,$A4)} -> Tinggi | H4: 62 | I4: 43 | J4: 4 | K4: 15 | L4: 1 | M4: Sedang | O4: Rendah | P4: =COUNTIF(M2:M164,"Rendah") -> 24 | Q4: =P4/163 -> 0.14723926
A5: =RANDBETWEEN(2,164) -> 55 | B5: {=INDEX(Data_DBD!$B:$B,$A5)} -> 7 | C5: {=INDEX(Data_DBD!$C:$C,$A5)} -> 4 | D5: {=INDEX(Data_DBD!$D:$D,$A5)} -> 15 | E5: {=INDEX(Data_DBD!$E:$E,$A5)} -> 1 | F5: {=INDEX(Data_DBD!$F:$F,$A5)} -> Sedang | H5: 137 | I5: 3 | J5: 1 | K5: 33 | L5: 1 | M5: Tinggi | O5: Entropy Root | P5: =-(IFERROR(Q2*LOG(Q2,2),0)+IFERROR(Q3*LOG(Q3,2),0)+IFERROR(Q4*LOG(Q4,2),0)) -> 1.4356417
A6: =RANDBETWEEN(2,164) -> 80 | B6: {=INDEX(Data_DBD!$B:$B,$A6)} -> 27 | C6: {=INDEX(Data_DBD!$C:$C,$A6)} -> 3 | D6: {=INDEX(Data_DBD!$D:$D,$A6)} -> 13 | E6: {=INDEX(Data_DBD!$E:$E,$A6)} -> 1 | F6: {=INDEX(Data_DBD!$F:$F,$A6)} -> Sedang | H6: 25 | I6: 81 | J6: 5 | K6: 14 | L6: 0 | M6: Sedang
A7: =RANDBETWEEN(2,164) -> 118 | B7: {=INDEX(Data_DBD!$B:$B,$A7)} -> 67 | C7: {=INDEX(Data_DBD!$C:$C,$A7)} -> 4 | D7: {=INDEX(Data_DBD!$D:$D,$A7)} -> 33 | E7: {=INDEX(Data_DBD!$E:$E,$A7)} -> 1 | F7: {=INDEX(Data_DBD!$F:$F,$A7)} -> Tinggi | H7: 151 | I7: 24 | J7: 3 | K7: 21 | L7: 0 | M7: Tinggi
A8: =RANDBETWEEN(2,164) -> 132 | B8: {=INDEX(Data_DBD!$B:$B,$A8)} -> 10 | C8: {=INDEX(Data_DBD!$C:$C,$A8)} -> 3 | D8: {=INDEX(Data_DBD!$D:$D,$A8)} -> 33 | E8: {=INDEX(Data_DBD!$E:$E,$A8)} -> 1 | F8: {=INDEX(Data_DBD!$F:$F,$A8)} -> Tinggi | H8: 138 | I8: 13 | J8: 3 | K8: 33 | L8: 1 | M8: Tinggi
A9: =RANDBETWEEN(2,164) -> 79 | B9: {=INDEX(Data_DBD!$B:$B,$A9)} -> 29 | C9: {=INDEX(Data_DBD!$C:$C,$A9)} -> 3 | D9: {=INDEX(Data_DBD!$D:$D,$A9)} -> 13 | E9: {=INDEX(Data_DBD!$E:$E,$A9)} -> 0 | F9: {=INDEX(Data_DBD!$F:$F,$A9)} -> Sedang | H9: 69 | I9: 24 | J9: 4 | K9: 10 | L9: 1 | M9: Rendah
A10: =RANDBETWEEN(2,164) -> 70 | B10: {=INDEX(Data_DBD!$B:$B,$A10)} -> 26 | C10: {=INDEX(Data_DBD!$C:$C,$A10)} -> 3 | D10: {=INDEX(Data_DBD!$D:$D,$A10)} -> 10 | E10: {=INDEX(Data_DBD!$E:$E,$A10)} -> 1 | F10: {=INDEX(Data_DBD!$F:$F,$A10)} -> Rendah | H10: 23 | I10: 28 | J10: 4 | K10: 14 | L10: 1 | M10: Sedang
A11: =RANDBETWEEN(2,164) -> 87 | B11: {=INDEX(Data_DBD!$B:$B,$A11)} -> 21 | C11: {=INDEX(Data_DBD!$C:$C,$A11)} -> 3 | D11: {=INDEX(Data_DBD!$D:$D,$A11)} -> 13 | E11: {=INDEX(Data_DBD!$E:$E,$A11)} -> 0 | F11: {=INDEX(Data_DBD!$F:$F,$A11)} -> Sedang | H11: 87 | I11: 21 | J11: 3 | K11: 13 | L11: 0 | M11: Sedang
A12: =RANDBETWEEN(2,164) -> 89 | B12: {=INDEX(Data_DBD!$B:$B,$A12)} -> 32 | C12: {=INDEX(Data_DBD!$C:$C,$A12)} -> 4 | D12: {=INDEX(Data_DBD!$D:$D,$A12)} -> 13 | E12: {=INDEX(Data_DBD!$E:$E,$A12)} -> 0 | F12: {=INDEX(Data_DBD!$F:$F,$A12)} -> Sedang | H12: 34 | I12: 55 | J12: 3 | K12: 14 | L12: 0 | M12: Sedang
A13: =RANDBETWEEN(2,164) -> 46 | B13: {=INDEX(Data_DBD!$B:$B,$A13)} -> 62 | C13: {=INDEX(Data_DBD!$C:$C,$A13)} -> 2 | D13: {=INDEX(Data_DBD!$D:$D,$A13)} -> 13 | E13: {=INDEX(Data_DBD!$E:$E,$A13)} -> 0 | F13: {=INDEX(Data_DBD!$F:$F,$A13)} -> Sedang | H13: 29 | I13: 19 | J13: 2 | K13: 14 | L13: 1 | M13: Sedang | U13: Pohon 5:
A14: =RANDBETWEEN(2,164) -> 143 | B14: {=INDEX(Data_DBD!$B:$B,$A14)} -> 20 | C14: {=INDEX(Data_DBD!$C:$C,$A14)} -> 4 | D14: {=INDEX(Data_DBD!$D:$D,$A14)} -> 21 | E14: {=INDEX(Data_DBD!$E:$E,$A14)} -> 1 | F14: {=INDEX(Data_DBD!$F:$F,$A14)} -> Tinggi | H14: 154 | I14: 18 | J14: 5 | K14: 21 | L14: 1 | M14: Tinggi | U14: Rule 1.1
A15: =RANDBETWEEN(2,164) -> 162 | B15: {=INDEX(Data_DBD!$B:$B,$A15)} -> 22 | C15: {=INDEX(Data_DBD!$C:$C,$A15)} -> 3 | D15: {=INDEX(Data_DBD!$D:$D,$A15)} -> 3 | E15: {=INDEX(Data_DBD!$E:$E,$A15)} -> 1 | F15: {=INDEX(Data_DBD!$F:$F,$A15)} -> Rendah | H15: 136 | I15: 6 | J15: 2 | K15: 33 | L15: 0 | M15: Tinggi | U15: IF Jumlah Kasus Per Bulan < 12,60
A16: =RANDBETWEEN(2,164) -> 155 | B16: {=INDEX(Data_DBD!$B:$B,$A16)} -> 19 | C16: {=INDEX(Data_DBD!$C:$C,$A16)} -> 5 | D16: {=INDEX(Data_DBD!$D:$D,$A16)} -> 21 | E16: {=INDEX(Data_DBD!$E:$E,$A16)} -> 1 | F16: {=INDEX(Data_DBD!$F:$F,$A16)} -> Tinggi | H16: 111 | I16: 25 | J16: 4 | K16: 33 | L16: 0 | M16: Tinggi | U16: THEN Risiko = Rendah
A17: =RANDBETWEEN(2,164) -> 121 | B17: {=INDEX(Data_DBD!$B:$B,$A17)} -> 82 | C17: {=INDEX(Data_DBD!$C:$C,$A17)} -> 5 | D17: {=INDEX(Data_DBD!$D:$D,$A17)} -> 33 | E17: {=INDEX(Data_DBD!$E:$E,$A17)} -> 1 | F17: {=INDEX(Data_DBD!$F:$F,$A17)} -> Tinggi | H17: 163 | I17: 34 | J17: 4 | K17: 3 | L17: 1 | M17: Rendah | U17: Rule 1.2
A18: =RANDBETWEEN(2,164) -> 80 | B18: {=INDEX(Data_DBD!$B:$B,$A18)} -> 27 | C18: {=INDEX(Data_DBD!$C:$C,$A18)} -> 3 | D18: {=INDEX(Data_DBD!$D:$D,$A18)} -> 13 | E18: {=INDEX(Data_DBD!$E:$E,$A18)} -> 1 | F18: {=INDEX(Data_DBD!$F:$F,$A18)} -> Sedang | H18: 17 | I18: 2 | J18: 3 | K18: 7 | L18: 0 | M18: Rendah | U18: IF Jumlah Kasus Per Bulan ≤ 12,60 AND Jumlah Kasus Per Bulan > 29,21
A19: =RANDBETWEEN(2,164) -> 17 | B19: {=INDEX(Data_DBD!$B:$B,$A19)} -> 2 | C19: {=INDEX(Data_DBD!$C:$C,$A19)} -> 3 | D19: {=INDEX(Data_DBD!$D:$D,$A19)} -> 7 | E19: {=INDEX(Data_DBD!$E:$E,$A19)} -> 0 | F19: {=INDEX(Data_DBD!$F:$F,$A19)} -> Rendah | H19: 138 | I19: 13 | J19: 3 | K19: 33 | L19: 1 | M19: Tinggi | U19: THEN Risiko = Sedang
A20: =RANDBETWEEN(2,164) -> 156 | B20: {=INDEX(Data_DBD!$B:$B,$A20)} -> 5 | C20: {=INDEX(Data_DBD!$C:$C,$A20)} -> 2 | D20: {=INDEX(Data_DBD!$D:$D,$A20)} -> 21 | E20: {=INDEX(Data_DBD!$E:$E,$A20)} -> 0 | F20: {=INDEX(Data_DBD!$F:$F,$A20)} -> Tinggi | H20: 143 | I20: 20 | J20: 4 | K20: 21 | L20: 1 | M20: Tinggi | U20: Rule 1.3
A21: =RANDBETWEEN(2,164) -> 104 | B21: {=INDEX(Data_DBD!$B:$B,$A21)} -> 37 | C21: {=INDEX(Data_DBD!$C:$C,$A21)} -> 4 | D21: {=INDEX(Data_DBD!$D:$D,$A21)} -> 18 | E21: {=INDEX(Data_DBD!$E:$E,$A21)} -> 1 | F21: {=INDEX(Data_DBD!$F:$F,$A21)} -> Sedang | H21: 15 | I21: 21 | J21: 2 | K21: 7 | L21: 0 | M21: Rendah | U21: IF Jumlah Kasus Per Bulan > 29,21 THEN Risiko = Tinggi
A22: =RANDBETWEEN(2,164) -> 137 | B22: {=INDEX(Data_DBD!$B:$B,$A22)} -> 3 | C22: {=INDEX(Data_DBD!$C:$C,$A22)} -> 1 | D22: {=INDEX(Data_DBD!$D:$D,$A22)} -> 33 | E22: {=INDEX(Data_DBD!$E:$E,$A22)} -> 1 | F22: {=INDEX(Data_DBD!$F:$F,$A22)} -> Tinggi | H22: 101 | I22: 42 | J22: 5 | K22: 18 | L22: 0 | M22: Sedang
A23: =RANDBETWEEN(2,164) -> 129 | B23: {=INDEX(Data_DBD!$B:$B,$A23)} -> 4 | C23: {=INDEX(Data_DBD!$C:$C,$A23)} -> 3 | D23: {=INDEX(Data_DBD!$D:$D,$A23)} -> 33 | E23: {=INDEX(Data_DBD!$E:$E,$A23)} -> 0 | F23: {=INDEX(Data_DBD!$F:$F,$A23)} -> Tinggi | H23: 13 | I23: 47 | J23: 2 | K23: 12 | L23: 0 | M23: Sedang
A24: =RANDBETWEEN(2,164) -> 110 | B24: {=INDEX(Data_DBD!$B:$B,$A24)} -> 42 | C24: {=INDEX(Data_DBD!$C:$C,$A24)} -> 2 | D24: {=INDEX(Data_DBD!$D:$D,$A24)} -> 33 | E24: {=INDEX(Data_DBD!$E:$E,$A24)} -> 1 | F24: {=INDEX(Data_DBD!$F:$F,$A24)} -> Tinggi | H24: 99 | I24: 4 | J24: 2 | K24: 18 | L24: 1 | M24: Sedang
A25: =RANDBETWEEN(2,164) -> 40 | B25: {=INDEX(Data_DBD!$B:$B,$A25)} -> 65 | C25: {=INDEX(Data_DBD!$C:$C,$A25)} -> 3 | D25: {=INDEX(Data_DBD!$D:$D,$A25)} -> 13 | E25: {=INDEX(Data_DBD!$E:$E,$A25)} -> 1 | F25: {=INDEX(Data_DBD!$F:$F,$A25)} -> Sedang | H25: 56 | I25: 4 | J25: 3 | K25: 15 | L25: 0 | M25: Sedang
A26: =RANDBETWEEN(2,164) -> 84 | B26: {=INDEX(Data_DBD!$B:$B,$A26)} -> 42 | C26: {=INDEX(Data_DBD!$C:$C,$A26)} -> 4 | D26: {=INDEX(Data_DBD!$D:$D,$A26)} -> 13 | E26: {=INDEX(Data_DBD!$E:$E,$A26)} -> 1 | F26: {=INDEX(Data_DBD!$F:$F,$A26)} -> Sedang | H26: 151 | I26: 24 | J26: 3 | K26: 21 | L26: 0 | M26: Tinggi
A27: =RANDBETWEEN(2,164) -> 148 | B27: {=INDEX(Data_DBD!$B:$B,$A27)} -> 55 | C27: {=INDEX(Data_DBD!$C:$C,$A27)} -> 3 | D27: {=INDEX(Data_DBD!$D:$D,$A27)} -> 21 | E27: {=INDEX(Data_DBD!$E:$E,$A27)} -> 1 | F27: {=INDEX(Data_DBD!$F:$F,$A27)} -> Tinggi | H27: 35 | I27: 40 | J27: 3 | K27: 4 | L27: 1 | M27: Rendah
A28: =RANDBETWEEN(2,164) -> 127 | B28: {=INDEX(Data_DBD!$B:$B,$A28)} -> 21 | C28: {=INDEX(Data_DBD!$C:$C,$A28)} -> 2 | D28: {=INDEX(Data_DBD!$D:$D,$A28)} -> 33 | E28: {=INDEX(Data_DBD!$E:$E,$A28)} -> 0 | F28: {=INDEX(Data_DBD!$F:$F,$A28)} -> Tinggi | H28: 100 | I28: 19 | J28: 6 | K28: 18 | L28: 0 | M28: Sedang
A29: =RANDBETWEEN(2,164) -> 111 | B29: {=INDEX(Data_DBD!$B:$B,$A29)} -> 25 | C29: {=INDEX(Data_DBD!$C:$C,$A29)} -> 4 | D29: {=INDEX(Data_DBD!$D:$D,$A29)} -> 33 | E29: {=INDEX(Data_DBD!$E:$E,$A29)} -> 0 | F29: {=INDEX(Data_DBD!$F:$F,$A29)} -> Tinggi | H29: 23 | I29: 28 | J29: 4 | K29: 14 | L29: 1 | M29: Sedang
A30: =RANDBETWEEN(2,164) -> 58 | B30: {=INDEX(Data_DBD!$B:$B,$A30)} -> 17 | C30: {=INDEX(Data_DBD!$C:$C,$A30)} -> 3 | D30: {=INDEX(Data_DBD!$D:$D,$A30)} -> 15 | E30: {=INDEX(Data_DBD!$E:$E,$A30)} -> 0 | F30: {=INDEX(Data_DBD!$F:$F,$A30)} -> Sedang | H30: 59 | I30: 28 | J30: 4 | K30: 15 | L30: 0 | M30: Sedang
A31: =RANDBETWEEN(2,164) -> 115 | B31: {=INDEX(Data_DBD!$B:$B,$A31)} -> 52 | C31: {=INDEX(Data_DBD!$C:$C,$A31)} -> 3 | D31: {=INDEX(Data_DBD!$D:$D,$A31)} -> 33 | E31: {=INDEX(Data_DBD!$E:$E,$A31)} -> 1 | F31: {=INDEX(Data_DBD!$F:$F,$A31)} -> Tinggi | H31: 63 | I31: 25 | J31: 3 | K31: 15 | L31: 0 | M31: Sedang
A32: =RANDBETWEEN(2,164) -> 44 | B32: {=INDEX(Data_DBD!$B:$B,$A32)} -> 28 | C32: {=INDEX(Data_DBD!$C:$C,$A32)} -> 5 | D32: {=INDEX(Data_DBD!$D:$D,$A32)} -> 13 | E32: {=INDEX(Data_DBD!$E:$E,$A32)} -> 1 | F32: {=INDEX(Data_DBD!$F:$F,$A32)} -> Sedang | H32: 113 | I32: 69 | J32: 1 | K32: 33 | L32: 1 | M32: Tinggi
A33: =RANDBETWEEN(2,164) -> 10 | B33: {=INDEX(Data_DBD!$B:$B,$A33)} -> 18 | C33: {=INDEX(Data_DBD!$C:$C,$A33)} -> 5 | D33: {=INDEX(Data_DBD!$D:$D,$A33)} -> 12 | E33: {=INDEX(Data_DBD!$E:$E,$A33)} -> 0 | F33: {=INDEX(Data_DBD!$F:$F,$A33)} -> Sedang | H33: 106 | I33: 23 | J33: 3 | K33: 18 | L33: 1 | M33: Sedang
... A164: =RANDBETWEEN(2,164) -> 66 | B164: {=INDEX(Data_DBD!$B:$B,$A164)} -> 21 | C164: {=INDEX(Data_DBD!$C:$C,$A164)} -> 5 | D164: {=INDEX(Data_DBD!$D:$D,$A164)} -> 15 | E164: {=INDEX(Data_DBD!$E:$E,$A164)} -> 1 | F164: {=INDEX(Data_DBD!$F:$F,$A164)} -> Sedang | H164: 57 | I164: 2 | J164: 2 | K164: 15 | L164: 1 | M164: Sedang
I165: =AVERAGE(I2:I164) -> 32.159509 | J165: =AVERAGE(J2:J164) -> 3.6625767 | K165: =AVERAGE(K2:K164) -> 18.411043 | L165: =AVERAGE(L2:L164) -> 0.58282209
B167: 18
E168: USIA | J168: LAMA RAWAT INAP | O168: JUMLAH KASUS PER BULAN | T168: JENIS KELAMIN
E169: Usia | F169: =AVERAGEIF($I$2:$I$164,"<="&$I$165) -> 17.153061 | G169: =AVERAGEIF($I$2:$I$164,">"&$I$165) -> 54.784615 | J169: Lama rawat inap | K169: =AVERAGEIF($J$2:$J$164,"<="&$J$165) -> 2.4805195 | L169: =AVERAGEIF($J$2:$J$164,">"&$J$165) -> 4.7209302 | O169: Jumlah kasus perbulan | P169: =AVERAGEIF($K$2:$K$164,"<="&$K$165) -> 12.603774 | Q169: =AVERAGEIF($K$2:$K$164,">"&$K$165) -> 29.210526 | T169: Jenis kelamin | U169: =AVERAGEIF($L$2:$L$164,"<="&$L$165) -> 0 | V169: =AVERAGEIF($L$2:$L$164,">"&$L$165) -> 1
E170: {=IF($I$2:$I$164<$F$169,"kiri",IF($I$2:$I$164<$G$169,"tengah","kanan"))} -> tengah | F170: Kanan > 54.7 | J170: {=IF($J$2:$J$164<$K$169,"kiri",IF($J$2:$J$164<$L$169,"tengah","kanan"))} -> tengah | K170: Kanan > 4.72 | O170: {=IF($K$2:$K$164<$P$169,"kiri",IF($K$2:$K$164<$Q$169,"tengah","kanan"))} -> kiri | P170: Kanan > 29.21 | T170: {=IF($L$2:$L$164<$U$169,"kiri",IF($L$2:$L$164<$V$169,"tengah","kanan"))} -> kanan | U170: Kanan > 1
E171: tengah | F171: =COUNTIFS($E$170:$E$332,"Kanan",$M$2:$M$164,"Tinggi") -> 13 | G171: =F171/34 -> 0.38235294 | J171: kiri | K171: =COUNTIFS($J$170:$J$332,"Kanan",$M$2:$M$164,"Tinggi") -> 10 | L171: =K171/33 -> 0.3030303 | O171: kanan | P171: =COUNTIFS($O$170:$O$332,"Kanan",$M$2:$M$164,"Tinggi") -> 39 | Q171: =P171/39 -> 1 | T171: tengah | U171: =COUNTIFS($T$170:$T$332,"Kanan",$M$2:$M$164,"Tinggi") -> 37 | V171: =U171/95 -> 0.38947368
...

Sheet Pohon 6
A1: No | B1: Usia | C1: Lama Rawat Inap | D1: Jenis Kelamin | E1: Tingkat Resiko | H1: No | I1: Usia | J1: Lama Rawat Inap | K1: Jenis Kelamin | L1: Tingkat Resiko | O1: Perhitungan root
A2: =RANDBETWEEN(2,164) -> 120 | B2: {=INDEX([1]data_dbd!$b:$b,$A2)} -> #NAME? | C2: {=INDEX([1]data_dbd!$c:$c,$A2)} -> #NAME? | D2: {=INDEX([1]data_dbd!$e:$e,$A2)} -> #NAME? | E2: {=INDEX([1]data_dbd!$f:$f,$A2)} -> #NAME? | H2: 42 | I2: 21 | J2: 5 | K2: 1 | L2: Sedang | O2: Tinggi | P2: =COUNTIF(L2:L164,"Tinggi") -> 74 | Q2: =P2/163 -> 0.45398773
A3: =RANDBETWEEN(2,164) -> 145 | B3: {=INDEX([1]data_dbd!$b:$b,$A3)} -> #NAME? | C3: {=INDEX([1]data_dbd!$c:$c,$A3)} -> #NAME? | D3: {=INDEX([1]data_dbd!$e:$e,$A3)} -> #NAME? | E3: {=INDEX([1]data_dbd!$f:$f,$A3)} -> #NAME? | H3: 30 | I3: 3 | J3: 2 | K3: 1 | L3: Sedang | O3: Sedang | P3: =COUNTIF(L2:L164,"Sedang") -> 74 | Q3: =P3/163 -> 0.45398773
A4: =RANDBETWEEN(2,164) -> 26 | B4: {=INDEX([1]data_dbd!$b:$b,$A4)} -> #NAME? | C4: {=INDEX([1]data_dbd!$c:$c,$A4)} -> #NAME? | D4: {=INDEX([1]data_dbd!$e:$e,$A4)} -> #NAME? | E4: {=INDEX([1]data_dbd!$f:$f,$A4)} -> #NAME? | H4: 139 | I4: 52 | J4: 7 | K4: 0 | L4: Tinggi | O4: Rendah | P4: =COUNTIF(L2:L164,"Rendah") -> 15 | Q4: =P4/163 -> 0.09202454
A5: =RANDBETWEEN(2,164) -> 16 | B5: {=INDEX([1]data_dbd!$b:$b,$A5)} -> #NAME? | C5: {=INDEX([1]data_dbd!$c:$c,$A5)} -> #NAME? | D5: {=INDEX([1]data_dbd!$e:$e,$A5)} -> #NAME? | E5: {=INDEX([1]data_dbd!$f:$f,$A5)} -> #NAME? | H5: 60 | I5: 68 | J5: 4 | K5: 0 | L5: Sedang | O5: Entropy Root | P5: =-(IFERROR(Q2*LOG(Q2,2),0)+IFERROR(Q3*LOG(Q3,2),0)+IFERROR(Q4*LOG(Q4,2),0)) -> 1.3511671
A6: =RANDBETWEEN(2,164) -> 65 | B6: {=INDEX([1]data_dbd!$b:$b,$A6)} -> #NAME? | C6: {=INDEX([1]data_dbd!$c:$c,$A6)} -> #NAME? | D6: {=INDEX([1]data_dbd!$e:$e,$A6)} -> #NAME? | E6: {=INDEX([1]data_dbd!$f:$f,$A6)} -> #NAME? | H6: 76 | I6: 70 | J6: 2 | K6: 0 | L6: Sedang
A7: =RANDBETWEEN(2,164) -> 7 | B7: {=INDEX([1]data_dbd!$b:$b,$A7)} -> #NAME? | C7: {=INDEX([1]data_dbd!$c:$c,$A7)} -> #NAME? | D7: {=INDEX([1]data_dbd!$e:$e,$A7)} -> #NAME? | E7: {=INDEX([1]data_dbd!$f:$f,$A7)} -> #NAME? | H7: 157 | I7: 15 | J7: 4 | K7: 1 | L7: Tinggi
A8: =RANDBETWEEN(2,164) -> 90 | B8: {=INDEX([1]data_dbd!$b:$b,$A8)} -> #NAME? | C8: {=INDEX([1]data_dbd!$c:$c,$A8)} -> #NAME? | D8: {=INDEX([1]data_dbd!$e:$e,$A8)} -> #NAME? | E8: {=INDEX([1]data_dbd!$f:$f,$A8)} -> #NAME? | H8: 48 | I8: 50 | J8: 5 | K8: 1 | L8: Sedang
A9: =RANDBETWEEN(2,164) -> 37 | B9: {=INDEX([1]data_dbd!$b:$b,$A9)} -> #NAME? | C9: {=INDEX([1]data_dbd!$c:$c,$A9)} -> #NAME? | D9: {=INDEX([1]data_dbd!$e:$e,$A9)} -> #NAME? | E9: {=INDEX([1]data_dbd!$f:$f,$A9)} -> #NAME? | H9: 60 | I9: 68 | J9: 4 | K9: 0 | L9: Sedang
A10: =RANDBETWEEN(2,164) -> 87 | B10: {=INDEX([1]data_dbd!$b:$b,$A10)} -> #NAME? | C10: {=INDEX([1]data_dbd!$c:$c,$A10)} -> #NAME? | D10: {=INDEX([1]data_dbd!$e:$e,$A10)} -> #NAME? | E10: {=INDEX([1]data_dbd!$f:$f,$A10)} -> #NAME? | H10: 8 | I10: 4 | J10: 2 | K10: 0 | L10: Sedang
A11: =RANDBETWEEN(2,164) -> 21 | B11: {=INDEX([1]data_dbd!$b:$b,$A11)} -> #NAME? | C11: {=INDEX([1]data_dbd!$c:$c,$A11)} -> #NAME? | D11: {=INDEX([1]data_dbd!$e:$e,$A11)} -> #NAME? | E11: {=INDEX([1]data_dbd!$f:$f,$A11)} -> #NAME? | H11: 149 | I11: 19 | J11: 5 | K11: 0 | L11: Tinggi
A12: =RANDBETWEEN(2,164) -> 119 | B12: {=INDEX([1]data_dbd!$b:$b,$A12)} -> #NAME? | C12: {=INDEX([1]data_dbd!$c:$c,$A12)} -> #NAME? | D12: {=INDEX([1]data_dbd!$e:$e,$A12)} -> #NAME? | E12: {=INDEX([1]data_dbd!$f:$f,$A12)} -> #NAME? | H12: 141 | I12: 36 | J12: 2 | K12: 0 | L12: Tinggi
A13: =RANDBETWEEN(2,164) -> 82 | B13: {=INDEX([1]data_dbd!$b:$b,$A13)} -> #NAME? | C13: {=INDEX([1]data_dbd!$c:$c,$A13)} -> #NAME? | D13: {=INDEX([1]data_dbd!$e:$e,$A13)} -> #NAME? | E13: {=INDEX([1]data_dbd!$f:$f,$A13)} -> #NAME? | H13: 6 | I13: 14 | J13: 4 | K13: 0 | L13: Sedang
A14: =RANDBETWEEN(2,164) -> 69 | B14: {=INDEX([1]data_dbd!$b:$b,$A14)} -> #NAME? | C14: {=INDEX([1]data_dbd!$c:$c,$A14)} -> #NAME? | D14: {=INDEX([1]data_dbd!$e:$e,$A14)} -> #NAME? | E14: {=INDEX([1]data_dbd!$f:$f,$A14)} -> #NAME? | H14: 39 | I14: 12 | J14: 5 | K14: 1 | L14: Sedang
A15: =RANDBETWEEN(2,164) -> 146 | B15: {=INDEX([1]data_dbd!$b:$b,$A15)} -> #NAME? | C15: {=INDEX([1]data_dbd!$c:$c,$A15)} -> #NAME? | D15: {=INDEX([1]data_dbd!$e:$e,$A15)} -> #NAME? | E15: {=INDEX([1]data_dbd!$f:$f,$A15)} -> #NAME? | H15: 54 | I15: 7 | J15: 3 | K15: 0 | L15: Sedang
A16: =RANDBETWEEN(2,164) -> 92 | B16: {=INDEX([1]data_dbd!$b:$b,$A16)} -> #NAME? | C16: {=INDEX([1]data_dbd!$c:$c,$A16)} -> #NAME? | D16: {=INDEX([1]data_dbd!$e:$e,$A16)} -> #NAME? | E16: {=INDEX([1]data_dbd!$f:$f,$A16)} -> #NAME? | H16: 8 | I16: 4 | J16: 2 | K16: 0 | L16: Sedang
A17: =RANDBETWEEN(2,164) -> 157 | B17: {=INDEX([1]data_dbd!$b:$b,$A17)} -> #NAME? | C17: {=INDEX([1]data_dbd!$c:$c,$A17)} -> #NAME? | D17: {=INDEX([1]data_dbd!$e:$e,$A17)} -> #NAME? | E17: {=INDEX([1]data_dbd!$f:$f,$A17)} -> #NAME? | H17: 44 | I17: 28 | J17: 5 | K17: 1 | L17: Sedang
... A138: =RANDBETWEEN(2,164) -> 32 | B138: {=INDEX([1]data_dbd!$b:$b,$A138)} -> #NAME? | C138: {=INDEX([1]data_dbd!$c:$c,$A138)} -> #NAME? | D138: {=INDEX([1]data_dbd!$e:$e,$A138)} -> #NAME? | E138: {=INDEX([1]data_dbd!$f:$f,$A138)} -> #NAME? | H138: 21 | I138: 10 | J138: 5 | K138: 1 | L138: Sedang
A139: =RANDBETWEEN(2,164) -> 10 | B139: {=INDEX([1]data_dbd!$b:$b,$A139)} -> #NAME? | C139: {=INDEX([1]data_dbd!$c:$c,$A139)} -> #NAME? | D139: {=INDEX([1]data_dbd!$e:$e,$A139)} -> #NAME? | E139: {=INDEX([1]data_dbd!$f:$f,$A139)} -> #NAME? | H139: 95 | I139: 11 | J139: 3 | K139: 1 | L139: Tinggi | W139: Pohon 6:
A140: =RANDBETWEEN(2,164) -> 143 | B140: {=INDEX([1]data_dbd!$b:$b,$A140)} -> #NAME? | C140: {=INDEX([1]data_dbd!$c:$c,$A140)} -> #NAME? | D140: {=INDEX([1]data_dbd!$e:$e,$A140)} -> #NAME? | E140: {=INDEX([1]data_dbd!$f:$f,$A140)} -> #NAME? | H140: 68 | I140: 44 | J140: 5 | K140: 0 | L140: Sedang | W140: Rule 1.1
A141: =RANDBETWEEN(2,164) -> 93 | B141: {=INDEX([1]data_dbd!$b:$b,$A141)} -> #NAME? | C141: {=INDEX([1]data_dbd!$c:$c,$A141)} -> #NAME? | D141: {=INDEX([1]data_dbd!$e:$e,$A141)} -> #NAME? | E141: {=INDEX([1]data_dbd!$f:$f,$A141)} -> #NAME? | H141: 14 | I141: 49 | J141: 4 | K141: 1 | L141: Rendah | W141: IF Lama Rawat Inap < 2,5
A142: =RANDBETWEEN(2,164) -> 93 | B142: {=INDEX([1]data_dbd!$b:$b,$A142)} -> #NAME? | C142: {=INDEX([1]data_dbd!$c:$c,$A142)} -> #NAME? | D142: {=INDEX([1]data_dbd!$e:$e,$A142)} -> #NAME? | E142: {=INDEX([1]data_dbd!$f:$f,$A142)} -> #NAME? | H142: 102 | I142: 41 | J142: 4 | K142: 0 | L142: Tinggi | W142: THEN Kelas = Sedang
A143: =RANDBETWEEN(2,164) -> 118 | B143: {=INDEX([1]data_dbd!$b:$b,$A143)} -> #NAME? | C143: {=INDEX([1]data_dbd!$c:$c,$A143)} -> #NAME? | D143: {=INDEX([1]data_dbd!$e:$e,$A143)} -> #NAME? | E143: {=INDEX([1]data_dbd!$f:$f,$A143)} -> #NAME? | H143: 30 | I143: 3 | J143: 2 | K143: 1 | L143: Sedang | W143: Rule 1.2
A144: =RANDBETWEEN(2,164) -> 49 | B144: {=INDEX([1]data_dbd!$b:$b,$A144)} -> #NAME? | C144: {=INDEX([1]data_dbd!$c:$c,$A144)} -> #NAME? | D144: {=INDEX([1]data_dbd!$e:$e,$A144)} -> #NAME? | E144: {=INDEX([1]data_dbd!$f:$f,$A144)} -> #NAME? | H144: 51 | I144: 48 | J144: 4 | K144: 0 | L144: Sedang | W144: IF Lama Rawat Inap ≤ 2,5 AND Lama Rawat Inap > 4,67
A145: =RANDBETWEEN(2,164) -> 44 | B145: {=INDEX([1]data_dbd!$b:$b,$A145)} -> #NAME? | C145: {=INDEX([1]data_dbd!$c:$c,$A145)} -> #NAME? | D145: {=INDEX([1]data_dbd!$e:$e,$A145)} -> #NAME? | E145: {=INDEX([1]data_dbd!$f:$f,$A145)} -> #NAME? | H145: 74 | I145: 9 | J145: 4 | K145: 0 | L145: Sedang | W145: THEN Kelas = Lama
A146: =RANDBETWEEN(2,164) -> 11 | B146: {=INDEX([1]data_dbd!$b:$b,$A146)} -> #NAME? | C146: {=INDEX([1]data_dbd!$c:$c,$A146)} -> #NAME? | D146: {=INDEX([1]data_dbd!$e:$e,$A146)} -> #NAME? | E146: {=INDEX([1]data_dbd!$f:$f,$A146)} -> #NAME? | H146: 26 | I146: 75 | J146: 4 | K146: 1 | L146: Sedang | W146: Rule 1.3
A147: =RANDBETWEEN(2,164) -> 159 | B147: {=INDEX([1]data_dbd!$b:$b,$A147)} -> #NAME? | C147: {=INDEX([1]data_dbd!$c:$c,$A147)} -> #NAME? | D147: {=INDEX([1]data_dbd!$e:$e,$A147)} -> #NAME? | E147: {=INDEX([1]data_dbd!$f:$f,$A147)} -> #NAME? | H147: 23 | I147: 28 | J147: 4 | K147: 1 | L147: Sedang | W147: IF Lama Rawat Inap > 4,67 THEN Kelas = Lama
A148: =RANDBETWEEN(2,164) -> 107 | B148: {=INDEX([1]data_dbd!$b:$b,$A148)} -> #NAME? | C148: {=INDEX([1]data_dbd!$c:$c,$A148)} -> #NAME? | D148: {=INDEX([1]data_dbd!$e:$e,$A148)} -> #NAME? | E148: {=INDEX([1]data_dbd!$f:$f,$A148)} -> #NAME? | H148: 125 | I148: 39 | J148: 4 | K148: 0 | L148: Tinggi
